Workbook

Sheet Summary
A1: Test Results Summary – Gazebo Baseline + ArUco Simulation
A3: Overall KPI | B3: Value | C3: N / formula basis | D3: Notes | H3: Failure reason | I3: Count | J3: % of failed | K3: Notes
A4: Total mission runs | B4: =COUNTA('Combined Mission Data'!$C$2:$C$76) -> 75 | C4: =B4 -> 75 | D4: Baseline and ArUco sheets counted together | H4: local_target_timeout | I4: =COUNTIF('Combined Mission Data'!$E$2:$E$76,H4) -> 13 | J4: =IFERROR(I4/$B$6,0) -> 0.59090909
A5: Successful runs | B5: =COUNTIF('Combined Mission Data'!$D$2:$D$76,TRUE) -> 53 | C5: =B4 -> 75 | D5: Success flag = 1 | H5: run_timeout | I5: =COUNTIF('Combined Mission Data'!$E$2:$E$76,H5) -> 6 | J5: =IFERROR(I5/$B$6,0) -> 0.27272727
A6: Failed runs | B6: =COUNTIF('Combined Mission Data'!$D$2:$D$76,FALSE) -> 22 | C6: =B4 -> 75 | D6: Success flag = 0 | H6: holonomic_goal_timeout | I6: =COUNTIF('Combined Mission Data'!$E$2:$E$76,H6) -> 1 | J6: =IFERROR(I6/$B$6,0) -> 0.045454545
A7: Success rate | B7: =IFERROR(B5/B4,0) -> 0.70666667 | C7: =B5&" / "&B4 -> 53 / 75 | D7: Successful runs divided by total runs | H7: aruco_no_markers_timeout | I7: =COUNTIF('Combined Mission Data'!$E$2:$E$76,H7) -> 1 | J7: =IFERROR(I7/$B$6,0) -> 0.045454545
A8: Average successful mission duration (s) | B8: =AVERAGEIF('Combined Mission Data'!D:D,TRUE,'Combined Mission Data'!G2:G76) -> 275.42475 | C8: =B$5 -> 53 | D8: Successful runs only | H8: detach_failed | I8: =COUNTIF('Combined Mission Data'!$E$2:$E$76,H8) -> 1 | J8: =IFERROR(I8/$B$6,0) -> 0.045454545
A9: Median successful mission duration (s) | B9: =MEDIAN('Combined Mission Data'!D:D,TRUE,'Combined Mission Data'!G2:G76) -> 276.861 | C9: =B$5 -> 53 | D9: Successful runs only | H9: Total | I9: =SUM(I4:I8) -> 22 | J9: =SUM(J4:J8) -> 1 | K9: All combined runs
A10: Minimum successful mission duration (s) | B10: =_xlfn.MINIFS('Combined Mission Data'!G:G,'Combined Mission Data'!D:D,TRUE) -> 253.126 | C10: =B$5 -> 53 | D10: Successful runs only
A11: Maximum successful mission duration (s) | B11: =_xlfn.MAXIFS('Combined Mission Data'!G:G,'Combined Mission Data'!D:D,TRUE) -> 311.838 | C11: =B$5 -> 53 | D11: Successful runs only
H12: Source | I12: Runs | J12: Successful | K12: Success rate
H13: Baseline | I13: =COUNTIF('Combined Mission Data'!$A$2:$A$76,H13) -> 50 | J13: =COUNTIFS('Combined Mission Data'!$A$2:$A$76,H13,'Combined Mission Data'!$D$2:$D$76,TRUE) -> 37 | K13: =IFERROR(J13/I13,0) -> 0.74
A14: Timing details sucessfull | B14: Average in s | C14: Median in s | D14: Min in s | E14: Max in s | H14: Baseline with ArUco | I14: =COUNTIF('Combined Mission Data'!$A$2:$A$76,H14) -> 25 | J14: =COUNTIFS('Combined Mission Data'!$A$2:$A$76,H14,'Combined Mission Data'!$D$2:$D$76,TRUE) -> 16 | K14: =IFERROR(J14/I14,0) -> 0.64
A15: Startup duration | B15: =AVERAGEIF('Combined Mission Data'!D:D,TRUE,'Combined Mission Data'!H:H) -> 9.5456604 | C15: {=MEDIAN(_xlfn._xlws.FILTER('Combined Mission Data'!H2:H76,'Combined Mission Data'!$D2:$D76=TRUE))} -> 9.487 | D15: =_xlfn.MINIFS('Combined Mission Data'!H2:H76,'Combined Mission Data'!$D2:$D76,TRUE) -> 9.181 | E15: =_xlfn.MAXIFS('Combined Mission Data'!H2:H76,'Combined Mission Data'!$D2:$D76,TRUE) -> 10.193
A16: Mission start time | B16: =AVERAGEIF('Combined Mission Data'!$D:$D,TRUE,'Combined Mission Data'!J:J) -> 13.36317 | C16: {=MEDIAN(_xlfn._xlws.FILTER('Combined Mission Data'!J2:J76,'Combined Mission Data'!$D2:$D76=TRUE))} -> 12.603 | D16: =_xlfn.MINIFS('Combined Mission Data'!J2:J76,'Combined Mission Data'!$D2:$D76,TRUE) -> 11.598 | E16: =_xlfn.MAXIFS('Combined Mission Data'!J2:J76,'Combined Mission Data'!$D2:$D76,TRUE) -> 17.405
A17: Pickup / attach time | B17: =AVERAGEIF('Combined Mission Data'!$D:$D,TRUE,'Combined Mission Data'!K:K) -> 119.07985 | C17: {=MEDIAN(_xlfn._xlws.FILTER('Combined Mission Data'!K2:K76,'Combined Mission Data'!$D2:$D76=TRUE))} -> 117.687 | D17: =_xlfn.MINIFS('Combined Mission Data'!K2:K76,'Combined Mission Data'!$D2:$D76,TRUE) -> 107.392 | E17: =_xlfn.MAXIFS('Combined Mission Data'!K2:K76,'Combined Mission Data'!$D2:$D76,TRUE) -> 139.538
A18: Attached driving to drop-off | B18: =AVERAGEIF('Combined Mission Data'!$D:$D,TRUE,'Combined Mission Data'!L:L) -> 211.37238 | C18: {=MEDIAN(_xlfn._xlws.FILTER('Combined Mission Data'!L2:L76,'Combined Mission Data'!$D2:$D76=TRUE))} -> 211.928 | D18: =_xlfn.MINIFS('Combined Mission Data'!L2:L76,'Combined Mission Data'!$D2:$D76,TRUE) -> 186.053 | E18: =_xlfn.MAXIFS('Combined Mission Data'!L2:L76,'Combined Mission Data'!$D2:$D76,TRUE) -> 244.051
A19: Drop-off release / detach time | B19: =AVERAGEIF('Combined Mission Data'!$D:$D,TRUE,'Combined Mission Data'!M:M) -> 183.02223 | C19: {=MEDIAN(_xlfn._xlws.FILTER('Combined Mission Data'!M2:M76,'Combined Mission Data'!$D2:$D76=TRUE))} -> 184.497 | D19: =_xlfn.MINIFS('Combined Mission Data'!M2:M76,'Combined Mission Data'!$D2:$D76,TRUE) -> 159.962 | E19: =_xlfn.MAXIFS('Combined Mission Data'!M2:M76,'Combined Mission Data'!$D2:$D76,TRUE) -> 208.243
A20: Return to charging time | B20: =AVERAGEIF('Combined Mission Data'!$D:$D,TRUE,'Combined Mission Data'!N:N) -> 277.19491 | C20: {=MEDIAN(_xlfn._xlws.FILTER('Combined Mission Data'!N2:N76,'Combined Mission Data'!$D2:$D76=TRUE))} -> 278.053 | D20: =_xlfn.MINIFS('Combined Mission Data'!N2:N76,'Combined Mission Data'!$D2:$D76,TRUE) -> 252.116 | E20: =_xlfn.MAXIFS('Combined Mission Data'!N2:N76,'Combined Mission Data'!$D2:$D76,TRUE) -> 310.831
A21: Command-to-success time | B21: =AVERAGEIF('Combined Mission Data'!$D:$D,TRUE,'Combined Mission Data'!O:O) -> 278.20108 | C21: {=MEDIAN(_xlfn._xlws.FILTER('Combined Mission Data'!O2:O76,'Combined Mission Data'!$D2:$D76=TRUE))} -> 279.059 | D21: =_xlfn.MINIFS('Combined Mission Data'!O2:O76,'Combined Mission Data'!$D2:$D76,TRUE) -> 253.123 | E21: =_xlfn.MAXIFS('Combined Mission Data'!O2:O76,'Combined Mission Data'!$D2:$D76,TRUE) -> 311.837
A22: Total mission duration
A25: Result group / thesis table | B25: Result name
A26: Gazebo mission success and timing results | B26: Total runs | C26: =COUNTA(sim_a[run]) -> 25
A27: Gazebo mission success and timing results | B27: Successful runs | C27: =COUNTIF(sim_a[success],TRUE) -> 16
A28: Gazebo mission success and timing results | B28: Failed runs | C28: =COUNTIF(sim_a[success],FALSE) -> 9
A29: Gazebo mission success and timing results | B29: Success rate | C29: =COUNTIF(sim_a[success],TRUE)/COUNTA(sim_a[run]) -> 0.64
A30: Gazebo mission success and timing results | B30: Average successful duration | C30: =AVERAGEIF(sim_a[success],TRUE,sim_a[duration_sec]) -> 263.0595
A31: Gazebo mission success and timing results | B31: Median successful duration | C31: {=MEDIAN(_xlfn._xlws.FILTER(sim_a[duration_sec],sim_a[success]=TRUE))} -> 262.525
A32: Gazebo mission success and timing results | B32: Minimum successful duration | C32: {=MIN(_xlfn._xlws.FILTER(sim_a[duration_sec],sim_a[success]=TRUE))} -> 253.126
A33: Gazebo mission success and timing results | B33: Maximum successful duration | C33: {=MAX(_xlfn._xlws.FILTER(sim_a[duration_sec],sim_a[success]=TRUE))} -> 274.303
A34: Gazebo mission success and timing results | B34: Average command-to-success time | C34: =AVERAGEIF(sim_a[success],TRUE,sim_a[command_to_success_sec]) -> 263.05713
A35: Simulation failure reasons | B35: Count per failure reason | C35: =COUNTIFS(sim_a[success],FALSE,sim_a[failure_reason],A2) -> 0
A36: Simulation failure reasons | B36: Percentage of failed runs | C36: =B2/COUNTIF(sim_a[success],FALSE) -> 0
A37: Final trolley and robot position errors | B37: Average trolley drop-off X error | C37: =AVERAGEIF(sim_a[success],TRUE,sim_a[abs_final_trolley_dropoff_x_mm]) -> 5.81875
A38: Final trolley and robot position errors | B38: Average trolley drop-off Y error | C38: =AVERAGEIF(sim_a[success],TRUE,sim_a[abs_final_trolley_dropoff_y_mm]) -> 63.40625
A39: Final trolley and robot position errors | B39: Average trolley drop-off distance error | C39: =AVERAGEIF(sim_a[success],TRUE,sim_a[final_trolley_dropoff_dist_mm]) -> 64.025
A40: Final trolley and robot position errors | B40: Average robot charging X error | C40: =AVERAGEIF(sim_a[success],TRUE,sim_a[abs_final_robot_charging_x_mm]) -> 0.39375
A41: Final trolley and robot position errors | B41: Average robot charging Y error | C41: =AVERAGEIF(sim_a[success],TRUE,sim_a[abs_final_robot_charging_y_mm]) -> 104.3875
A42: Final trolley and robot position errors | B42: Average robot charging distance error | C42: =AVERAGEIF(sim_a[success],TRUE,sim_a[final_robot_charging_dist_mm]) -> 104.3875
A43: Side-alignment completion | B43: Side alignment completed | C43: =COUNT(sim_a[side_align_complete_sec]) -> 24
...

Sheet baseline_mission_results (2)
A1: run | B1: success | C1: failure_reason | D1: failure_detail | E1: duration_sec | F1: startup_duration_sec | G1: command_to_success_sec | H1: mission_started_sec | I1: attach_sec | J1: detach_sec | K1: dropoff_detected_sec | L1: charging_detected_sec | M1: last_trolley_x | N1: last_trolley_y | O1: last_robot_x | P1: last_robot_y | Q1: mission_param_overrides | R1: holonomic_param_overrides | S1: last_log_line
A2: 1 | B2: TRUE | E2: 289.854 | F2: 9.28 | G2: 289.852 | H2: 12.446 | I2: 120.994 | J2: 222.805 | K2: 195.203 | L2: 288.845 | M2: 5.2033 | N2: -0.0778 | O2: 0.0002 | P2: 0.0994 | S2: [python3-22] [INFO] [1779400767,120909397] [nav2_trolley_mission_controller]: Local target 'return lane above drop zones' reached,
A3: 2 | B3: TRUE | E3: 291.981 | F3: 9.24 | G3: 291.98 | H3: 16.905 | I3: 125.127 | J3: 225.603 | K3: 197.946 | L3: 290.975 | M3: 5.2031 | N3: -0.0351 | O3: -0.0011 | P3: 0.0927 | S3: [python3-22] [INFO] [1779401059,774966934] [nav2_trolley_mission_controller]: Local target 'return lane above drop zones' reached,
A4: 3 | B4: TRUE | E4: 280.732 | F4: 9.535 | G4: 280.731 | H4: 17.203 | I4: 113.714 | J4: 213.904 | K4: 185.688 | L4: 279.725 | M4: 5.2223 | N4: -0.1732 | O4: -0.0002 | P4: 0.0982 | S4: [python3-22] [INFO] [1779401341,476298780] [nav2_trolley_mission_controller]: Local target 'return lane above drop zones' reached,
A5: 4 | B5: TRUE | E5: 282.655 | F5: 9.435 | G5: 282.653 | H5: 13.601 | I5: 112.831 | J5: 215.974 | K5: 186.603 | L5: 281.648 | M5: 5.1864 | N5: -0.0187 | O5: -0.001 | P5: 0.1001 | S5: [python3-22] [INFO] [1779401625,139209710] [nav2_trolley_mission_controller]: Local target 'return lane above drop zones' reached,
A6: 5 | B6: FALSE | C6: local_target_timeout | D6: [python3-22] [ERROR] [1779401884,165594121] [nav2_trolley_mission_controller]: Local target 'drop-off center' timed out: distance=0,029, yaw=+0,33 deg | E6: 247.577 | F6: 9.337 | H6: 17.002 | I6: 139.453 | K6: 211.612 | M6: 5.199 | N6: 0.0129 | O6: 5.2003 | P6: 0.0291 | S6: [python3-23] [INFO] [1779401884,166443925] [holonomic_goal_controller]: Holonomic lidar ignore radius set to 0,00 m,
A7: 6 | B7: TRUE | E7: 293.527 | F7: 9.232 | G7: 293.526 | H7: 12.397 | I7: 118.964 | J7: 226.886 | K7: 196.455 | L7: 292.52 | M7: 5.1962 | N7: -0.0311 | O7: 0.0003 | P7: 0.0968 | S7: [python3-22] [INFO] [1779402172,403670692] [nav2_trolley_mission_controller]: Local target 'return lane above drop zones' reached,
A8: 7 | B8: TRUE | E8: 311.838 | F8: 9.443 | G8: 311.837 | H8: 14.11 | I8: 132.508 | J8: 244.051 | K8: 208.243 | L8: 310.831 | M8: 5.2132 | N8: -0.1616 | O8: 0.0009 | P8: 0.0972 | S8: [python3-22] [INFO] [1779402484,713304423] [nav2_trolley_mission_controller]: Local target 'return lane above drop zones' reached,
A9: 8 | B9: TRUE | E9: 281.635 | F9: 9.333 | G9: 281.633 | H9: 13.093 | I9: 115.185 | J9: 215.36 | K9: 186.59 | L9: 280.628 | M9: 5.2208 | N9: -0.0441 | O9: 0.0006 | P9: 0.0994 | S9: [python3-22] [INFO] [1779402767,554791470] [nav2_trolley_mission_controller]: Local target 'return lane above drop zones' reached,
A10: 9 | B10: TRUE | E10: 280.591 | F10: 9.181 | G10: 280.589 | H10: 12.348 | I10: 114.71 | J10: 212.951 | K10: 188.499 | L10: 279.582 | M10: 5.2085 | N10: -0.0318 | O10: -0.0009 | P10: 0.0939 | S10: [python3-22] [INFO] [1779403049,123255652] [nav2_trolley_mission_controller]: Local target 'return lane above drop zones' reached,
A11: 10 | B11: TRUE | E11: 282.183 | F11: 9.183 | G11: 282.182 | H11: 12.632 | I11: 115.927 | J11: 215.549 | K11: 188.135 | L11: 281.176 | M11: 5.1912 | N11: -0.0215 | O11: -0.0001 | P11: 0.104 | S11: [python3-22] [INFO] [1779403332,698544269] [nav2_trolley_mission_controller]: Local target 'return lane above drop zones' reached,
A12: 11 | B12: TRUE | E12: 278.131 | F12: 9.433 | G12: 278.129 | H12: 11.598 | I12: 109.611 | J12: 211.197 | K12: 185.597 | L12: 277.124 | M12: 5.1533 | N12: -0.0183 | O12: -0.0003 | P12: 0.1054 | S12: [python3-22] [INFO] [1779403611,394082521] [nav2_trolley_mission_controller]: Local target 'return lane above drop zones' reached,
A13: 12 | B13: FALSE | C13: run_timeout | D13: Robot did not return to charging while trolley remained in orange drop-off before timeout, | E13: 420.004 | F13: 9.585 | H13: 11.749 | I13: 114.452 | J13: 215.891 | K13: 186.762 | L13: 281.82 | M13: 5.1687 | N13: -0.5982 | O13: 0.0011 | P13: 0.027 | S13: [python3-23] [INFO] [1779403913,978006695] [holonomic_goal_controller]: Holonomic lidar ignore radius set to 0,00 m,
A14: 13 | B14: FALSE | C14: run_timeout | D14: Robot did not return to charging while trolley remained in orange drop-off before timeout, | E14: 420.037 | F14: 9.535 | H14: 14.452 | I14: 133.088 | J14: 236.641 | K14: 207.574 | L14: 303.118 | M14: 5.229 | N14: -0.7873 | O14: 0.0009 | P14: 0.0274 | S14: [python3-23] [INFO] [1779404355,542661361] [holonomic_goal_controller]: Holonomic lidar ignore radius set to 0,00 m,
A15: 14 | B15: TRUE | E15: 291.776 | F15: 9.485 | G15: 291.774 | H15: 11.65 | I15: 118.22 | J15: 224.642 | K15: 194.208 | L15: 290.768 | M15: 5.1974 | N15: -0.0308 | O15: 0.001 | P15: 0.1015 | S15: [python3-22] [INFO] [1779404745,301644056] [nav2_trolley_mission_controller]: Local target 'return lane above drop zones' reached,
A16: 15 | B16: TRUE | E16: 277.183 | F16: 9.483 | G16: 277.181 | H16: 11.648 | I16: 112.288 | J16: 210.148 | K16: 185.659 | L16: 276.175 | M16: 5.2095 | N16: -0.1142 | O16: 0.001 | P16: 0.104 | S16: [python3-22] [INFO] [1779405023,026550787] [nav2_trolley_mission_controller]: Local target 'return lane above drop zones' reached,
A17: 16 | B17: TRUE | E17: 291.783 | F17: 9.487 | G17: 291.782 | H17: 11.658 | I17: 122.856 | J17: 224.591 | K17: 195.721 | L17: 290.776 | M17: 5.1808 | N17: -0.1716 | O17: -0.0001 | P17: 0.1072 | S17: [python3-22] [INFO] [1779405315,434277759] [nav2_trolley_mission_controller]: Local target 'return lane above drop zones' reached,
A18: 17 | B18: TRUE | E18: 294.059 | F18: 9.484 | G18: 294.057 | H18: 12.429 | I18: 119.446 | J18: 226.771 | K18: 198.505 | L18: 293.052 | M18: 5.2008 | N18: -0.035 | O18: 0.0002 | P18: 0.1032 | S18: [python3-22] [INFO] [1779405609,793560650] [nav2_trolley_mission_controller]: Local target 'return lane above drop zones' reached,
A19: 18 | B19: TRUE | E19: 275.956 | F19: 9.531 | G19: 275.955 | H19: 12.446 | I19: 108.544 | J19: 208.828 | K19: 180.408 | L19: 274.949 | M19: 5.1904 | N19: -0.0263 | O19: 0 | P19: 0.0935 | S19: [python3-22] [INFO] [1779405886,188781421] [nav2_trolley_mission_controller]: Local target 'return lane above drop zones' reached,
A20: 19 | B20: TRUE | E20: 277.511 | F20: 9.532 | G20: 277.509 | H20: 13.997 | I20: 109.649 | J20: 210.179 | K20: 181.45 | L20: 276.503 | M20: 5.1994 | N20: -0.0245 | O20: 0.0002 | P20: 0.095 | S20: [python3-22] [INFO] [1779406164,520318367] [nav2_trolley_mission_controller]: Local target 'return lane above drop zones' reached,
A21: 20 | B21: TRUE | E21: 283.205 | F21: 9.39 | G21: 283.203 | H21: 11.64 | I21: 113.076 | J21: 215.869 | K21: 186.142 | L21: 282.197 | M21: 5.207 | N21: -0.023 | O21: -0.0002 | P21: 0.0937 | S21: [python3-22] [INFO] [1779406448,550052743] [nav2_trolley_mission_controller]: Local target 'return lane above drop zones' reached,
A22: 21 | B22: FALSE | C22: local_target_timeout | D22: [python3-22] [ERROR] [1779406685,450673931] [nav2_trolley_mission_controller]: Local target 'drop-off center' timed out: distance=0,030, yaw=-4,28 deg | E22: 225.533 | F22: 9.434 | H22: 12.607 | I22: 113.987 | K22: 189.125 | M22: 5.2007 | N22: 0.012 | O22: 5.1981 | P22: 0.0299 | S22: [python3-23] [INFO] [1779406685,451428658] [holonomic_goal_controller]: Holonomic lidar ignore radius set to 0,00 m,
A23: 22 | B23: TRUE | E23: 278.681 | F23: 9.489 | G23: 278.679 | H23: 11.655 | I23: 111.581 | J23: 211.897 | K23: 184.141 | L23: 277.674 | M23: 5.1886 | N23: -0.0221 | O23: -0.0001 | P23: 0.1004 | S23: [python3-22] [INFO] [1779406954,883848531] [nav2_trolley_mission_controller]: Local target 'return lane above drop zones' reached,
A24: 23 | B24: TRUE | E24: 290.337 | F24: 9.48 | G24: 290.335 | H24: 13.229 | I24: 115.623 | J24: 224.406 | K24: 192.765 | L24: 289.33 | M24: 5.1455 | N24: -0.1591 | O24: -0.0003 | P24: 0.0933 | S24: [python3-22] [INFO] [1779407246,112403451] [nav2_trolley_mission_controller]: Local target 'return lane above drop zones' reached,
A25: 24 | B25: TRUE | E25: 280.47 | F25: 9.487 | G25: 280.468 | H25: 13.422 | I25: 112.041 | J25: 214.176 | K25: 184.406 | L25: 279.463 | M25: 5.1929 | N25: -0.1324 | O25: -0.0002 | P25: 0.1068 | S25: [python3-22] [INFO] [1779407527,352570769] [nav2_trolley_mission_controller]: Local target 'return lane above drop zones' reached,
A26: 25 | B26: FALSE | C26: local_target_timeout | D26: [python3-22] [ERROR] [1779407760,816316232] [nav2_trolley_mission_controller]: Local target 'drop-off center' timed out: distance=0,031, yaw=+5,39 deg | E26: 222.775 | F26: 9.487 | H26: 11.651 | I26: 112.786 | K26: 186.165 | M26: 5.2037 | N26: 0.0141 | O26: 5.2026 | P26: 0.0307 | S26: [python3-23] [INFO] [1779407760,817166000] [holonomic_goal_controller]: Holonomic lidar ignore radius set to 0,00 m,
A27: 26 | B27: TRUE | E27: 275.22 | F27: 9.433 | G27: 275.218 | H27: 12.716 | I27: 109.121 | J27: 208.137 | K27: 180.178 | L27: 274.213 | M27: 5.1919 | N27: -0.0225 | O27: 0.0002 | P27: 0.1075 | S27: [python3-22] [INFO] [1779408026,858227011] [nav2_trolley_mission_controller]: Local target 'return lane above drop zones' reached,
A28: 27 | B28: FALSE | C28: local_target_timeout | D28: [python3-22] [ERROR] [1779408204,902850771] [nav2_trolley_mission_controller]: Local target 'pickup exit lane' timed out: distance=0,025, yaw=-0,84 deg | E28: 167.263 | F28: 9.384 | H28: 17.051 | I28: 122.11 | M28: 2.512 | N28: 1.3087 | O28: 2.5155 | P28: 1.3249 | S28: [python3-23] [INFO] [1779408204,903748410] [holonomic_goal_controller]: Holonomic lidar ignore radius set to 0,00 m,
A29: 28 | B29: FALSE | C29: local_target_timeout | D29: [python3-22] [ERROR] [1779408422,851393718] [nav2_trolley_mission_controller]: Local target 'drop-off center' timed out: distance=0,031, yaw=+5,44 deg | E29: 217.188 | F29: 9.386 | H29: 11.551 | I29: 109.672 | K29: 180.525 | M29: 5.2036 | N29: 0.0126 | O29: 5.2026 | P29: 0.0307 | S29: [python3-23] [INFO] [1779408422,852442142] [holonomic_goal_controller]: Holonomic lidar ignore radius set to 0,00 m,
A30: 29 | B30: TRUE | E30: 291.261 | F30: 9.486 | G30: 291.26 | H30: 14.153 | I30: 121.532 | J30: 224.426 | K30: 199.737 | L30: 290.254 | M30: 5.2105 | N30: -0.1022 | O30: -0.0001 | P30: 0.1053 | S30: [python3-22] [INFO] [1779408704,469834293] [nav2_trolley_mission_controller]: Local target 'return lane above drop zones' reached,
A31: 30 | B31: TRUE | E31: 292.796 | F31: 9.538 | G31: 292.794 | H31: 17.204 | I31: 117.687 | J31: 225.962 | K31: 194.224 | L31: 291.789 | M31: 5.1948 | N31: -0.0243 | O31: 0.0002 | P31: 0.0924 | S31: [python3-22] [INFO] [1779408997,517295828] [nav2_trolley_mission_controller]: Local target 'return lane above drop zones' reached,
A32: 31 | B32: FALSE | C32: local_target_timeout | D32: [python3-22] [ERROR] [1779409229,846244368] [nav2_trolley_mission_controller]: Local target 'drop-off center' timed out: distance=0,025, yaw=-4,82 deg | E32: 221.043 | F32: 9.484 | H32: 13.779 | I32: 112.658 | K32: 184.778 | M32: 5.2037 | N32: 0.0092 | O32: 5.1981 | P32: 0.0252 | S32: [python3-23] [INFO] [1779409229,847084174] [holonomic_goal_controller]: Holonomic lidar ignore radius set to 0,00 m,
A33: 32 | B33: TRUE | E33: 276.539 | F33: 9.532 | G33: 276.537 | H33: 14.012 | I33: 109.511 | J33: 209.298 | K33: 184.497 | L33: 275.532 | M33: 5.2036 | N33: -0.0747 | O33: -0.0001 | P33: 0.0943 | S33: [python3-22] [INFO] [1779409496,576593356] [nav2_trolley_mission_controller]: Local target 'return lane above drop zones' reached,
A34: 33 | B34: TRUE | E34: 279.061 | F34: 9.383 | G34: 279.059 | H34: 17.05 | I34: 114.009 | J34: 211.928 | K34: 188.033 | L34: 278.053 | M34: 5.207 | N34: -0.0277 | O34: -0.0001 | P34: 0.0973 | S34: [python3-22] [INFO] [1779409776,201681101] [nav2_trolley_mission_controller]: Local target 'return lane above drop zones' reached,
A35: 34 | B35: TRUE | E35: 272.62 | F35: 9.438 | G35: 272.618 | H35: 12.603 | I35: 108.52 | J35: 206.539 | K35: 179.584 | L35: 271.611 | M35: 5.2014 | N35: -0.0294 | O35: -0.0005 | P35: 0.0962 | S35: [python3-22] [INFO] [1779410049,492180342] [nav2_trolley_mission_controller]: Local target 'return lane above drop zones' reached,
A36: 35 | B36: TRUE | E36: 280.242 | F36: 9.516 | G36: 280.24 | H36: 11.682 | I36: 109.452 | J36: 213.256 | K36: 183.179 | L36: 279.234 | M36: 5.1909 | N36: -0.0211 | O36: -0.0008 | P36: 0.0927 | S36: [python3-22] [INFO] [1779410330,097743149] [nav2_trolley_mission_controller]: Local target 'return lane above drop zones' reached,
A37: 36 | B37: TRUE | E37: 302.205 | F37: 9.387 | G37: 302.203 | H37: 17.054 | I37: 126.141 | J37: 234.97 | K37: 202.632 | L37: 301.198 | M37: 5.1952 | N37: -0.0226 | O37: 0.0002 | P37: 0.0954 | S37: [python3-22] [INFO] [1779410632,941458095] [nav2_trolley_mission_controller]: Local target 'return lane above drop zones' reached,
A38: 37 | B38: TRUE | E38: 281.587 | F38: 9.388 | G38: 281.586 | H38: 17.054 | I38: 114.466 | J38: 214.501 | K38: 186.029 | L38: 280.58 | M38: 5.2081 | N38: -0.0358 | O38: -0.0003 | P38: 0.0969 | S38: [python3-22] [INFO] [1779410915,036969336] [nav2_trolley_mission_controller]: Local target 'return lane above drop zones' reached,
A39: 38 | B39: TRUE | E39: 281.727 | F39: 9.491 | G39: 281.725 | H39: 11.655 | I39: 114.516 | J39: 215.244 | K39: 186.678 | L39: 280.719 | M39: 5.1878 | N39: -0.019 | O39: 0.0005 | P39: 0.113 | S39: [python3-22] [INFO] [1779411197,601325212] [nav2_trolley_mission_controller]: Local target 'return lane above drop zones' reached,
A40: 39 | B40: FALSE | C40: run_timeout | D40: Robot did not return to charging while trolley remained in orange drop-off before timeout, | E40: 420.001 | F40: 9.588 | H40: 11.752 | I40: 112.593 | J40: 214.227 | K40: 185.255 | L40: 280.81 | M40: 5.1316 | N40: -0.8426 | O40: 0.0013 | P40: 0.0274 | S40: [python3-23] [INFO] [1779411498,914204898] [holonomic_goal_controller]: Holonomic lidar ignore radius set to 0,00 m,
...

Sheet baseline_mission_results_with_a
A1: run | B1: success | C1: failure_reason | D1: failure_detail | E1: duration_sec | F1: startup_duration_sec | G1: command_to_success_sec | H1: mission_started_sec | I1: attach_sec | J1: detach_sec | K1: dropoff_detected_sec | L1: charging_detected_sec | M1: last_trolley_x | N1: last_trolley_y | O1: last_trolley_yaw_deg | P1: last_robot_x | Q1: last_robot_y | R1: last_robot_yaw_deg | S1: final_trolley_dropoff_error_x | T1: final_trolley_dropoff_error_y | U1: final_trolley_dropoff_error_dist | V1: final_robot_charging_error_x | W1: final_robot_charging_error_y | X1: final_robot_charging_error_dist | Y1: side_align_complete_sec | Z1: side_align_aruco_est_error_x | AA1: side_align_aruco_est_error_y | AB1: side_align_aruco_est_yaw_error_deg | AC1: side_align_aruco_est_marker_count | AD1: side_align_actual_trolley_base_x | AE1: side_align_actual_trolley_base_y | AF1: side_align_actual_trolley_yaw_error_deg | AG1: side_align_actual_aruco_error_x | AH1: side_align_actual_aruco_error_y | AI1: side_align_actual_aruco_error_dist | AJ1: side_align_actual_aruco_yaw_error_deg | AK1: side_align_aruco_vs_actual_error_x | AL1: side_align_aruco_vs_actual_error_y | AM1: side_align_aruco_vs_actual_yaw_error_deg | AN1: fine_align_complete_sec | AO1: fine_align_aruco_est_error_x | AP1: fine_align_aruco_est_error_y | AQ1: fine_align_aruco_est_yaw_error_deg | AR1: fine_align_aruco_est_marker_count | AS1: fine_align_actual_trolley_base_x | AT1: fine_align_actual_trolley_base_y | AU1: fine_align_actual_trolley_yaw_error_deg | AV1: fine_align_actual_aruco_error_x | AW1: fine_align_actual_aruco_error_y | AX1: fine_align_actual_aruco_error_dist | AY1: fine_align_actual_aruco_yaw_error_deg | AZ1: fine_align_aruco_vs_actual_error_x | BA1: fine_align_aruco_vs_actual_error_y | BB1: fine_align_aruco_vs_actual_yaw_error_deg | BC1: mission_param_overrides | BD1: holonomic_param_overrides | BE1: last_log_line | BF1: abs_final_trolley_dropoff_x_mm | BG1: abs_final_trolley_dropoff_y_mm | BH1: final_trolley_dropoff_dist_mm | BI1: abs_final_robot_charging_x_mm | BJ1: abs_final_robot_charging_y_mm | BK1: final_robot_charging_dist_mm | BL1: abs_side_est_x_mm | BM1: abs_side_est_y_mm | BN1: abs_side_est_yaw_deg | BO1: abs_side_actual_x_mm | BP1: abs_side_actual_y_mm | BQ1: abs_side_actual_yaw_deg | BR1: abs_side_vs_actual_x_mm | BS1: abs_side_vs_actual_y_mm | BT1: abs_side_vs_actual_yaw_deg | BU1: abs_fine_est_x_mm | BV1: abs_fine_est_y_mm | BW1: abs_fine_est_yaw_deg | BX1: abs_fine_actual_x_mm | BY1: abs_fine_actual_y_mm | BZ1: abs_fine_actual_yaw_deg | CA1: abs_fine_vs_actual_x_mm | CB1: abs_fine_vs_actual_y_mm | CC1: abs_fine_vs_actual_yaw_deg
A2: 1 | B2: TRUE | E2: 266.313 | F2: 9.833 | G2: 266.309 | H2: 12.001 | I2: 128.278 | J2: 199.247 | K2: 169.131 | L2: 265.3 | M2: 5.2019 | N2: -0.0401 | O2: -0.77 | P2: -0.0001 | Q2: 0.1066 | R2: 0.081 | S2: 0.0019 | T2: -0.0401 | U2: 0.0401 | V2: -0.0001 | W2: 0.1066 | X2: 0.1066 | Y2: 76.598 | Z2: 0.004 | AA2: 0 | AB2: -0.7 | AC2: 5 | AD2: 0.0178 | AE2: -1.057 | AF2: -0.607 | AG2: 0.0028 | AH2: -1.057 | AI2: 1.057 | AJ2: -0.607 | AK2: 0.0012 | AL2: 1.057 | AM2: -0.093 | AN2: 128.275 | AO2: 0.008 | AP2: -0.025 | AQ2: -0.05 | AR2: 11 | AS2: 0.0079 | AT2: -0.0251 | AU2: -0.094 | AV2: 0.0079 | AW2: -0.0251 | AX2: 0.0263 | AY2: -0.094 | AZ2: 0.0001 | BA2: 0.0001 | BB2: 0.044 | BE2: [python3-22] [INFO] [1783093089.174777147] [nav2_trolley_mission_controller]: Local target 'return lane above drop zones' reached. | BF2: =IF(sim_a[[#This Row],[final_trolley_dropoff_error_x]]="","",ABS(sim_a[[#This Row],[final_trolley_dropoff_error_x]])*1000) -> 1.9 | BG2: =IF(sim_a[[#This Row],[final_trolley_dropoff_error_y]]="","",ABS(sim_a[[#This Row],[final_trolley_dropoff_error_y]])*1000) -> 40.1 | BH2: =IF(sim_a[[#This Row],[final_trolley_dropoff_error_dist]]="","",sim_a[[#This Row],[final_trolley_dropoff_error_dist]]*1000) -> 40.1 | BI2: =IF(sim_a[[#This Row],[final_robot_charging_error_x]]="","",ABS(sim_a[[#This Row],[final_robot_charging_error_x]])*1000) -> 0.1 | BJ2: =IF(sim_a[[#This Row],[final_robot_charging_error_y]]="","",ABS(sim_a[[#This Row],[final_robot_charging_error_y]])*1000) -> 106.6 | BK2: =IF(sim_a[[#This Row],[final_robot_charging_error_dist]]="","",sim_a[[#This Row],[final_robot_charging_error_dist]]*1000) -> 106.6 | BL2: =IF(sim_a[[#This Row],[side_align_aruco_est_error_x]]="","",ABS(sim_a[[#This Row],[side_align_aruco_est_error_x]])*1000) -> 4 | BM2: =IF(sim_a[[#This Row],[side_align_aruco_est_error_y]]="","",ABS(sim_a[[#This Row],[side_align_aruco_est_error_y]])*1000) -> 0 | BN2: =IF(sim_a[[#This Row],[side_align_aruco_est_yaw_error_deg]]="","",ABS(sim_a[[#This Row],[side_align_aruco_est_yaw_error_deg]])) -> 0.7 | BO2: =IF(sim_a[[#This Row],[side_align_actual_aruco_error_x]]="","",ABS(sim_a[[#This Row],[side_align_actual_aruco_error_x]])*1000) -> 2.8 | BP2: =IF(sim_a[[#This Row],[side_align_actual_aruco_error_y]]="","",ABS(sim_a[[#This Row],[side_align_actual_aruco_error_y]])*1000) -> 1057 | BQ2: =IF(sim_a[[#This Row],[side_align_actual_aruco_yaw_error_deg]]="","",ABS(sim_a[[#This Row],[side_align_actual_aruco_yaw_error_deg]])) -> 0.607 | BR2: =IF(sim_a[[#This Row],[side_align_aruco_vs_actual_error_x]]="","",ABS(sim_a[[#This Row],[side_align_aruco_vs_actual_error_x]])*1000) -> 1.2 | BS2: =IF(sim_a[[#This Row],[side_align_aruco_vs_actual_error_y]]="","",ABS(sim_a[[#This Row],[side_align_aruco_vs_actual_error_y]])*1000) -> 1057 | BT2: =IF(sim_a[[#This Row],[side_align_aruco_vs_actual_yaw_error_deg]]="","",ABS(sim_a[[#This Row],[side_align_aruco_vs_actual_yaw_error_deg]])) -> 0.093 | BU2: =IF(sim_a[[#This Row],[fine_align_aruco_est_error_x]]="","",ABS(sim_a[[#This Row],[fine_align_aruco_est_error_x]])*1000) -> 8 | BV2: =IF(sim_a[[#This Row],[fine_align_aruco_est_error_y]]="","",ABS(sim_a[[#This Row],[fine_align_aruco_est_error_y]])*1000) -> 25 | BW2: =IF(sim_a[[#This Row],[fine_align_aruco_est_yaw_error_deg]]="","",ABS(sim_a[[#This Row],[fine_align_aruco_est_yaw_error_deg]])) -> 0.05 | BX2: =IF(sim_a[[#This Row],[fine_align_actual_aruco_error_x]]="","",ABS(sim_a[[#This Row],[fine_align_actual_aruco_error_x]])*1000) -> 7.9 | BY2: =IF(sim_a[[#This Row],[fine_align_actual_aruco_error_y]]="","",ABS(sim_a[[#This Row],[fine_align_actual_aruco_error_y]])*1000) -> 25.1 | BZ2: =IF(sim_a[[#This Row],[fine_align_actual_aruco_yaw_error_deg]]="","",ABS(sim_a[[#This Row],[fine_align_actual_aruco_yaw_error_deg]])) -> 0.094 | CA2: =IF(sim_a[[#This Row],[fine_align_aruco_vs_actual_error_x]]="","",ABS(sim_a[[#This Row],[fine_align_aruco_vs_actual_error_x]])*1000) -> 0.1 | CB2: =IF(sim_a[[#This Row],[fine_align_aruco_vs_actual_error_y]]="","",ABS(sim_a[[#This Row],[fine_align_aruco_vs_actual_error_y]])*1000) -> 0.1 | CC2: =IF(sim_a[[#This Row],[fine_align_aruco_vs_actual_yaw_error_deg]]="","",ABS(sim_a[[#This Row],[fine_align_aruco_vs_actual_yaw_error_deg]])) -> 0.044
A3: 2 | B3: TRUE | E3: 261.538 | F3: 9.785 | G3: 261.535 | H3: 14.758 | I3: 127.565 | J3: 194.599 | K3: 168.358 | L3: 260.528 | M3: 5.2042 | N3: -0.0376 | O3: 0.341 | P3: 0 | Q3: 0.1092 | R3: -0.026 | S3: 0.0042 | T3: -0.0376 | U3: 0.0378 | V3: 0 | W3: 0.1092 | X3: 0.1092 | Y3: 75.39 | Z3: -0.002 | AA3: 0 | AB3: 0.48 | AC3: 5 | AD3: 0.0102 | AE3: -1.0453 | AF3: 0.019 | AG3: -0.0048 | AH3: -1.0453 | AI3: 1.0453 | AJ3: 0.019 | AK3: 0.0028 | AL3: 1.0453 | AM3: 0.461 | AN3: 127.563 | AO3: 0.007 | AP3: -0.025 | AQ3: -0.18 | AR3: 10 | AS3: 0.0068 | AT3: -0.0251 | AU3: -0.261 | AV3: 0.0068 | AW3: -0.0251 | AX3: 0.026 | AY3: -0.261 | AZ3: 0.0002 | BA3: 0.0001 | BB3: 0.081 | BE3: [python3-22] [INFO] [1783093351.359922148] [nav2_trolley_mission_controller]: Local target 'return lane above drop zones' reached. | BF3: =IF(sim_a[[#This Row],[final_trolley_dropoff_error_x]]="","",ABS(sim_a[[#This Row],[final_trolley_dropoff_error_x]])*1000) -> 4.2 | BG3: =IF(sim_a[[#This Row],[final_trolley_dropoff_error_y]]="","",ABS(sim_a[[#This Row],[final_trolley_dropoff_error_y]])*1000) -> 37.6 | BH3: =IF(sim_a[[#This Row],[final_trolley_dropoff_error_dist]]="","",sim_a[[#This Row],[final_trolley_dropoff_error_dist]]*1000) -> 37.8 | BI3: =IF(sim_a[[#This Row],[final_robot_charging_error_x]]="","",ABS(sim_a[[#This Row],[final_robot_charging_error_x]])*1000) -> 0 | BJ3: =IF(sim_a[[#This Row],[final_robot_charging_error_y]]="","",ABS(sim_a[[#This Row],[final_robot_charging_error_y]])*1000) -> 109.2 | BK3: =IF(sim_a[[#This Row],[final_robot_charging_error_dist]]="","",sim_a[[#This Row],[final_robot_charging_error_dist]]*1000) -> 109.2 | BL3: =IF(sim_a[[#This Row],[side_align_aruco_est_error_x]]="","",ABS(sim_a[[#This Row],[side_align_aruco_est_error_x]])*1000) -> 2 | BM3: =IF(sim_a[[#This Row],[side_align_aruco_est_error_y]]="","",ABS(sim_a[[#This Row],[side_align_aruco_est_error_y]])*1000) -> 0 | BN3: =IF(sim_a[[#This Row],[side_align_aruco_est_yaw_error_deg]]="","",ABS(sim_a[[#This Row],[side_align_aruco_est_yaw_error_deg]])) -> 0.48 | BO3: =IF(sim_a[[#This Row],[side_align_actual_aruco_error_x]]="","",ABS(sim_a[[#This Row],[side_align_actual_aruco_error_x]])*1000) -> 4.8 | BP3: =IF(sim_a[[#This Row],[side_align_actual_aruco_error_y]]="","",ABS(sim_a[[#This Row],[side_align_actual_aruco_error_y]])*1000) -> 1045.3 | BQ3: =IF(sim_a[[#This Row],[side_align_actual_aruco_yaw_error_deg]]="","",ABS(sim_a[[#This Row],[side_align_actual_aruco_yaw_error_deg]])) -> 0.019 | BR3: =IF(sim_a[[#This Row],[side_align_aruco_vs_actual_error_x]]="","",ABS(sim_a[[#This Row],[side_align_aruco_vs_actual_error_x]])*1000) -> 2.8 | BS3: =IF(sim_a[[#This Row],[side_align_aruco_vs_actual_error_y]]="","",ABS(sim_a[[#This Row],[side_align_aruco_vs_actual_error_y]])*1000) -> 1045.3 | BT3: =IF(sim_a[[#This Row],[side_align_aruco_vs_actual_yaw_error_deg]]="","",ABS(sim_a[[#This Row],[side_align_aruco_vs_actual_yaw_error_deg]])) -> 0.461 | BU3: =IF(sim_a[[#This Row],[fine_align_aruco_est_error_x]]="","",ABS(sim_a[[#This Row],[fine_align_aruco_est_error_x]])*1000) -> 7 | BV3: =IF(sim_a[[#This Row],[fine_align_aruco_est_error_y]]="","",ABS(sim_a[[#This Row],[fine_align_aruco_est_error_y]])*1000) -> 25 | BW3: =IF(sim_a[[#This Row],[fine_align_aruco_est_yaw_error_deg]]="","",ABS(sim_a[[#This Row],[fine_align_aruco_est_yaw_error_deg]])) -> 0.18 | BX3: =IF(sim_a[[#This Row],[fine_align_actual_aruco_error_x]]="","",ABS(sim_a[[#This Row],[fine_align_actual_aruco_error_x]])*1000) -> 6.8 | BY3: =IF(sim_a[[#This Row],[fine_align_actual_aruco_error_y]]="","",ABS(sim_a[[#This Row],[fine_align_actual_aruco_error_y]])*1000) -> 25.1 | BZ3: =IF(sim_a[[#This Row],[fine_align_actual_aruco_yaw_error_deg]]="","",ABS(sim_a[[#This Row],[fine_align_actual_aruco_yaw_error_deg]])) -> 0.261 | CA3: =IF(sim_a[[#This Row],[fine_align_aruco_vs_actual_error_x]]="","",ABS(sim_a[[#This Row],[fine_align_aruco_vs_actual_error_x]])*1000) -> 0.2 | CB3: =IF(sim_a[[#This Row],[fine_align_aruco_vs_actual_error_y]]="","",ABS(sim_a[[#This Row],[fine_align_aruco_vs_actual_error_y]])*1000) -> 0.1 | CC3: =IF(sim_a[[#This Row],[fine_align_aruco_vs_actual_yaw_error_deg]]="","",ABS(sim_a[[#This Row],[fine_align_aruco_vs_actual_yaw_error_deg]])) -> 0.081
A4: 3 | B4: TRUE | E4: 265.001 | F4: 9.735 | G4: 264.999 | H4: 12.156 | I4: 127.807 | J4: 198.572 | K4: 168.802 | L4: 263.991 | M4: 5.1867 | N4: -0.0298 | O4: -2.993 | P4: 0.001 | Q4: 0.1072 | R4: -0.235 | S4: -0.0133 | T4: -0.0298 | U4: 0.0327 | V4: 0.001 | W4: 0.1072 | X4: 0.1072 | Y4: 75.209 | Z4: -0.001 | AA4: 0 | AB4: -0.12 | AC4: 6 | AD4: 0.0085 | AE4: -1.0553 | AF4: 0.512 | AG4: -0.0065 | AH4: -1.0553 | AI4: 1.0553 | AJ4: 0.512 | AK4: 0.0055 | AL4: 1.0553 | AM4: -0.632 | AN4: 127.754 | AO4: -0.007 | AP4: -0.025 | AQ4: 0 | AR4: 11 | AS4: -0.0065 | AT4: -0.0252 | AU4: -0.098 | AV4: -0.0065 | AW4: -0.0252 | AX4: 0.0261 | AY4: -0.098 | AZ4: -0.0005 | BA4: 0.0002 | BB4: 0.098 | BE4: [python3-22] [INFO] [1783093621.465201077] [nav2_trolley_mission_controller]: Local target 'return lane above drop zones' reached. | BF4: =IF(sim_a[[#This Row],[final_trolley_dropoff_error_x]]="","",ABS(sim_a[[#This Row],[final_trolley_dropoff_error_x]])*1000) -> 13.3 | BG4: =IF(sim_a[[#This Row],[final_trolley_dropoff_error_y]]="","",ABS(sim_a[[#This Row],[final_trolley_dropoff_error_y]])*1000) -> 29.8 | BH4: =IF(sim_a[[#This Row],[final_trolley_dropoff_error_dist]]="","",sim_a[[#This Row],[final_trolley_dropoff_error_dist]]*1000) -> 32.7 | BI4: =IF(sim_a[[#This Row],[final_robot_charging_error_x]]="","",ABS(sim_a[[#This Row],[final_robot_charging_error_x]])*1000) -> 1 | BJ4: =IF(sim_a[[#This Row],[final_robot_charging_error_y]]="","",ABS(sim_a[[#This Row],[final_robot_charging_error_y]])*1000) -> 107.2 | BK4: =IF(sim_a[[#This Row],[final_robot_charging_error_dist]]="","",sim_a[[#This Row],[final_robot_charging_error_dist]]*1000) -> 107.2 | BL4: =IF(sim_a[[#This Row],[side_align_aruco_est_error_x]]="","",ABS(sim_a[[#This Row],[side_align_aruco_est_error_x]])*1000) -> 1 | BM4: =IF(sim_a[[#This Row],[side_align_aruco_est_error_y]]="","",ABS(sim_a[[#This Row],[side_align_aruco_est_error_y]])*1000) -> 0 | BN4: =IF(sim_a[[#This Row],[side_align_aruco_est_yaw_error_deg]]="","",ABS(sim_a[[#This Row],[side_align_aruco_est_yaw_error_deg]])) -> 0.12 | BO4: =IF(sim_a[[#This Row],[side_align_actual_aruco_error_x]]="","",ABS(sim_a[[#This Row],[side_align_actual_aruco_error_x]])*1000) -> 6.5 | BP4: =IF(sim_a[[#This Row],[side_align_actual_aruco_error_y]]="","",ABS(sim_a[[#This Row],[side_align_actual_aruco_error_y]])*1000) -> 1055.3 | BQ4: =IF(sim_a[[#This Row],[side_align_actual_aruco_yaw_error_deg]]="","",ABS(sim_a[[#This Row],[side_align_actual_aruco_yaw_error_deg]])) -> 0.512 | BR4: =IF(sim_a[[#This Row],[side_align_aruco_vs_actual_error_x]]="","",ABS(sim_a[[#This Row],[side_align_aruco_vs_actual_error_x]])*1000) -> 5.5 | BS4: =IF(sim_a[[#This Row],[side_align_aruco_vs_actual_error_y]]="","",ABS(sim_a[[#This Row],[side_align_aruco_vs_actual_error_y]])*1000) -> 1055.3 | BT4: =IF(sim_a[[#This Row],[side_align_aruco_vs_actual_yaw_error_deg]]="","",ABS(sim_a[[#This Row],[side_align_aruco_vs_actual_yaw_error_deg]])) -> 0.632 | BU4: =IF(sim_a[[#This Row],[fine_align_aruco_est_error_x]]="","",ABS(sim_a[[#This Row],[fine_align_aruco_est_error_x]])*1000) -> 7 | BV4: =IF(sim_a[[#This Row],[fine_align_aruco_est_error_y]]="","",ABS(sim_a[[#This Row],[fine_align_aruco_est_error_y]])*1000) -> 25 | BW4: =IF(sim_a[[#This Row],[fine_align_aruco_est_yaw_error_deg]]="","",ABS(sim_a[[#This Row],[fine_align_aruco_est_yaw_error_deg]])) -> 0 | BX4: =IF(sim_a[[#This Row],[fine_align_actual_aruco_error_x]]="","",ABS(sim_a[[#This Row],[fine_align_actual_aruco_error_x]])*1000) -> 6.5 | BY4: =IF(sim_a[[#This Row],[fine_align_actual_aruco_error_y]]="","",ABS(sim_a[[#This Row],[fine_align_actual_aruco_error_y]])*1000) -> 25.2 | BZ4: =IF(sim_a[[#This Row],[fine_align_actual_aruco_yaw_error_deg]]="","",ABS(sim_a[[#This Row],[fine_align_actual_aruco_yaw_error_deg]])) -> 0.098 | CA4: =IF(sim_a[[#This Row],[fine_align_aruco_vs_actual_error_x]]="","",ABS(sim_a[[#This Row],[fine_align_aruco_vs_actual_error_x]])*1000) -> 0.5 | CB4: =IF(sim_a[[#This Row],[fine_align_aruco_vs_actual_error_y]]="","",ABS(sim_a[[#This Row],[fine_align_aruco_vs_actual_error_y]])*1000) -> 0.2 | CC4: =IF(sim_a[[#This Row],[fine_align_aruco_vs_actual_yaw_error_deg]]="","",ABS(sim_a[[#This Row],[fine_align_aruco_vs_actual_yaw_error_deg]])) -> 0.098
A5: 4 | B5: FALSE | C5: local_target_timeout | D5: [python3-22] [ERROR] [1783093847.752841244] [nav2_trolley_mission_controller]: Local target 'drop-off center' timed out: distance=0.029, yaw=+5.26 deg | E5: 215.213 | F5: 9.789 | H5: 17.462 | I5: 131.306 | K5: 175.62 | M5: 5.1943 | N5: 0.0048 | O5: -5.484 | P5: 5.2026 | Q5: 0.0291 | R5: -5.265 | S5: -0.0057 | T5: 0.0048 | U5: 0.0074 | V5: 5.2026 | W5: 0.0291 | X5: 5.2027 | Y5: 79.209 | Z5: 0 | AA5: 0 | AB5: -0.8 | AC5: 6 | AD5: 0.0144 | AE5: -1.0524 | AF5: 0.817 | AG5: -0.0006 | AH5: -1.0524 | AI5: 1.0524 | AJ5: 0.817 | AK5: 0.0006 | AL5: 1.0524 | AM5: -1.617 | AN5: 131.254 | AO5: -0.006 | AP5: -0.025 | AQ5: -0.1 | AR5: 11 | AS5: -0.006 | AT5: -0.025 | AU5: -0.219 | AV5: -0.006 | AW5: -0.025 | AX5: 0.0257 | AY5: -0.219 | AZ5: 0 | BA5: 0 | BB5: 0.119 | BE5: [python3-23] [INFO] [1783093847.753690416] [holonomic_goal_controller]: Holonomic lidar ignore radius set to 0.00 m. | BF5: =IF(sim_a[[#This Row],[final_trolley_dropoff_error_x]]="","",ABS(sim_a[[#This Row],[final_trolley_dropoff_error_x]])*1000) -> 5.7 | BG5: =IF(sim_a[[#This Row],[final_trolley_dropoff_error_y]]="","",ABS(sim_a[[#This Row],[final_trolley_dropoff_error_y]])*1000) -> 4.8 | BH5: =IF(sim_a[[#This Row],[final_trolley_dropoff_error_dist]]="","",sim_a[[#This Row],[final_trolley_dropoff_error_dist]]*1000) -> 7.4 | BI5: =IF(sim_a[[#This Row],[final_robot_charging_error_x]]="","",ABS(sim_a[[#This Row],[final_robot_charging_error_x]])*1000) -> 5202.6 | BJ5: =IF(sim_a[[#This Row],[final_robot_charging_error_y]]="","",ABS(sim_a[[#This Row],[final_robot_charging_error_y]])*1000) -> 29.1 | BK5: =IF(sim_a[[#This Row],[final_robot_charging_error_dist]]="","",sim_a[[#This Row],[final_robot_charging_error_dist]]*1000) -> 5202.7 | BL5: =IF(sim_a[[#This Row],[side_align_aruco_est_error_x]]="","",ABS(sim_a[[#This Row],[side_align_aruco_est_error_x]])*1000) -> 0 | BM5: =IF(sim_a[[#This Row],[side_align_aruco_est_error_y]]="","",ABS(sim_a[[#This Row],[side_align_aruco_est_error_y]])*1000) -> 0 | BN5: =IF(sim_a[[#This Row],[side_align_aruco_est_yaw_error_deg]]="","",ABS(sim_a[[#This Row],[side_align_aruco_est_yaw_error_deg]])) -> 0.8 | BO5: =IF(sim_a[[#This Row],[side_align_actual_aruco_error_x]]="","",ABS(sim_a[[#This Row],[side_align_actual_aruco_error_x]])*1000) -> 0.6 | BP5: =IF(sim_a[[#This Row],[side_align_actual_aruco_error_y]]="","",ABS(sim_a[[#This Row],[side_align_actual_aruco_error_y]])*1000) -> 1052.4 | BQ5: =IF(sim_a[[#This Row],[side_align_actual_aruco_yaw_error_deg]]="","",ABS(sim_a[[#This Row],[side_align_actual_aruco_yaw_error_deg]])) -> 0.817 | BR5: =IF(sim_a[[#This Row],[side_align_aruco_vs_actual_error_x]]="","",ABS(sim_a[[#This Row],[side_align_aruco_vs_actual_error_x]])*1000) -> 0.6 | BS5: =IF(sim_a[[#This Row],[side_align_aruco_vs_actual_error_y]]="","",ABS(sim_a[[#This Row],[side_align_aruco_vs_actual_error_y]])*1000) -> 1052.4 | BT5: =IF(sim_a[[#This Row],[side_align_aruco_vs_actual_yaw_error_deg]]="","",ABS(sim_a[[#This Row],[side_align_aruco_vs_actual_yaw_error_deg]])) -> 1.617 | BU5: =IF(sim_a[[#This Row],[fine_align_aruco_est_error_x]]="","",ABS(sim_a[[#This Row],[fine_align_aruco_est_error_x]])*1000) -> 6 | BV5: =IF(sim_a[[#This Row],[fine_align_aruco_est_error_y]]="","",ABS(sim_a[[#This Row],[fine_align_aruco_est_error_y]])*1000) -> 25 | BW5: =IF(sim_a[[#This Row],[fine_align_aruco_est_yaw_error_deg]]="","",ABS(sim_a[[#This Row],[fine_align_aruco_est_yaw_error_deg]])) -> 0.1 | BX5: =IF(sim_a[[#This Row],[fine_align_actual_aruco_error_x]]="","",ABS(sim_a[[#This Row],[fine_align_actual_aruco_error_x]])*1000) -> 6 | BY5: =IF(sim_a[[#This Row],[fine_align_actual_aruco_error_y]]="","",ABS(sim_a[[#This Row],[fine_align_actual_aruco_error_y]])*1000) -> 25 | BZ5: =IF(sim_a[[#This Row],[fine_align_actual_aruco_yaw_error_deg]]="","",ABS(sim_a[[#This Row],[fine_align_actual_aruco_yaw_error_deg]])) -> 0.219 | CA5: =IF(sim_a[[#This Row],[fine_align_aruco_vs_actual_error_x]]="","",ABS(sim_a[[#This Row],[fine_align_aruco_vs_actual_error_x]])*1000) -> 0 | CB5: =IF(sim_a[[#This Row],[fine_align_aruco_vs_actual_error_y]]="","",ABS(sim_a[[#This Row],[fine_align_aruco_vs_actual_error_y]])*1000) -> 0 | CC5: =IF(sim_a[[#This Row],[fine_align_aruco_vs_actual_yaw_error_deg]]="","",ABS(sim_a[[#This Row],[fine_align_aruco_vs_actual_yaw_error_deg]])) -> 0.119
A6: 5 | B6: FALSE | C6: local_target_timeout | D6: [python3-22] [ERROR] [1783094053.707800312] [nav2_trolley_mission_controller]: Local target 'drop-off center' timed out: distance=0.028, yaw=+1.86 deg | E6: 205.101 | F6: 9.884 | H6: 12.05 | I6: 125.726 | K6: 165.662 | M6: 5.1949 | N6: 0.0026 | O6: -1.987 | P6: 5.2009 | Q6: 0.0276 | R6: -1.859 | S6: -0.0051 | T6: 0.0026 | U6: 0.0057 | V6: 5.2009 | W6: 0.0276 | X6: 5.201 | Y6: 74.643 | Z6: -0.001 | AA6: 0 | AB6: -0.96 | AC6: 6 | AD6: 0.0147 | AE6: -1.0558 | AF6: 0.191 | AG6: -0.0003 | AH6: -1.0558 | AI6: 1.0558 | AJ6: 0.191 | AK6: -0.0007 | AL6: 1.0558 | AM6: -1.151 | AN6: 125.724 | AO6: -0.005 | AP6: -0.025 | AQ6: -0.03 | AR6: 11 | AS6: -0.0052 | AT6: -0.0251 | AU6: -0.128 | AV6: -0.0052 | AW6: -0.0251 | AX6: 0.0256 | AY6: -0.128 | AZ6: 0.0002 | BA6: 0.0001 | BB6: 0.098 | BE6: [python3-23] [INFO] [1783094053.708565484] [holonomic_goal_controller]: Holonomic lidar ignore radius set to 0.00 m. | BF6: =IF(sim_a[[#This Row],[final_trolley_dropoff_error_x]]="","",ABS(sim_a[[#This Row],[final_trolley_dropoff_error_x]])*1000) -> 5.1 | BG6: =IF(sim_a[[#This Row],[final_trolley_dropoff_error_y]]="","",ABS(sim_a[[#This Row],[final_trolley_dropoff_error_y]])*1000) -> 2.6 | BH6: =IF(sim_a[[#This Row],[final_trolley_dropoff_error_dist]]="","",sim_a[[#This Row],[final_trolley_dropoff_error_dist]]*1000) -> 5.7 | BI6: =IF(sim_a[[#This Row],[final_robot_charging_error_x]]="","",ABS(sim_a[[#This Row],[final_robot_charging_error_x]])*1000) -> 5200.9 | BJ6: =IF(sim_a[[#This Row],[final_robot_charging_error_y]]="","",ABS(sim_a[[#This Row],[final_robot_charging_error_y]])*1000) -> 27.6 | BK6: =IF(sim_a[[#This Row],[final_robot_charging_error_dist]]="","",sim_a[[#This Row],[final_robot_charging_error_dist]]*1000) -> 5201 | BL6: =IF(sim_a[[#This Row],[side_align_aruco_est_error_x]]="","",ABS(sim_a[[#This Row],[side_align_aruco_est_error_x]])*1000) -> 1 | BM6: =IF(sim_a[[#This Row],[side_align_aruco_est_error_y]]="","",ABS(sim_a[[#This Row],[side_align_aruco_est_error_y]])*1000) -> 0 | BN6: =IF(sim_a[[#This Row],[side_align_aruco_est_yaw_error_deg]]="","",ABS(sim_a[[#This Row],[side_align_aruco_est_yaw_error_deg]])) -> 0.96 | BO6: =IF(sim_a[[#This Row],[side_align_actual_aruco_error_x]]="","",ABS(sim_a[[#This Row],[side_align_actual_aruco_error_x]])*1000) -> 0.3 | BP6: =IF(sim_a[[#This Row],[side_align_actual_aruco_error_y]]="","",ABS(sim_a[[#This Row],[side_align_actual_aruco_error_y]])*1000) -> 1055.8 | BQ6: =IF(sim_a[[#This Row],[side_align_actual_aruco_yaw_error_deg]]="","",ABS(sim_a[[#This Row],[side_align_actual_aruco_yaw_error_deg]])) -> 0.191 | BR6: =IF(sim_a[[#This Row],[side_align_aruco_vs_actual_error_x]]="","",ABS(sim_a[[#This Row],[side_align_aruco_vs_actual_error_x]])*1000) -> 0.7 | BS6: =IF(sim_a[[#This Row],[side_align_aruco_vs_actual_error_y]]="","",ABS(sim_a[[#This Row],[side_align_aruco_vs_actual_error_y]])*1000) -> 1055.8 | BT6: =IF(sim_a[[#This Row],[side_align_aruco_vs_actual_yaw_error_deg]]="","",ABS(sim_a[[#This Row],[side_align_aruco_vs_actual_yaw_error_deg]])) -> 1.151 | BU6: =IF(sim_a[[#This Row],[fine_align_aruco_est_error_x]]="","",ABS(sim_a[[#This Row],[fine_align_aruco_est_error_x]])*1000) -> 5 | BV6: =IF(sim_a[[#This Row],[fine_align_aruco_est_error_y]]="","",ABS(sim_a[[#This Row],[fine_align_aruco_est_error_y]])*1000) -> 25 | BW6: =IF(sim_a[[#This Row],[fine_align_aruco_est_yaw_error_deg]]="","",ABS(sim_a[[#This Row],[fine_align_aruco_est_yaw_error_deg]])) -> 0.03 | BX6: =IF(sim_a[[#This Row],[fine_align_actual_aruco_error_x]]="","",ABS(sim_a[[#This Row],[fine_align_actual_aruco_error_x]])*1000) -> 5.2 | BY6: =IF(sim_a[[#This Row],[fine_align_actual_aruco_error_y]]="","",ABS(sim_a[[#This Row],[fine_align_actual_aruco_error_y]])*1000) -> 25.1 | BZ6: =IF(sim_a[[#This Row],[fine_align_actual_aruco_yaw_error_deg]]="","",ABS(sim_a[[#This Row],[fine_align_actual_aruco_yaw_error_deg]])) -> 0.128 | CA6: =IF(sim_a[[#This Row],[fine_align_aruco_vs_actual_error_x]]="","",ABS(sim_a[[#This Row],[fine_align_aruco_vs_actual_error_x]])*1000) -> 0.2 | CB6: =IF(sim_a[[#This Row],[fine_align_aruco_vs_actual_error_y]]="","",ABS(sim_a[[#This Row],[fine_align_aruco_vs_actual_error_y]])*1000) -> 0.1 | CC6: =IF(sim_a[[#This Row],[fine_align_aruco_vs_actual_yaw_error_deg]]="","",ABS(sim_a[[#This Row],[fine_align_aruco_vs_actual_yaw_error_deg]])) -> 0.098
A7: 6 | B7: TRUE | E7: 258.71 | F7: 9.885 | G7: 258.708 | H7: 14.411 | I7: 125.082 | J7: 191.971 | K7: 165.023 | L7: 257.701 | M7: 5.209 | N7: -0.075 | O7: 6.74 | P7: -0.0001 | Q7: 0.1063 | R7: 0.01 | S7: 0.009 | T7: -0.075 | U7: 0.0756 | V7: -0.0001 | W7: 0.1063 | X7: 0.1063 | Y7: 74.189 | Z7: 0.008 | AA7: 0 | AB7: 0.17 | AC7: 6 | AD7: 0.0125 | AE7: -1.0523 | AF7: -0.157 | AG7: -0.0025 | AH7: -1.0523 | AI7: 1.0523 | AJ7: -0.157 | AK7: 0.0105 | AL7: 1.0523 | AM7: 0.327 | AN7: 125.029 | AO7: 0.007 | AP7: -0.025 | AQ7: -0.1 | AR7: 10 | AS7: 0.0063 | AT7: -0.0251 | AU7: -0.168 | AV7: 0.0063 | AW7: -0.0251 | AX7: 0.0258 | AY7: -0.168 | AZ7: 0.0007 | BA7: 0.0001 | BB7: 0.068 | BE7: [python3-22] [INFO] [1783094302.881573410] [nav2_trolley_mission_controller]: Local target 'return lane above drop zones' reached. | BF7: =IF(sim_a[[#This Row],[final_trolley_dropoff_error_x]]="","",ABS(sim_a[[#This Row],[final_trolley_dropoff_error_x]])*1000) -> 9 | BG7: =IF(sim_a[[#This Row],[final_trolley_dropoff_error_y]]="","",ABS(sim_a[[#This Row],[final_trolley_dropoff_error_y]])*1000) -> 75 | BH7: =IF(sim_a[[#This Row],[final_trolley_dropoff_error_dist]]="","",sim_a[[#This Row],[final_trolley_dropoff_error_dist]]*1000) -> 75.6 | BI7: =IF(sim_a[[#This Row],[final_robot_charging_error_x]]="","",ABS(sim_a[[#This Row],[final_robot_charging_error_x]])*1000) -> 0.1 | BJ7: =IF(sim_a[[#This Row],[final_robot_charging_error_y]]="","",ABS(sim_a[[#This Row],[final_robot_charging_error_y]])*1000) -> 106.3 | BK7: =IF(sim_a[[#This Row],[final_robot_charging_error_dist]]="","",sim_a[[#This Row],[final_robot_charging_error_dist]]*1000) -> 106.3 | BL7: =IF(sim_a[[#This Row],[side_align_aruco_est_error_x]]="","",ABS(sim_a[[#This Row],[side_align_aruco_est_error_x]])*1000) -> 8 | BM7: =IF(sim_a[[#This Row],[side_align_aruco_est_error_y]]="","",ABS(sim_a[[#This Row],[side_align_aruco_est_error_y]])*1000) -> 0 | BN7: =IF(sim_a[[#This Row],[side_align_aruco_est_yaw_error_deg]]="","",ABS(sim_a[[#This Row],[side_align_aruco_est_yaw_error_deg]])) -> 0.17 | BO7: =IF(sim_a[[#This Row],[side_align_actual_aruco_error_x]]="","",ABS(sim_a[[#This Row],[side_align_actual_aruco_error_x]])*1000) -> 2.5 | BP7: =IF(sim_a[[#This Row],[side_align_actual_aruco_error_y]]="","",ABS(sim_a[[#This Row],[side_align_actual_aruco_error_y]])*1000) -> 1052.3 | BQ7: =IF(sim_a[[#This Row],[side_align_actual_aruco_yaw_error_deg]]="","",ABS(sim_a[[#This Row],[side_align_actual_aruco_yaw_error_deg]])) -> 0.157 | BR7: =IF(sim_a[[#This Row],[side_align_aruco_vs_actual_error_x]]="","",ABS(sim_a[[#This Row],[side_align_aruco_vs_actual_error_x]])*1000) -> 10.5 | BS7: =IF(sim_a[[#This Row],[side_align_aruco_vs_actual_error_y]]="","",ABS(sim_a[[#This Row],[side_align_aruco_vs_actual_error_y]])*1000) -> 1052.3 | BT7: =IF(sim_a[[#This Row],[side_align_aruco_vs_actual_yaw_error_deg]]="","",ABS(sim_a[[#This Row],[side_align_aruco_vs_actual_yaw_error_deg]])) -> 0.327 | BU7: =IF(sim_a[[#This Row],[fine_align_aruco_est_error_x]]="","",ABS(sim_a[[#This Row],[fine_align_aruco_est_error_x]])*1000) -> 7 | BV7: =IF(sim_a[[#This Row],[fine_align_aruco_est_error_y]]="","",ABS(sim_a[[#This Row],[fine_align_aruco_est_error_y]])*1000) -> 25 | BW7: =IF(sim_a[[#This Row],[fine_align_aruco_est_yaw_error_deg]]="","",ABS(sim_a[[#This Row],[fine_align_aruco_est_yaw_error_deg]])) -> 0.1 | BX7: =IF(sim_a[[#This Row],[fine_align_actual_aruco_error_x]]="","",ABS(sim_a[[#This Row],[fine_align_actual_aruco_error_x]])*1000) -> 6.3 | BY7: =IF(sim_a[[#This Row],[fine_align_actual_aruco_error_y]]="","",ABS(sim_a[[#This Row],[fine_align_actual_aruco_error_y]])*1000) -> 25.1 | BZ7: =IF(sim_a[[#This Row],[fine_align_actual_aruco_yaw_error_deg]]="","",ABS(sim_a[[#This Row],[fine_align_actual_aruco_yaw_error_deg]])) -> 0.168 | CA7: =IF(sim_a[[#This Row],[fine_align_aruco_vs_actual_error_x]]="","",ABS(sim_a[[#This Row],[fine_align_aruco_vs_actual_error_x]])*1000) -> 0.7 | CB7: =IF(sim_a[[#This Row],[fine_align_aruco_vs_actual_error_y]]="","",ABS(sim_a[[#This Row],[fine_align_aruco_vs_actual_error_y]])*1000) -> 0.1 | CC7: =IF(sim_a[[#This Row],[fine_align_aruco_vs_actual_yaw_error_deg]]="","",ABS(sim_a[[#This Row],[fine_align_aruco_vs_actual_yaw_error_deg]])) -> 0.068
A8: 7 | B8: TRUE | E8: 266.349 | F8: 9.84 | G8: 266.346 | H8: 12.006 | I8: 128.332 | J8: 199.37 | K8: 169.133 | L8: 265.338 | M8: 5.1966 | N8: -0.0322 | O8: -1.472 | P8: 0.0009 | Q8: 0.11 | R8: -0.28 | S8: -0.0034 | T8: -0.0322 | U8: 0.0324 | V8: 0.0009 | W8: 0.11 | X8: 0.11 | Y8: 74.642 | Z8: 0.006 | AA8: 0 | AB8: -0.45 | AC8: 6 | AD8: 0.0169 | AE8: -1.0532 | AF8: -0.057 | AG8: 0.0019 | AH8: -1.0532 | AI8: 1.0532 | AJ8: -0.057 | AK8: 0.0041 | AL8: 1.0532 | AM8: -0.393 | AN8: 128.33 | AO8: 0.005 | AP8: -0.025 | AQ8: -0.06 | AR8: 10 | AS8: 0.0053 | AT8: -0.0249 | AU8: -0.164 | AV8: 0.0053 | AW8: -0.0249 | AX8: 0.0255 | AY8: -0.164 | AZ8: -0.0003 | BA8: -0.0001 | BB8: 0.104 | BE8: [planner_server-16] [INFO] [1783094573.434418557] [global_costmap.global_costmap]: StaticLayer: Resizing costmap to 158 X 118 at 0.050000 m/pix | BF8: =IF(sim_a[[#This Row],[final_trolley_dropoff_error_x]]="","",ABS(sim_a[[#This Row],[final_trolley_dropoff_error_x]])*1000) -> 3.4 | BG8: =IF(sim_a[[#This Row],[final_trolley_dropoff_error_y]]="","",ABS(sim_a[[#This Row],[final_trolley_dropoff_error_y]])*1000) -> 32.2 | BH8: =IF(sim_a[[#This Row],[final_trolley_dropoff_error_dist]]="","",sim_a[[#This Row],[final_trolley_dropoff_error_dist]]*1000) -> 32.4 | BI8: =IF(sim_a[[#This Row],[final_robot_charging_error_x]]="","",ABS(sim_a[[#This Row],[final_robot_charging_error_x]])*1000) -> 0.9 | BJ8: =IF(sim_a[[#This Row],[final_robot_charging_error_y]]="","",ABS(sim_a[[#This Row],[final_robot_charging_error_y]])*1000) -> 110 | BK8: =IF(sim_a[[#This Row],[final_robot_charging_error_dist]]="","",sim_a[[#This Row],[final_robot_charging_error_dist]]*1000) -> 110 | BL8: =IF(sim_a[[#This Row],[side_align_aruco_est_error_x]]="","",ABS(sim_a[[#This Row],[side_align_aruco_est_error_x]])*1000) -> 6 | BM8: =IF(sim_a[[#This Row],[side_align_aruco_est_error_y]]="","",ABS(sim_a[[#This Row],[side_align_aruco_est_error_y]])*1000) -> 0 | BN8: =IF(sim_a[[#This Row],[side_align_aruco_est_yaw_error_deg]]="","",ABS(sim_a[[#This Row],[side_align_aruco_est_yaw_error_deg]])) -> 0.45 | BO8: =IF(sim_a[[#This Row],[side_align_actual_aruco_error_x]]="","",ABS(sim_a[[#This Row],[side_align_actual_aruco_error_x]])*1000) -> 1.9 | BP8: =IF(sim_a[[#This Row],[side_align_actual_aruco_error_y]]="","",ABS(sim_a[[#This Row],[side_align_actual_aruco_error_y]])*1000) -> 1053.2 | BQ8: =IF(sim_a[[#This Row],[side_align_actual_aruco_yaw_error_deg]]="","",ABS(sim_a[[#This Row],[side_align_actual_aruco_yaw_error_deg]])) -> 0.057 | BR8: =IF(sim_a[[#This Row],[side_align_aruco_vs_actual_error_x]]="","",ABS(sim_a[[#This Row],[side_align_aruco_vs_actual_error_x]])*1000) -> 4.1 | BS8: =IF(sim_a[[#This Row],[side_align_aruco_vs_actual_error_y]]="","",ABS(sim_a[[#This Row],[side_align_aruco_vs_actual_error_y]])*1000) -> 1053.2 | BT8: =IF(sim_a[[#This Row],[side_align_aruco_vs_actual_yaw_error_deg]]="","",ABS(sim_a[[#This Row],[side_align_aruco_vs_actual_yaw_error_deg]])) -> 0.393 | BU8: =IF(sim_a[[#This Row],[fine_align_aruco_est_error_x]]="","",ABS(sim_a[[#This Row],[fine_align_aruco_est_error_x]])*1000) -> 5 | BV8: =IF(sim_a[[#This Row],[fine_align_aruco_est_error_y]]="","",ABS(sim_a[[#This Row],[fine_align_aruco_est_error_y]])*1000) -> 25 | BW8: =IF(sim_a[[#This Row],[fine_align_aruco_est_yaw_error_deg]]="","",ABS(sim_a[[#This Row],[fine_align_aruco_est_yaw_error_deg]])) -> 0.06 | BX8: =IF(sim_a[[#This Row],[fine_align_actual_aruco_error_x]]="","",ABS(sim_a[[#This Row],[fine_align_actual_aruco_error_x]])*1000) -> 5.3 | BY8: =IF(sim_a[[#This Row],[fine_align_actual_aruco_error_y]]="","",ABS(sim_a[[#This Row],[fine_align_actual_aruco_error_y]])*1000) -> 24.9 | BZ8: =IF(sim_a[[#This Row],[fine_align_actual_aruco_yaw_error_deg]]="","",ABS(sim_a[[#This Row],[fine_align_actual_aruco_yaw_error_deg]])) -> 0.164 | CA8: =IF(sim_a[[#This Row],[fine_align_aruco_vs_actual_error_x]]="","",ABS(sim_a[[#This Row],[fine_align_aruco_vs_actual_error_x]])*1000) -> 0.3 | CB8: =IF(sim_a[[#This Row],[fine_align_aruco_vs_actual_error_y]]="","",ABS(sim_a[[#This Row],[fine_align_aruco_vs_actual_error_y]])*1000) -> 0.1 | CC8: =IF(sim_a[[#This Row],[fine_align_aruco_vs_actual_yaw_error_deg]]="","",ABS(sim_a[[#This Row],[fine_align_aruco_vs_actual_yaw_error_deg]])) -> 0.104
A9: 8 | B9: TRUE | E9: 258.055 | F9: 9.837 | G9: 258.053 | H9: 13.258 | I9: 123.789 | J9: 191.223 | K9: 163.873 | L9: 257.046 | M9: 5.2059 | N9: -0.0395 | O9: -3.078 | P9: -0.0005 | Q9: 0.1031 | R9: 0.067 | S9: 0.0059 | T9: -0.0395 | U9: 0.04 | V9: -0.0005 | W9: 0.1031 | X9: 0.1031 | Y9: 73.504 | Z9: 0.005 | AA9: 0 | AB9: -0.74 | AC9: 6 | AD9: 0.0175 | AE9: -1.0422 | AF9: 0.373 | AG9: 0.0025 | AH9: -1.0422 | AI9: 1.0422 | AJ9: 0.373 | AK9: 0.0025 | AL9: 1.0422 | AM9: -1.113 | AN9: 123.735 | AO9: 0.007 | AP9: -0.025 | AQ9: -0.03 | AR9: 11 | AS9: 0.0065 | AT9: -0.0245 | AU9: -0.141 | AV9: 0.0065 | AW9: -0.0245 | AX9: 0.0253 | AY9: -0.141 | AZ9: 0.0005 | BA9: -0.0005 | BB9: 0.111 | BE9: [python3-22] [INFO] [1783094828.342074230] [nav2_trolley_mission_controller]: Local target 'return lane above drop zones' reached. | BF9: =IF(sim_a[[#This Row],[final_trolley_dropoff_error_x]]="","",ABS(sim_a[[#This Row],[final_trolley_dropoff_error_x]])*1000) -> 5.9 | BG9: =IF(sim_a[[#This Row],[final_trolley_dropoff_error_y]]="","",ABS(sim_a[[#This Row],[final_trolley_dropoff_error_y]])*1000) -> 39.5 | BH9: =IF(sim_a[[#This Row],[final_trolley_dropoff_error_dist]]="","",sim_a[[#This Row],[final_trolley_dropoff_error_dist]]*1000) -> 40 | BI9: =IF(sim_a[[#This Row],[final_robot_charging_error_x]]="","",ABS(sim_a[[#This Row],[final_robot_charging_error_x]])*1000) -> 0.5 | BJ9: =IF(sim_a[[#This Row],[final_robot_charging_error_y]]="","",ABS(sim_a[[#This Row],[final_robot_charging_error_y]])*1000) -> 103.1 | BK9: =IF(sim_a[[#This Row],[final_robot_charging_error_dist]]="","",sim_a[[#This Row],[final_robot_charging_error_dist]]*1000) -> 103.1 | BL9: =IF(sim_a[[#This Row],[side_align_aruco_est_error_x]]="","",ABS(sim_a[[#This Row],[side_align_aruco_est_error_x]])*1000) -> 5 | BM9: =IF(sim_a[[#This Row],[side_align_aruco_est_error_y]]="","",ABS(sim_a[[#This Row],[side_align_aruco_est_error_y]])*1000) -> 0 | BN9: =IF(sim_a[[#This Row],[side_align_aruco_est_yaw_error_deg]]="","",ABS(sim_a[[#This Row],[side_align_aruco_est_yaw_error_deg]])) -> 0.74 | BO9: =IF(sim_a[[#This Row],[side_align_actual_aruco_error_x]]="","",ABS(sim_a[[#This Row],[side_align_actual_aruco_error_x]])*1000) -> 2.5 | BP9: =IF(sim_a[[#This Row],[side_align_actual_aruco_error_y]]="","",ABS(sim_a[[#This Row],[side_align_actual_aruco_error_y]])*1000) -> 1042.2 | BQ9: =IF(sim_a[[#This Row],[side_align_actual_aruco_yaw_error_deg]]="","",ABS(sim_a[[#This Row],[side_align_actual_aruco_yaw_error_deg]])) -> 0.373 | BR9: =IF(sim_a[[#This Row],[side_align_aruco_vs_actual_error_x]]="","",ABS(sim_a[[#This Row],[side_align_aruco_vs_actual_error_x]])*1000) -> 2.5 | BS9: =IF(sim_a[[#This Row],[side_align_aruco_vs_actual_error_y]]="","",ABS(sim_a[[#This Row],[side_align_aruco_vs_actual_error_y]])*1000) -> 1042.2 | BT9: =IF(sim_a[[#This Row],[side_align_aruco_vs_actual_yaw_error_deg]]="","",ABS(sim_a[[#This Row],[side_align_aruco_vs_actual_yaw_error_deg]])) -> 1.113 | BU9: =IF(sim_a[[#This Row],[fine_align_aruco_est_error_x]]="","",ABS(sim_a[[#This Row],[fine_align_aruco_est_error_x]])*1000) -> 7 | BV9: =IF(sim_a[[#This Row],[fine_align_aruco_est_error_y]]="","",ABS(sim_a[[#This Row],[fine_align_aruco_est_error_y]])*1000) -> 25 | BW9: =IF(sim_a[[#This Row],[fine_align_aruco_est_yaw_error_deg]]="","",ABS(sim_a[[#This Row],[fine_align_aruco_est_yaw_error_deg]])) -> 0.03 | BX9: =IF(sim_a[[#This Row],[fine_align_actual_aruco_error_x]]="","",ABS(sim_a[[#This Row],[fine_align_actual_aruco_error_x]])*1000) -> 6.5 | BY9: =IF(sim_a[[#This Row],[fine_align_actual_aruco_error_y]]="","",ABS(sim_a[[#This Row],[fine_align_actual_aruco_error_y]])*1000) -> 24.5 | BZ9: =IF(sim_a[[#This Row],[fine_align_actual_aruco_yaw_error_deg]]="","",ABS(sim_a[[#This Row],[fine_align_actual_aruco_yaw_error_deg]])) -> 0.141 | CA9: =IF(sim_a[[#This Row],[fine_align_aruco_vs_actual_error_x]]="","",ABS(sim_a[[#This Row],[fine_align_aruco_vs_actual_error_x]])*1000) -> 0.5 | CB9: =IF(sim_a[[#This Row],[fine_align_aruco_vs_actual_error_y]]="","",ABS(sim_a[[#This Row],[fine_align_aruco_vs_actual_error_y]])*1000) -> 0.5 | CC9: =IF(sim_a[[#This Row],[fine_align_aruco_vs_actual_yaw_error_deg]]="","",ABS(sim_a[[#This Row],[fine_align_aruco_vs_actual_yaw_error_deg]])) -> 0.111
