Workbook

Sheet Handnotes
A1: count (y/n) | B1: Test | C1: Trolley orientation | D1: Type | E1: Side align | F1: Notes | G1: Check type | H1: Drive under | I1: notes | J1: fine align | K1: fine align extra light | L1: notes | M1: docking | N1: notes | O1: deliver | P1: drive out | Q1: return charging
A2: y | B2: 1 | C2: Normal | D2: Trash Trolley | E2: success | G2: correct | H2: success | J2: success | K2: NO | M2: success | O2: success | P2: success | Q2: success
A3: y | B3: 2 | C3: Normal | D3: Trash Trolley | E3: success | G3: correct | H3: success | J3: success | K3: NO | M3: success | O3: success | P3: success | Q3: success
A4: y | B4: 3 | C4: Flipped 180 deg | D4: Trash Trolley | E4: success | G4: correct | H4: success | J4: success | K4: YES | L4: too_dark_added light_new_fine_aling_try fine align with light worked but not exact enough | M4: unsuccessfull | N4: docking unsuccessfull_helped_docking | O4: success | P4: success | Q4: success
A5: y | B5: 4 | C5: Flipped 180 deg | D5: Laundry Trolley | E5: success | G5: correct | H5: success | J5: success | K5: NO | M5: success | O5: success | P5: success | Q5: success
A6: y | B6: 5 | C6: Flipped 180 deg | D6: Laundry Trolley | E6: success | G6: correct | H6: success | J6: unsuccessfull | K6: YES | L6: too_dark_added light_new_fine_aling_try | M6: unsuccessfull | N6: docking unsuccessfull_helped_docking | O6: success | P6: success | Q6: success
A7: y | B7: 6 | C7: Normal | D7: Laundry Trolley | E7: success | G7: correct | H7: success | J7: success | K7: NO | M7: success | O7: success | P7: success | Q7: success
A8: y | B8: 7 | C8: Normal | D8: Laundry Trolley | E8: success | G8: correct | H8: success | J8: success | K8: NO | M8: success | O8: success | P8: success | Q8: success
A10: y | B10: 9 | C10: Flipped 180 deg | D10: Trash Trolley | E10: success | G10: correct | H10: success | J10: success | K10: NO | M10: success | O10: success | P10: success | Q10: success
A13: y | B13: 12 | C13: Normal | D13: Trash Trolley | E13: partial | F13: needed retry | G13: correct | H13: success | J13: success | K13: NO | M13: success | O13: success | P13: success | Q13: success
A14: y | B14: 13 | C14: Normal | D14: Trash Trolley | E14: success | G14: correct | H14: success | J14: success | K14: YES | M14: success | O14: success | P14: success | Q14: success
A15: y | B15: 14 | C15: Normal | D15: Trash Trolley | E15: success | G15: correct | H15: unsuccessfull
A16: y | B16: 15 | C16: Normal | D16: Trash Trolley | E16: success | G16: correct | H16: success | J16: success | K16: NO | M16: success | O16: success | P16: success | Q16: success
A17: y | B17: 16 | C17: Flipped 180 deg | D17: Laundry Trolley | E17: unsuccessfull | F17: success on second2 | G17: correct | H17: success | I17: too far but did drive under | J17: unsuccessfull | K17: YES | M17: unsuccessfull
A18: y | B18: 17 | C18: Flipped 180 deg | D18: Laundry Trolley | E18: success | G18: correct | H18: success | I18: too far but did drive under | J18: success | K18: YES | L18: with light fine align but still not exact enough | M18: unsuccessfull | O18: success | P18: success | Q18: success
A19: y | B19: 18 | C19: Flipped 180 deg | D19: Laundry Trolley | E19: success | G19: correct | H19: success | J19: success | K19: YES | L19: after changing target value | M19: partial | O19: success | P19: success | Q19: success
A20: y | B20: 19 | C20: Flipped 180 deg | D20: Laundry Trolley | E20: partial | F20: needed retry/ move an centimeter | G20: correct | H20: success | J20: success | K20: YES | M20: success | O20: success | P20: success | Q20: success
A21: y | B21: 20 | C21: Normal | D21: Laundry Trolley | E21: partial | F21: needed retry/ drove to far | G21: correct | H21: success | J21: success | K21: YES | M21: success | O21: success | P21: success | Q21: success
F22: restart robot, aruko node crashed and goal pose got too unreliable
A23: y | B23: 21 | C23: Normal | D23: Laundry Trolley | E23: success | G23: correct | H23: success | J23: success | K23: YES | M23: success | O23: success | P23: success | Q23: success
A24: y | B24: 22 | C24: Normal | D24: Laundry Trolley | E24: unsuccessfull | F24: drove to far, corrected | G24: correct | H24: unsuccessful
A25: y | B25: 23 | C25: Normal | D25: Laundry Trolley | E25: success | G25: correct | H25: success | J25: partial | K25: YES | L25: wheels in way after moving wheel success | M25: partial | O25: unsuccessfull | P25: unsuccessfull
A26: y | B26: 24 | C26: Flipped 180 deg | D26: Trash Trolley | E26: success | G26: correct | H26: unsuccessfull | I26: f hit wheels
F27: cleaned wheels , two more aruco crashes --> fixed arucu node
A28: y | B28: 25 | C28: Flipped 180 deg | D28: Trash Trolley | E28: success | G28: correct | H28: success | J28: success | K28: YES | M28: success | O28: success | P28: success | Q28: success
A29: y | B29: 26 | C29: Flipped 180 deg | D29: Trash Trolley | E29: success | G29: correct | H29: success | J29: success | K29: YES | M29: success | O29: success | P29: success | Q29: success
A30: y | B30: 27 | C30: Flipped 180 deg | D30: Trash Trolley | E30: success | G30: correct | H30: success | J30: success | K30: YES | M30: success | O30: success | P30: success | Q30: success
A31: y | B31: 28 | C31: Normal | D31: Trash Trolley | E31: partial | F31: drove to far, corrected | G31: correct | H31: success | J31: success | K31: YES | M31: success | O31: success | P31: success | Q31: success
A32: y | B32: 29 | C32: Normal | D32: Trash Trolley | E32: success | G32: correct | H32: success | J32: success | K32: YES | M32: success | O32: success | P32: success | Q32: success
A33: y | B33: 30 | C33: Normal | D33: Trash Trolley | E33: success | G33: correct | H33: success | J33: success | K33: YES | M33: success | O33: success | P33: success | Q33: success
A34: y | B34: 31 | C34: Normal | D34: Trash Trolley | E34: success | G34: correct | H34: success | J34: success | K34: YES | L34: needed a second try | M34: partial | N34: needed second try | O34: success | P34: success | Q34: success
A35: y | B35: 32 | C35: Flipped 180 deg | D35: Laundry Trolley | E35: success | G35: correct | H35: success | J35: success | K35: YES | L35: needed a second try | M35: partial | N35: needed second try | O35: success | P35: success | Q35: success
A36: y | B36: 33 | C36: Flipped 180 deg | D36: Laundry Trolley | E36: success | G36: correct | H36: success | J36: unsuccessfull | K36: YES | M36: unsuccessfull | O36: success | P36: success | Q36: success
A37: n | B37: 34 | C37: Flipped 180 deg | D37: Laundry Trolley | E37: success | F37: aruco node died failed restart robot | G37: correct
A39: y | B39: 35 | C39: Flipped 180 deg | D39: Laundry Trolley | E39: success | G39: correct | H39: success | J39: success | K39: YES | M39: success | O39: success | P39: success | Q39: success
A40: y | B40: 36 | C40: Normal | D40: Laundry Trolley | E40: unsuccessfull | F40: needed more time (2ndcommand) | G40: correct | H40: unsuccessfull
A41: y | B41: 37 | C41: Normal | D41: Laundry Trolley | E41: success | G41: correct | H41: success | J41: success | K41: YES | M41: unsuccessfull | O41: success | P41: unsuccessfull
A42: y | B42: 38 | C42: Normal | D42: Laundry Trolley | E42: success | G42: correct | H42: unsuccessfull
A43: y | B43: 39 | C43: Normal | D43: Laundry Trolley | E43: success | G43: correct | H43: unsuccessfull | I43: f hit wheel | J43: partial | K43: YES | L43: succeded after restarting aruko node | M43: unsuccessfull
A44: y | B44: 40 | C44: Flipped 180 deg | D44: Trash Trolley | E44: success | G44: correct | H44: success | J44: unsuccessfull | K44: YES | M44: unsuccessfull
...

Sheet Event_logs
A1: Run Id Manual | B1: wall_time | C1: ros_time_sec | D1: run_id | E1: elapsed_sec | F1: event_type | G1: source | H1: label | I1: data
B2: 2026-06-19_13-35-38-302756 | C2: 1.7818689e+15 | D2: 20260619_133538 | E2: 0.000 | F2: run_start | G2: logger | H2: command_trolley_ready
B3: 2026-06-19_13-35-38-304263 | C3: 1.7818689e+15 | D3: 20260619_133538 | E3: 0.002 | F3: command | G3: trolley_command | H3: trolley_ready | I3: trolley_ready
B4: 2026-06-19_13-35-38-307258 | C4: 1.7818689e+15 | D4: 20260619_133538 | E4: 0.005 | F4: dropzone_status | G4: dropzone | H4: approach_goal_sent | I4: approach_goal_sent. Inspect the robot pose, then approve side alignment with: ros2 topic pub --once /trolley_command std_msgs/msg/String "{data: 'side_align'}"
B5: 2026-06-19_13-36-11-270822 | C5: 1.781869e+15 | D5: 20260619_133538 | E5: 32968 | F5: run_end | G5: logger | H5: auto_closed_before_command_trolley_ready
B6: 2026-06-19_13-36-11-272558 | C6: 1.781869e+15 | D6: 20260619_133611 | E6: 0.000 | F6: run_start | G6: logger | H6: command_trolley_ready
B7: 2026-06-19_13-36-11-273476 | C7: 1.781869e+15 | D7: 20260619_133611 | E7: 0.001 | F7: command | G7: trolley_command | H7: trolley_ready | I7: trolley_ready
B8: 2026-06-19_13-36-11-276228 | C8: 1.781869e+15 | D8: 20260619_133611 | E8: 0.004 | F8: dropzone_status | G8: dropzone | H8: approach_goal_sent | I8: approach_goal_sent. Inspect the robot pose, then approve side alignment with: ros2 topic pub --once /trolley_command std_msgs/msg/String "{data: 'side_align'}"
B9: 2026-06-19_13-37-08-194963 | C9: 1.781869e+15 | D9: 20260619_133611 | E9: 56923 | F9: run_end | G9: logger | H9: auto_closed_before_command_trolley_ready
A10: 1 | B10: 2026-06-19_13-37-08-197502 | C10: 1.781869e+15 | D10: 20260619_133708 | E10: 0.000 | F10: run_start | G10: logger | H10: command_trolley_ready
A11: 1 | B11: 2026-06-19_13-37-08-199036 | C11: 1.781869e+15 | D11: 20260619_133708 | E11: 0.002 | F11: command | G11: trolley_command | H11: trolley_ready | I11: trolley_ready
A12: 1 | B12: 2026-06-19_13-37-08-203294 | C12: 1.781869e+15 | D12: 20260619_133708 | E12: 0.006 | F12: dropzone_status | G12: dropzone | H12: approach_goal_sent | I12: approach_goal_sent. Inspect the robot pose, then approve side alignment with: ros2 topic pub --once /trolley_command std_msgs/msg/String "{data: 'side_align'}"
A13: 1 | B13: 2026-06-19_13-37-26-702925 | C13: 1.781869e+15 | D13: 20260619_133708 | E13: 18506 | F13: command | G13: trolley_command | H13: side_align | I13: side_align
A14: 1 | B14: 2026-06-19_13-37-26-708780 | C14: 1.781869e+15 | D14: 20260619_133708 | E14: 18511 | F14: dropzone_status | G14: dropzone | H14: status | I14: side_aligning via side_align_left. Waiting for side_align_left_done.
A15: 1 | B15: 2026-06-19_13-37-26-710258 | C15: 1.781869e+15 | D15: 20260619_133708 | E15: 18513 | F15: physical_status | G15: physical_alignment | H15: status | I15: side_align_left_started
A16: 1 | B16: 2026-06-19_13-37-32-571275 | C16: 1.7818691e+15 | D16: 20260619_133708 | E16: 24374 | F16: physical_status | G16: physical_alignment | H16: side_align_complete | I16: side_align_left_done | final camera=left ids=[22, 23, 24, 25, 26] target_pair=[24, 25] target_x=+0.3576 target_y=+0.2541 center_x=+0.3144 center_y=-0.0530 yaw=+179.71deg error_x=+0.0016 yaw_error=-0.29deg tolerance_x=0.0060 tolerance_yaw=2.00deg
A17: 1 | B17: 2026-06-19_13-37-32-574208 | C17: 1.7818691e+15 | D17: 20260619_133708 | E17: 24377 | F17: dropzone_status | G17: dropzone | H17: side_align_complete | I17: side_align_complete: side_align_left_done | final camera=left ids=[22, 23, 24, 25, 26] target_pair=[24, 25] target_x=+0.3576 target_y=+0.2541 center_x=+0.3144 center_y=-0.0530 yaw=+179.71deg error_x=+0.0016 yaw_error=-0.29deg tolerance_x=0.0060 tolerance_yaw=2.00deg. Optional: check trolley type with ros2 topic pub --once /trolley_command std_msgs/msg/String "{data: 'check_trolley_type'}" or approve straight drive with ros2 topic pub --once /trolley_command std_msgs/msg/String "{data: 'drive_under'}"
A18: 1 | B18: 2026-06-19_13-37-34-978948 | C18: 1.7818691e+15 | D18: 20260619_133708 | E18: 26782 | F18: yolo_detection | G18: yolo | H18: trash_trolley | I18: {"classes": ["trash_trolley"]}
A19: 1 | B19: 2026-06-19_13-37-43-968504 | C19: 1.7818691e+15 | D19: 20260619_133708 | E19: 35771 | F19: dropzone_status | G19: dropzone | H19: trolley_type_checked | I19: trolley_type_checked: trash_trolley via live_yolov8_topic
A20: 1 | B20: 2026-06-19_13-37-43-971801 | C20: 1.7818691e+15 | D20: 20260619_133708 | E20: 35775 | F20: command | G20: trolley_command | H20: check_trolley_type | I20: check_trolley_type
A21: 1 | B21: 2026-06-19_13-38-00-510675 | C21: 1.7818691e+15 | D21: 20260619_133708 | E21: 52313 | F21: dropzone_status | G21: dropzone | H21: status | I21: drive_under_active via drive_straight_under. Waiting for drive_straight_under_done.
A22: 1 | B22: 2026-06-19_13-38-00-511968 | C22: 1.7818691e+15 | D22: 20260619_133708 | E22: 52315 | F22: physical_status | G22: physical_alignment | H22: status | I22: drive_straight_under_started
A23: 1 | B23: 2026-06-19_13-38-00-516941 | C23: 1.7818691e+15 | D23: 20260619_133708 | E23: 52320 | F23: command | G23: trolley_command | H23: drive_under | I23: drive_under
A24: 1 | B24: 2026-06-19_13-38-09-972920 | C24: 1.7818691e+15 | D24: 20260619_133708 | E24: 61776 | F24: physical_status | G24: physical_alignment | H24: under_trolley | I24: drive_straight_under_done
... A31: 1 | B31: 2026-06-19_13-39-12-074796 | C31: 1.7818692e+15 | D31: 20260619_133708 | E31: 123877 | F31: dropzone_status | G31: dropzone | H31: fine_align_complete | I31: fine_align_complete: fine_align_under_done | final ids=[3, 12] center_x=+0.1290 center_y=-0.0002 yaw=-12.73deg orientation=normal error_x=-0.0035 error_y=-0.0064 yaw_error=-1.73deg target_x=+0.1325 target_y=+0.0062 tolerance_x=0.0040 tolerance_y=0.0100 tolerance_yaw=3.00deg. Remembered trash_trolley
A32: 1 | B32: 2026-06-19_13-40-27-248245 | C32: 1.7818692e+15 | D32: 20260619_133708 | E32: 199051 | F32: manual_mark | G32: operator | H32: docking sucessfull
A33: 1 | B33: 2026-06-19_13-40-32-503391 | C33: 1.7818692e+15 | D33: 20260619_133708 | E33: 204306 | F33: command | G33: trolley_command | H33: deliver_trolley | I33: deliver_trolley
A34: 1 | B34: 2026-06-19_13-40-32-505854 | C34: 1.7818692e+15 | D34: 20260619_133708 | E34: 204309 | F34: dropzone_status | G34: dropzone | H34: dropoff_goal_sent | I34: dropoff_goal_sent: remembered trash_trolley -> trash_dropoff. When the robot arrives, approve trolley release with: ros2 topic pub --once /trolley_command std_msgs/msg/String "{data: 'drive_out'}"
A35: 1 | B35: 2026-06-19_13-41-13-307342 | C35: 1.7818693e+15 | D35: 20260619_133708 | E35: 245110 | F35: command | G35: trolley_command | H35: drive_out | I35: drive_out
A36: 1 | B36: 2026-06-19_13-41-13-308960 | C36: 1.7818693e+15 | D36: 20260619_133708 | E36: 245112 | F36: dropzone_status | G36: dropzone | H36: status | I36: drive_out_active for 7.0s. Publishing direct cmd_vel to release trolley.
A37: 1 | B37: 2026-06-19_13-41-20-310921 | C37: 1.7818693e+15 | D37: 20260619_133708 | E37: 252114 | F37: dropzone_status | G37: dropzone | H37: drive_out_done | I37: drive_out_done. Released trash_trolley
A38: 1 | B38: 2026-06-19_13-41-20-311469 | C38: 1.7818693e+15 | D38: 20260619_133708 | E38: 252114 | F38: run_end | G38: logger | H38: drive_out_done
A39: 1 | B39: 2026-06-19_13-41-58-818796 | C39: 1.7818693e+15 | D39: 20260619_134158 | E39: 0.000 | F39: run_start | G39: logger | H39: manual_mark_without_active_run
A40: 1 | B40: 2026-06-19_13-41-58-821957 | C40: 1.7818693e+15 | D40: 20260619_134158 | E40: 0.004 | F40: manual_mark | G40: operator | H40: perfect_run
A41: 1 | B41: 2026-06-19_13-42-16-682291 | C41: 1.7818693e+15 | D41: 20260619_134158 | E41: 17864 | F41: run_end | G41: logger | H41: manual_end
B42: 2026-06-19_13-46-53-486307 | C42: 1.7818696e+15 | D42: 20260619_134653 | E42: 0.000 | F42: run_start | G42: logger | H42: command_trolley_ready
B43: 2026-06-19_13-46-53-488085 | C43: 1.7818696e+15 | D43: 20260619_134653 | E43: 0.002 | F43: command | G43: trolley_command | H43: trolley_ready | I43: trolley_ready
B44: 2026-06-19_13-46-53-499885 | C44: 1.7818696e+15 | D44: 20260619_134653 | E44: 0.014 | F44: dropzone_status | G44: dropzone | H44: approach_goal_sent | I44: approach_goal_sent. Inspect the robot pose, then approve side alignment with: ros2 topic pub --once /trolley_command std_msgs/msg/String "{data: 'side_align'}"
B45: 2026-06-19_13-47-26-282777 | C45: 1.7818696e+15 | D45: 20260619_134653 | E45: 32797 | F45: command | G45: trolley_command | H45: charging | I45: charging
B46: 2026-06-19_13-48-00-448218 | C46: 1.7818697e+15 | D46: 20260619_134653 | E46: 66962 | F46: command | G46: trolley_command | H46: charging | I46: charging
...

Sheet Summary
A1: Test Results Summary
A4: Overall KPI | B4: Value | C4: N | D4: Notes | G4: Breakdown | H4: Successful | I4: Total | J4: Success % | M4: Timing details | N4: Average in s | O4: Median in s | P4: Min in s | Q4: Max in s | AA4: Fail runs reasons
A5: Counted test rows | B5: =COUNTIF(Handnotes!$A$2:$A$95,"y") -> 53 | C5: =COUNTIF(Handnotes!$A$2:$A$95,"y") -> 53 | D5: Handnotes column A = y | G5: Trash Trolley | H5: {=SUMPRODUCT((Handnotes!$A$2:$A$95="y")*(Handnotes!$D$2:$D$95="Trash Trolley")*(Handnotes!$E$2:$E$95="success")*(Handnotes!$G$2:$G$95="correct")*(Handnotes!$H$2:$H$95="success")*((Handnotes!$J$2:$J$95="success"))*(Handnotes!$M$2:$M$95="success")*(Handnotes!$O$2:$O$95="success")*(Handnotes!$P$2:$P$95="success")*(Handnotes!$Q$2:$Q$95="success"))} -> 11 | I5: =COUNTIFS(Handnotes!$A$2:$A$95,"y",Handnotes!$D$2:$D$95,"Trash Trolley") -> 19 | J5: =IFERROR(H5/I5,"") -> 0.57894737 | M5: Side align time | N5: =AVERAGE(M26:M90) -> 12.597103 | O5: =MEDIAN(M26:M90) -> 11.217 | P5: =MIN(M26:M90) -> 2.254 | Q5: =MAX(M26:M90) -> 29.9
A6: Overall complete success | B6: =SUMPRODUCT((Handnotes!$A$2:$A$95="y")*(Handnotes!$E$2:$E$95="success")*(Handnotes!$G$2:$G$95="correct")*(Handnotes!$H$2:$H$95="success")*((Handnotes!$J$2:$J$95="success")+(Handnotes!$J$2:$J$95="sucess"))*(Handnotes!$M$2:$M$95="success")*(Handnotes!$O$2:$O$95="success")*(Handnotes!$P$2:$P$95="success")*(Handnotes!$Q$2:$Q$95="success"))/COUNTIF(Handnotes!$A$2:$A$95,"y") -> 0.30188679 | C6: =COUNTIF(Handnotes!$A$2:$A$95,"y") -> 53 | D6: All main manual stages successful/correct | G6: Laundry Trolley | H6: {=SUMPRODUCT((Handnotes!$A$2:$A$95="y")*(Handnotes!$D$2:$D$95="Laundry Trolley")*(Handnotes!$E$2:$E$95="success")*(Handnotes!$G$2:$G$95="correct")*(Handnotes!$H$2:$H$95="success")*((Handnotes!$J$2:$J$95="success"))*(Handnotes!$M$2:$M$95="success")*(Handnotes!$O$2:$O$95="success")*(Handnotes!$P$2:$P$95="success")*(Handnotes!$Q$2:$Q$95="success"))} -> 5 | I6: =COUNTIFS(Handnotes!$A$2:$A$95,"y",Handnotes!$D$2:$D$95,"Laundry Trolley") -> 19 | J6: =IFERROR(H6/I6,"") -> 0.26315789 | M6: Drive under | N6: =AVERAGE(N26:N90) -> 9.4112903 | O6: =MEDIAN(N26:N90) -> 9.431 | P6: =MIN(N26:N90) -> 9.019 | Q6: =MAX(N26:N90) -> 9.587
A7: Average side align time | B7: =N5 -> 12.597103 | C7: =COUNT($M$26:$M$119) -> 39 | D7: Successful side align only; seconds | G7: Normal orientation | H7: {=SUMPRODUCT((Handnotes!$A$2:$A$95="y")*(Handnotes!$C$2:$C$95="Normal")*(Handnotes!$E$2:$E$95="success")*(Handnotes!$G$2:$G$95="correct")*(Handnotes!$H$2:$H$95="success")*((Handnotes!$J$2:$J$95="success")+(Handnotes!$M$2:$M$95="success")*(Handnotes!$O$2:$O$95="success")*(Handnotes!$P$2:$P$95="success")*(Handnotes!$Q$2:$Q$95="success")))} -> 20 | I7: =COUNTIFS(Handnotes!$A$2:$A$95,"y",Handnotes!$C$2:$C$95,"Normal") -> 28 | J7: =IFERROR(H7/I7,"") -> 0.71428571 | M7: Fine align time | N7: =AVERAGE(O26:O72) -> 26.386846 | O7: =MEDIAN(O26:O72) -> 18.883 | P7: =MIN(O26:O90) -> 2.232 | Q7: =MAX(O26:O72) -> 134.049
A8: Average fine align time | B8: =N7 -> 26.386846 | C8: =COUNT($O$26:$O$119) -> 26 | D8: Successful fine align only; seconds | G8: Flipped 180 deg | H8: {=SUMPRODUCT((Handnotes!$A$2:$A$95="y")*(Handnotes!$C$2:$C$95="Flipped 180 deg")*(Handnotes!$E$2:$E$95="success")*(Handnotes!$G$2:$G$95="correct")*(Handnotes!$H$2:$H$95="success")*((Handnotes!$J$2:$J$95="success"))*(Handnotes!$M$2:$M$95="success")*(Handnotes!$O$2:$O$95="success")*(Handnotes!$P$2:$P$95="success")*(Handnotes!$Q$2:$Q$95="success"))} -> 7 | I8: =COUNTIFS(Handnotes!$A$2:$A$95,"y",Handnotes!$C$2:$C$95,"Flipped 180 deg") -> 25 | J8: =IFERROR(H8/I8,"") -> 0.28 | M8: Docking time | N8: =AVERAGE(Q26:Q72) -> 36.443765 | O8: =MEDIAN(Q26:Q72) -> 31.172 | P8: =MIN(Q26:Q90) -> 21.754 | Q8: =MAX(Q26:Q72) -> 75.178 | R8: Note: Docking was faster but needed to check manually if actually docked,--> time can be improved
A9: Average docking time | B9: =N8 -> 36.443765 | C9: =COUNT($Q$26:$Q$119) -> 17 | D9: Successful docking only; seconds | G9: Trash + Normal | H9: {=SUMPRODUCT((Handnotes!$A$2:$A$95="y")*(Handnotes!$D$2:$D$95="Trash Trolley")*(Handnotes!$C$2:$C$95="Normal")*(Handnotes!$E$2:$E$95="success")*(Handnotes!$G$2:$G$95="correct")*(Handnotes!$H$2:$H$95="success")*((Handnotes!$J$2:$J$95="success"))*(Handnotes!$M$2:$M$95="success")*(Handnotes!$O$2:$O$95="success")*(Handnotes!$P$2:$P$95="success")*(Handnotes!$Q$2:$Q$95="success"))} -> 6 | I9: =COUNTIFS(Handnotes!$A$2:$A$95,"y",Handnotes!$D$2:$D$95,"Trash Trolley",Handnotes!$C$2:$C$95,"Normal") -> 10 | J9: =IFERROR(H9/I9,"") -> 0.6 | M9: Side align - Fine align done for successfull runs | N9: =AVERAGE(P26:P72) -> 47.378182 | O9: =MEDIAN(P26:P72) -> 38.904 | P9: =MAX(M26:M90) -> 29.9 | Q9: =MAX(P26:P72) -> 162.207
A10: Fine align extra light used | B10: =COUNTIFS(Handnotes!$A$2:$A$95,"y",Handnotes!$K$2:$K$95,"YES") -> 24 | C10: =COUNTIF(Handnotes!$A$2:$A$95,"y") -> 53 | D10: =B10/C10 -> 0.45283019 | G10: Trash + Flipped | H10: {=SUMPRODUCT((Handnotes!$A$2:$A$95="y")*(Handnotes!$D$2:$D$95="Trash Trolley")*(Handnotes!$C$2:$C$95="Flipped 180 deg")*(Handnotes!$E$2:$E$95="success")*(Handnotes!$G$2:$G$95="correct")*(Handnotes!$H$2:$H$95="success")*((Handnotes!$J$2:$J$95="success"))*(Handnotes!$M$2:$M$95="success")*(Handnotes!$O$2:$O$95="success")*(Handnotes!$P$2:$P$95="success")*(Handnotes!$Q$2:$Q$95="success"))} -> 5 | I10: =COUNTIFS(Handnotes!$A$2:$A$95,"y",Handnotes!$D$2:$D$95,"Trash Trolley",Handnotes!$C$2:$C$95,"Flipped 180 deg") -> 9 | J10: =IFERROR(H10/I10,"") -> 0.55555556
A11: extra light success | B11: =COUNTIFS(Handnotes!$J$2:$J$95,"success",Handnotes!$K$2:$K$95,"YES") -> 18 | C11: =B10 -> 24 | D11: =B11/C11 -> 0.75
A12: no light attempts success | B12: =COUNTIFS(Handnotes!$J$2:$J$95,"success",Handnotes!$K$2:$K$95,"NO") -> 8 | C12: =COUNTIFS(Handnotes!$A$2:$A$95,"y",Handnotes!$K$2:$K$95,"NO") -> 8 | D12: =B12/C12 -> 1
A13: Generated | B13: =NOW() -> 46216.792 | C13: ="" | G13: Laundry + Normal | H13: {=SUMPRODUCT((Handnotes!$A$2:$A$95="y")*(Handnotes!$D$2:$D$95="Laundry Trolley")*(Handnotes!$C$2:$C$95="Normal")*(Handnotes!$E$2:$E$95="success")*(Handnotes!$G$2:$G$95="correct")*(Handnotes!$H$2:$H$95="success")*((Handnotes!$J$2:$J$95="success"))*(Handnotes!$M$2:$M$95="success")*(Handnotes!$O$2:$O$95="success")*(Handnotes!$P$2:$P$95="success")*(Handnotes!$Q$2:$Q$95="success"))} -> 3 | I13: =COUNTIFS(Handnotes!$A$2:$A$95,"y",Handnotes!$D$2:$D$95,"Laundry Trolley",Handnotes!$C$2:$C$95,"Normal") -> 10 | J13: =IFERROR(H13/I13,"") -> 0.3 | L13: Side align | M13: Aruco error_x all | N13: Aruco error_x drive under sucess | O13: Aruco yaw_error all | P13: Aruco yaw_error drive under sucess | Q13: based on aruco estimated error
G14: Laundry + Flipped | H14: {=SUMPRODUCT((Handnotes!$A$2:$A$95="y")*(Handnotes!$D$2:$D$95="Laundry Trolley")*(Handnotes!$C$2:$C$95="Flipped 180 deg")*(Handnotes!$E$2:$E$95="success")*(Handnotes!$G$2:$G$95="correct")*(Handnotes!$H$2:$H$95="success")*((Handnotes!$J$2:$J$95="success"))*(Handnotes!$M$2:$M$95="success")*(Handnotes!$O$2:$O$95="success")*(Handnotes!$P$2:$P$95="success")*(Handnotes!$Q$2:$Q$95="success"))} -> 2 | I14: =COUNTIFS(Handnotes!$A$2:$A$95,"y",Handnotes!$D$2:$D$95,"Laundry Trolley",Handnotes!$C$2:$C$95,"Flipped 180 deg") -> 9 | J14: =IFERROR(H14/I14,"") -> 0.22222222 | M14: =R98 -> 0.00040833333 | N14: =S98 -> 0.00054 | O14: =T98 -> 0.032083333 | P14: =U98 -> 0.117
A15: Stage | B15: Success count | C15: Partial | D15: Attempted | E15: Success % | F15: Criteria | L15: in mm | M15: =M14*1000 -> 0.40833333 | N15: =N14*1000 -> 0.54
A16: Side align | B16: =COUNTIFS(Handnotes!$A$2:$A$95,"y",Handnotes!$E$2:$E$95,"success") -> 44 | C16: =COUNTIFS(Handnotes!$A$2:$A$95,"y",Handnotes!$E$2:$E$95,"partial") -> 4 | D16: =COUNTIFS(Handnotes!$A$2:$A$95,"y",Handnotes!$E$2:$E$95,"unsuccessfull")+COUNTIFS(Handnotes!$A$2:$A$95,"y",Handnotes!$E$2:$E$95,"success") + COUNTIFS(Handnotes!$A$2:$A$95,"y",Handnotes!$E$2:$E$95,"partial") -> 53 | E16: =IFERROR(B16/D16,"") -> 0.83018868 | F16: E = success | L16: Fine align | M16: Aruco error_x all | N16: Aruco error_x sucess docking | O16: Aruco error_y all fine align | P16: Aruco error_y docking success | Q16: Aruco yaw error (deg) success | R16: Aruco yaw error (deg) all | T16: based on aruco estimated error
A17: Check type | B17: =COUNTIFS(Handnotes!$A$2:$A$95,"y",Handnotes!$G$2:$G$95,"correct") -> 52 | D17: =COUNTIFS(Handnotes!$A$2:$A$95,"y",Handnotes!$G$2:$G$95,"nothing detected")+COUNTIFS(Handnotes!$A$2:$A$95,"y",Handnotes!$G$2:$G$95,"correct")+COUNTIFS(Handnotes!$A$2:$A$95,"y",Handnotes!$G$2:$G$95,"partial") -> 53 | E17: =IFERROR(B17/D17,"") -> 0.98113208 | F17: G = correct | H17: Check type | I17: Attempted | J17: success count | K17: Success % | M17: =Z70 -> 0.0029741935 | N17: =AA70 -> 0.0028 | O17: =AB70 -> 0.005332 | P17: =AC70 -> 0.0054789474 | Q17: =AD70 -> 1.6357895 | R17: =AE70 -> 1.4876 | S17: =AF70 -> 0
A18: Drive under | B18: =COUNTIFS(Handnotes!$A$2:$A$95,"y",Handnotes!$H$2:$H$95,"success") -> 31 | C18: =COUNTIFS(Handnotes!$A$2:$A$95,"y",Handnotes!$H$2:$H$95,"partial") -> 0 | D18: =COUNTIFS(Handnotes!$A$2:$A$95,"y",Handnotes!$H$2:$H$95,"unsuccessfull")+COUNTIFS(Handnotes!$A$2:$A$95,"y",Handnotes!$H$2:$H$95,"success")+COUNTIFS(Handnotes!$A$2:$A$95,"y",Handnotes!$H$2:$H$95,"partial") -> 37 | E18: =IFERROR(B18/D18,"") -> 0.83783784 | F18: H = success | H18: Laundry | I18: =COUNTIF(C26:C90,"Laundry Trolley") -> 19 | J18: =COUNTIFS(E26:E90, "correct",C26:C90,"Laundry Trolley") -> 19 | K18: =J18/I18 -> 1 | L18: in mm | M18: =M17*1000 -> 2.9741935 | N18: =N17*1000 -> 2.8 | O18: =O17*1000 -> 5.332 | P18: =P17*1000 -> 5.4789474
A19: Fine align | B19: =COUNTIFS(Handnotes!$A$2:$A$95,"y",Handnotes!$J$2:$J$95,"success")+COUNTIFS(Handnotes!$A$2:$A$95,"y",Handnotes!$J$2:$J$95,"sucess") -> 26 | C19: =COUNTIFS(Handnotes!$A$2:$A$95,"y",Handnotes!$J$2:$J$95,"partial") -> 2 | D19: =COUNTIFS(Handnotes!$A$2:$A$95,"y",Handnotes!$J$2:$J$95,"unsuccessfull")+COUNTIFS(Handnotes!$A$2:$A$95,"y",Handnotes!$J$2:$J$95,"success")+COUNTIFS(Handnotes!$A$2:$A$95,"y",Handnotes!$J$2:$J$95,"partial") -> 32 | E19: =IFERROR(B19/D19,"") -> 0.8125 | F19: J = success | H19: Trash | I19: =COUNTIF(C27:C91,"Trash Trolley") -> 18 | J19: =COUNTIFS(E27:E91, "correct",C27:C91,"Trash Trolley") -> 18 | K19: =J19/I19 -> 1
A20: Docking | B20: =COUNTIFS(Handnotes!$A$2:$A$95,"y",Handnotes!$M$2:$M$95,"success") -> 20 | C20: =COUNTIFS(Handnotes!$A$2:$A$95,"y",Handnotes!$M$2:$M$95,"partial") -> 4 | D20: =COUNTIFS(Handnotes!$A$2:$A$95,"y",Handnotes!$M$2:$M$95,"unsuccessfull")+COUNTIFS(Handnotes!$A$2:$A$95,"y",Handnotes!$M$2:$M$95,"success")+COUNTIFS(Handnotes!$A$2:$A$95,"y",Handnotes!$M$2:$M$95,"partial") -> 32 | E20: =IFERROR(B20/D20,"") -> 0.625 | F20: M = success | H20: Empty | I20: =COUNTIF(C28:C92,"empty") -> 15 | J20: =COUNTIFS(E28:E92, "correct",C28:C92,"empty") -> 14 | K20: =J20/I20 -> 0.93333333
A21: Deliver | B21: =COUNTIFS(Handnotes!$A$2:$A$95,"y",Handnotes!$O$2:$O$95,"success") -> 28 | C21: =COUNTIFS(Handnotes!$A$2:$A$95,"y",Handnotes!$O$2:$O$95,"partial") -> 0 | D21: =COUNTIFS(Handnotes!$A$2:$A$95,"y",Handnotes!$O$2:$O$95,"unsuccessfull")+COUNTIFS(Handnotes!$A$2:$A$95,"y",Handnotes!$O$2:$O$95,"success")+COUNTIFS(Handnotes!$A$2:$A$95,"y",Handnotes!$O$2:$O$95,"partial") -> 29 | E21: =IFERROR(B21/D21,"") -> 0.96551724 | F21: O = success | H21: total | I21: =SUM(I18:I20) -> 52 | J21: =SUM(J18:J20) -> 51 | K21: =J21/I21 -> 0.98076923
A22: Drive out | B22: =COUNTIFS(Handnotes!$A$2:$A$95,"y",Handnotes!$P$2:$P$95,"success") -> 27 | C22: =COUNTIFS(Handnotes!$A$2:$A$95,"y",Handnotes!$P$2:$P$95,"partial") -> 0 | D22: =COUNTIFS(Handnotes!$A$2:$A$95,"y",Handnotes!$P$2:$P$95,"unsuccessfull")+COUNTIFS(Handnotes!$A$2:$A$95,"y",Handnotes!$P$2:$P$95,"success")+COUNTIFS(Handnotes!$A$2:$A$95,"y",Handnotes!$P$2:$P$95,"partial") -> 29 | E22: =IFERROR(B22/D22,"") -> 0.93103448 | F22: P = success
A23: Return charging | B23: =COUNTIFS(Handnotes!$A$2:$A$95,"y",Handnotes!$Q$2:$Q$95,"success") -> 27 | C23: =COUNTIFS(Handnotes!$A$2:$A$95,"y",Handnotes!$Q$2:$Q$95,"partial") -> 0 | D23: =COUNTIFS(Handnotes!$A$2:$A$95,"y",Handnotes!$Q$2:$Q$95,"unsuccessfull")+COUNTIFS(Handnotes!$A$2:$A$95,"y",Handnotes!$Q$2:$Q$95,"success")+COUNTIFS(Handnotes!$A$2:$A$95,"y",Handnotes!$Q$2:$Q$95,"partial") -> 27 | E23: =IFERROR(B23/D23,"") -> 1 | F23: Q = success | U23: =T26 -> -0.29
R24: side align | S24: side align | T24: side align | U24: side align | W24: side align | Z24: fine align | AA24: fine align | AB24: fine align | AD24: fine align
A25: Test | B25: Orientation | C25: Type | D25: Side align | E25: Check type | F25: Drive under | G25: Fine align | H25: Fine light | I25: Docking | J25: Deliver | K25: Drive out | L25: Return charging | M25: Side align time (s) | N25: Drive under time (s) | O25: Fine align time (s) | P25: Side align - Fine align done | Q25: Docking time (s) | R25: Aruco error_x all | S25: Aruco error_x drive under sucess | T25: Aruco yaw_error all | U25: Aruco yaw_error drive under sucess | X25: side align event data | Y25: fine align | Z25: Aruco error_x all | AA25: Aruco error_x sucess docking | AB25: Aruco error_y all fine align | AC25: Aruco error_y docking success | AD25: Aruco yaw error (deg) success | AE25: Aruco yaw error (deg) all
A26: =IF(Handnotes!$A$2="y",Handnotes!$B$2,"") -> 1 | B26: =IF($A26="","",IFERROR(Handnotes!$C$2,"")) -> Normal | C26: =IF($A26="","",IFERROR(Handnotes!$D$2,"")) -> Trash Trolley | D26: =IF($A26="","",IFERROR(Handnotes!$E$2,"")) -> success | E26: =IF($A26="","",IFERROR(Handnotes!$G$2,"")) -> correct | F26: =IF($A26="","",IFERROR(Handnotes!$H$2,"")) -> success | G26: =IF($A26="","",IFERROR(Handnotes!$J$2,"")) -> success | H26: =IF($A26="","",IFERROR(Handnotes!$K$2,"")) -> NO | I26: =IF($A26="","",IFERROR(Handnotes!$M$2,"")) -> success | J26: =IF($A26="","",IFERROR(Handnotes!$O$2,"")) -> success | K26: =IF($A26="","",IFERROR(Handnotes!$P$2,"")) -> success | L26: =IF($A26="","",IFERROR(Handnotes!$Q$2,"")) -> success | M26: {=IF($D26="success",_xlfn.LET(_xlpm.run,$A26,_xlpm.start_cmd,IFERROR(_xlfn.XLOOKUP(1,(Event_logs!$A$2:$A$1588=_xlpm.run)*(Event_logs!$F$2:$F$1588="command")*(Event_logs!$G$2:$G$1588="trolley_command")*(Event_logs!$H$2:$H$1588="side_align"),Event_logs!$E$2:$E$1588),""),_xlpm.start_fb,IFERROR(_xlfn.XLOOKUP(1,(Event_logs!$A$2:$A$1588=_xlpm.run)*(Event_logs!$F$2:$F$1588="dropzone_status")*ISNUMBER(SEARCH("side_aligning",Event_logs!$I$2:$I$1588)),Event_logs!$E$2:$E$1588),""),_xlpm.start,IF(_xlpm.start_cmd<>"",_xlpm.start_cmd,_xlpm.start_fb),_xlpm.ende,IFERROR(_xlfn.XLOOKUP(1,(Event_logs!$A$2:$A$1588=_xlpm.run)*(Event_logs!$F$2:$F$1588="physical_status")*(Event_logs!$G$2:$G$1588="physical_alignment")*(Event_logs!$H$2:$H$1588="side_align_complete")*ISNUMBER(SEARCH("side_align_left_done",Event_logs!$I$2:$I$1588)),Event_logs!$E$2:$E$1588),""),_xlpm.diff,_xlpm.ende-_xlpm.start,_xlpm.sek,IF(_xlpm.diff>1000,_xlpm.diff/1000,_xlpm.diff),IFERROR(IF(AND(_xlpm.start<>"",_xlpm.ende<>"",_xlpm.sek>=0),_xlpm.sek,""),"")),"")} -> 5.868 | N26: {=IF($F26="success",_xlfn.LET(_xlpm.run,$A26,_xlpm.start_cmd,IFERROR(_xlfn.XLOOKUP(1,(Event_logs!$A$2:$A$1588=_xlpm.run)*(Event_logs!$F$2:$F$1588="command")*(Event_logs!$G$2:$G$1588="trolley_command")*(Event_logs!$H$2:$H$1588="drive_under"),Event_logs!$E$2:$E$1588),""),_xlpm.start_fb,IFERROR(_xlfn.XLOOKUP(1,(Event_logs!$A$2:$A$1588=_xlpm.run)*(Event_logs!$F$2:$F$1588="dropzone_status")*ISNUMBER(SEARCH("drive_under_active",Event_logs!$I$2:$I$1588)),Event_logs!$E$2:$E$1588),""),_xlpm.start,IF(_xlpm.start_cmd<>"",_xlpm.start_cmd,_xlpm.start_fb),_xlpm.ende,IFERROR(_xlfn.XLOOKUP(1,(Event_logs!$A$2:$A$1588=_xlpm.run)*(Event_logs!$F$2:$F$1588="physical_status")*(Event_logs!$G$2:$G$1588="physical_alignment")*(Event_logs!$H$2:$H$1588="under_trolley")*ISNUMBER(SEARCH("drive_straight_under_done",Event_logs!$I$2:$I$1588)),Event_logs!$E$2:$E$1588),""),_xlpm.diff,_xlpm.ende-_xlpm.start,_xlpm.sek,IF(_xlpm.diff>1000,_xlpm.diff/1000,_xlpm.diff),IFERROR(IF(AND(_xlpm.start<>"",_xlpm.ende<>"",_xlpm.sek>=0),_xlpm.sek,""),"")),"")} -> 9.456 | O26: {=IF($G26="success",_xlfn.LET(_xlpm.run,$A26,_xlpm.start_cmd,IFERROR(_xlfn.XLOOKUP(1,(Event_logs!$A$2:$A$1588=_xlpm.run)*(Event_logs!$F$2:$F$1588="command")*(Event_logs!$G$2:$G$1588="trolley_command")*(Event_logs!$H$2:$H$1588="fine_align"),Event_logs!$E$2:$E$1588),""),_xlpm.start_fb,IFERROR(_xlfn.XLOOKUP(1,(Event_logs!$A$2:$A$1588=_xlpm.run)*(Event_logs!$F$2:$F$1588="dropzone_status")*ISNUMBER(SEARCH("fine_aligning",Event_logs!$I$2:$I$1588)),Event_logs!$E$2:$E$1588),""),_xlpm.start,IF(_xlpm.start_cmd<>"",_xlpm.start_cmd,_xlpm.start_fb),_xlpm.ende,IFERROR(_xlfn.XLOOKUP(1,(Event_logs!$A$2:$A$1588=_xlpm.run)*(Event_logs!$F$2:$F$1588="physical_status")*(Event_logs!$G$2:$G$1588="physical_alignment")*(Event_logs!$H$2:$H$1588="fine_align_complete")*ISNUMBER(SEARCH("fine_align_under_done",Event_logs!$I$2:$I$1588)),Event_logs!$E$2:$E$1588),""),_xlpm.diff,_xlpm.ende-_xlpm.start,_xlpm.sek,IF(_xlpm.diff>1000,_xlpm.diff/1000,_xlpm.diff),IFERROR(IF(AND(_xlpm.start<>"",_xlpm.ende<>"",_xlpm.sek>=0),_xlpm.sek,""),"")),"")} -> 28.055 | P26: =IF(AND(D26="success",F26="success",G26="success"),SUM(M26:O26),"") -> 43.379 | Q26: =_xlfn.LET(_xlpm.t,$A26,_xlpm.s,_xlfn.MINIFS(Event_logs!$E$2:$E$1588,Event_logs!$A$2:$A$1588,_xlpm.t,Event_logs!$H$2:$H$1588,"fine_align_complete"),_xlpm.e,_xlfn.MINIFS(Event_logs!$E$2:$E$1588,Event_logs!$A$2:$A$1588,_xlpm.t,Event_logs!$H$2:$H$1588,"docking sucessfull"),IF(AND(OR($I26="success",$I26="sucess"),_xlpm.s>0,_xlpm.e>_xlpm.s),(_xlpm.e-_xlpm.s)/1000,"")) -> 75.178 | R26: {=IF($D26="success",_xlfn.LET(_xlpm.d,_xlfn.XLOOKUP(1,(Event_logs!$A$2:$A$1588=$A26)*(Event_logs!$H$2:$H$1588="side_align_complete"),Event_logs!$I$2:$I$1588,""),IFERROR(_xlfn.NUMBERVALUE(_xlfn.TEXTBEFORE(_xlfn.TEXTAFTER(_xlpm.d,"error_x=")&" "," "),".",","),"")),"")} -> 0.0016 | S26: {=IF(AND($F26="success",$D26="success"),_xlfn.LET(_xlpm.d,_xlfn.XLOOKUP(1,(Event_logs!$A$2:$A$1588=$A26)*(Event_logs!$H$2:$H$1588="side_align_complete"),Event_logs!$I$2:$I$1588,""),IFERROR(_xlfn.NUMBERVALUE(_xlfn.TEXTBEFORE(_xlfn.TEXTAFTER(_xlpm.d,"error_x=")&" "," "),".",","),"")),"")} -> 0.0016 | T26: {=IF($D26="success",_xlfn.LET(_xlpm.d,_xlfn.XLOOKUP(1,(Event_logs!$A$2:$A$1588=$A26)*(Event_logs!$H$2:$H$1588="side_align_complete"),Event_logs!$I$2:$I$1588,""),IFERROR(_xlfn.NUMBERVALUE(_xlfn.TEXTBEFORE(_xlfn.TEXTAFTER(_xlpm.d,"yaw_error="),"deg"),".",","),"")),"")} -> -0.29 | U26: {=IF(AND($F26="success",D26="success"),_xlfn.LET(_xlpm.d,_xlfn.XLOOKUP(1,(Event_logs!$A$2:$A$1588=$A26)*(Event_logs!$H$2:$H$1588="side_align_complete"),Event_logs!$I$2:$I$1588,""),IFERROR(_xlfn.NUMBERVALUE(_xlfn.TEXTBEFORE(_xlfn.TEXTAFTER(_xlpm.d,"yaw_error="),"deg"),".",","),"")),"")} -> -0.29 | X26: {=IF(OR($G26="success",$G26="sucess"),_xlfn.XLOOKUP(1,(Event_logs!$A$2:$A$1588=$A26)*(Event_logs!$H$2:$H$1588="side_align_complete"),Event_logs!$I$2:$I$1588,""),"")} -> side_align_left_done | final camera=left ids=[22, 23, 24, 25, 26] target_pair=[24, 25] target_x=+0.3576 target_y=+0.2541 center_x=+0.3144 center_y=-0.0530 yaw=+179.71deg error_x=+0.0016 yaw_error=-0.29deg tolerance_x=0.0060 tolerance_yaw=2.00deg | Y26: {=IF(OR($G26="success",$G26="sucess"),_xlfn.XLOOKUP(1,(Event_logs!$A$2:$A$1588=$A26)*(Event_logs!$H$2:$H$1588="fine_align_complete"),Event_logs!$I$2:$I$1588,""),"")} -> fine_align_under_done | final ids=[3, 12] center_x=+0.1290 center_y=-0.0002 yaw=-12.73deg orientation=normal error_x=-0.0035 error_y=-0.0064 yaw_error=-1.73deg target_x=+0.1325 target_y=+0.0062 tolerance_x=0.0040 tolerance_y=0.0100 tolerance_yaw=3.00deg | Z26: {=IF(OR($G26="success",$G26="sucess",$G26="unsuccessfull",$G26="partial"),_xlfn.LET(_xlpm.d,_xlfn.XLOOKUP(1,(Event_logs!$A$2:$A$1588=$A26)*(Event_logs!$H$2:$H$1588="fine_align_complete"),Event_logs!$I$2:$I$1588,""),IFERROR(_xlfn.NUMBERVALUE(_xlfn.TEXTBEFORE(_xlfn.TEXTAFTER(_xlpm.d,"error_x=")&" "," "),".",","),"")),"")} -> -0.0035 | AA26: {=IF(AND($G26="success",$I26="success"),_xlfn.LET(_xlpm.d,_xlfn.XLOOKUP(1,(Event_logs!$A$2:$A$1588=$A26)*(Event_logs!$H$2:$H$1588="fine_align_complete"),Event_logs!$I$2:$I$1588,""),IFERROR(_xlfn.NUMBERVALUE(_xlfn.TEXTBEFORE(_xlfn.TEXTAFTER(_xlpm.d,"error_x=")&" "," "),".",","),"")),"")} -> -0.0035 | AB26: {=IF($G26="success",_xlfn.LET(_xlpm.d,_xlfn.XLOOKUP(1,(Event_logs!$A$2:$A$1588=$A26)*(Event_logs!$H$2:$H$1588="fine_align_complete"),Event_logs!$I$2:$I$1588,""),IFERROR(_xlfn.NUMBERVALUE(_xlfn.TEXTBEFORE(_xlfn.TEXTAFTER(_xlpm.d,"error_y=")&" "," "),".",","),"")),"")} -> -0.0064 | AC26: {=IF(AND($G26="success",$I26="success"),_xlfn.LET(_xlpm.d,_xlfn.XLOOKUP(1,(Event_logs!$A$2:$A$1588=$A26)*(Event_logs!$H$2:$H$1588="fine_align_complete"),Event_logs!$I$2:$I$1588,""),IFERROR(_xlfn.NUMBERVALUE(_xlfn.TEXTBEFORE(_xlfn.TEXTAFTER(_xlpm.d,"error_y=")&" "," "),".",","),"")),"")} -> -0.0064 | AD26: {=IF(AND($G26="success",$I26="success"),_xlfn.LET(_xlpm.d,_xlfn.XLOOKUP(1,(Event_logs!$A$2:$A$1588=$A26)*(Event_logs!$H$2:$H$1588="fine_align_complete"),Event_logs!$I$2:$I$1588,""),IFERROR(_xlfn.NUMBERVALUE(_xlfn.TEXTBEFORE(_xlfn.TEXTAFTER(_xlpm.d,"yaw_error="),"deg"),".",","),"")),"")} -> -1.73 | AE26: {=IF($G26="success",_xlfn.LET(_xlpm.d,_xlfn.XLOOKUP(1,(Event_logs!$A$2:$A$1588=$A26)*(Event_logs!$H$2:$H$1588="fine_align_complete"),Event_logs!$I$2:$I$1588,""),IFERROR(_xlfn.NUMBERVALUE(_xlfn.TEXTBEFORE(_xlfn.TEXTAFTER(_xlpm.d,"yaw_error="),"deg"),".",","),"")),"")} -> -1.73
A27: =IF(Handnotes!$A$3="y",Handnotes!$B$3,"") -> 2 | B27: =IF($A27="","",IFERROR(Handnotes!$C$3,"")) -> Normal | C27: =IF($A27="","",IFERROR(Handnotes!$D$3,"")) -> Trash Trolley | D27: =IF($A27="","",IFERROR(Handnotes!$E$3,"")) -> success | E27: =IF($A27="","",IFERROR(Handnotes!$G$3,"")) -> correct | F27: =IF($A27="","",IFERROR(Handnotes!$H$3,"")) -> success | G27: =IF($A27="","",IFERROR(Handnotes!$J$3,"")) -> success | H27: =IF($A27="","",IFERROR(Handnotes!$K$3,"")) -> NO | I27: =IF($A27="","",IFERROR(Handnotes!$M$3,"")) -> success | J27: =IF($A27="","",IFERROR(Handnotes!$O$3,"")) -> success | K27: =IF($A27="","",IFERROR(Handnotes!$P$3,"")) -> success | L27: =IF($A27="","",IFERROR(Handnotes!$Q$3,"")) -> success | M27: {=IF($D27="success",_xlfn.LET(_xlpm.run,$A27,_xlpm.start_cmd,IFERROR(_xlfn.XLOOKUP(1,(Event_logs!$A$2:$A$1588=_xlpm.run)*(Event_logs!$F$2:$F$1588="command")*(Event_logs!$G$2:$G$1588="trolley_command")*(Event_logs!$H$2:$H$1588="side_align"),Event_logs!$E$2:$E$1588),""),_xlpm.start_fb,IFERROR(_xlfn.XLOOKUP(1,(Event_logs!$A$2:$A$1588=_xlpm.run)*(Event_logs!$F$2:$F$1588="dropzone_status")*ISNUMBER(SEARCH("side_aligning",Event_logs!$I$2:$I$1588)),Event_logs!$E$2:$E$1588),""),_xlpm.start,IF(_xlpm.start_cmd<>"",_xlpm.start_cmd,_xlpm.start_fb),_xlpm.ende,IFERROR(_xlfn.XLOOKUP(1,(Event_logs!$A$2:$A$1588=_xlpm.run)*(Event_logs!$F$2:$F$1588="physical_status")*(Event_logs!$G$2:$G$1588="physical_alignment")*(Event_logs!$H$2:$H$1588="side_align_complete")*ISNUMBER(SEARCH("side_align_left_done",Event_logs!$I$2:$I$1588)),Event_logs!$E$2:$E$1588),""),_xlpm.diff,_xlpm.ende-_xlpm.start,_xlpm.sek,IF(_xlpm.diff>1000,_xlpm.diff/1000,_xlpm.diff),IFERROR(IF(AND(_xlpm.start<>"",_xlpm.ende<>"",_xlpm.sek>=0),_xlpm.sek,""),"")),"")} -> 7.603 | N27: {=IF($F27="success",_xlfn.LET(_xlpm.run,$A27,_xlpm.start_cmd,IFERROR(_xlfn.XLOOKUP(1,(Event_logs!$A$2:$A$1588=_xlpm.run)*(Event_logs!$F$2:$F$1588="command")*(Event_logs!$G$2:$G$1588="trolley_command")*(Event_logs!$H$2:$H$1588="drive_under"),Event_logs!$E$2:$E$1588),""),_xlpm.start_fb,IFERROR(_xlfn.XLOOKUP(1,(Event_logs!$A$2:$A$1588=_xlpm.run)*(Event_logs!$F$2:$F$1588="dropzone_status")*ISNUMBER(SEARCH("drive_under_active",Event_logs!$I$2:$I$1588)),Event_logs!$E$2:$E$1588),""),_xlpm.start,IF(_xlpm.start_cmd<>"",_xlpm.start_cmd,_xlpm.start_fb),_xlpm.ende,IFERROR(_xlfn.XLOOKUP(1,(Event_logs!$A$2:$A$1588=_xlpm.run)*(Event_logs!$F$2:$F$1588="physical_status")*(Event_logs!$G$2:$G$1588="physical_alignment")*(Event_logs!$H$2:$H$1588="under_trolley")*ISNUMBER(SEARCH("drive_straight_under_done",Event_logs!$I$2:$I$1588)),Event_logs!$E$2:$E$1588),""),_xlpm.diff,_xlpm.ende-_xlpm.start,_xlpm.sek,IF(_xlpm.diff>1000,_xlpm.diff/1000,_xlpm.diff),IFERROR(IF(AND(_xlpm.start<>"",_xlpm.ende<>"",_xlpm.sek>=0),_xlpm.sek,""),"")),"")} -> 9.43 | O27: {=IF($G27="success",_xlfn.LET(_xlpm.run,$A27,_xlpm.start_cmd,IFERROR(_xlfn.XLOOKUP(1,(Event_logs!$A$2:$A$1588=_xlpm.run)*(Event_logs!$F$2:$F$1588="command")*(Event_logs!$G$2:$G$1588="trolley_command")*(Event_logs!$H$2:$H$1588="fine_align"),Event_logs!$E$2:$E$1588),""),_xlpm.start_fb,IFERROR(_xlfn.XLOOKUP(1,(Event_logs!$A$2:$A$1588=_xlpm.run)*(Event_logs!$F$2:$F$1588="dropzone_status")*ISNUMBER(SEARCH("fine_aligning",Event_logs!$I$2:$I$1588)),Event_logs!$E$2:$E$1588),""),_xlpm.start,IF(_xlpm.start_cmd<>"",_xlpm.start_cmd,_xlpm.start_fb),_xlpm.ende,IFERROR(_xlfn.XLOOKUP(1,(Event_logs!$A$2:$A$1588=_xlpm.run)*(Event_logs!$F$2:$F$1588="physical_status")*(Event_logs!$G$2:$G$1588="physical_alignment")*(Event_logs!$H$2:$H$1588="fine_align_complete")*ISNUMBER(SEARCH("fine_align_under_done",Event_logs!$I$2:$I$1588)),Event_logs!$E$2:$E$1588),""),_xlpm.diff,_xlpm.ende-_xlpm.start,_xlpm.sek,IF(_xlpm.diff>1000,_xlpm.diff/1000,_xlpm.diff),IFERROR(IF(AND(_xlpm.start<>"",_xlpm.ende<>"",_xlpm.sek>=0),_xlpm.sek,""),"")),"")} -> 2.232 | P27: =IF(AND(D27="success",F27="success",G27="success"),SUM(M27:O27),"") -> 19.265 | Q27: =_xlfn.LET(_xlpm.t,$A27,_xlpm.s,_xlfn.MINIFS(Event_logs!$E$2:$E$1588,Event_logs!$A$2:$A$1588,_xlpm.t,Event_logs!$H$2:$H$1588,"fine_align_complete"),_xlpm.e,_xlfn.MINIFS(Event_logs!$E$2:$E$1588,Event_logs!$A$2:$A$1588,_xlpm.t,Event_logs!$H$2:$H$1588,"docking sucessfull"),IF(AND(OR($I27="success",$I27="sucess"),_xlpm.s>0,_xlpm.e>_xlpm.s),(_xlpm.e-_xlpm.s)/1000,"")) -> 33.933 | R27: {=IF($D27="success",_xlfn.LET(_xlpm.d,_xlfn.XLOOKUP(1,(Event_logs!$A$2:$A$1588=$A27)*(Event_logs!$H$2:$H$1588="side_align_complete"),Event_logs!$I$2:$I$1588,""),IFERROR(_xlfn.NUMBERVALUE(_xlfn.TEXTBEFORE(_xlfn.TEXTAFTER(_xlpm.d,"error_x=")&" "," "),".",","),"")),"")} -> 0.0034 | S27: {=IF(AND($F27="success",$D27="success"),_xlfn.LET(_xlpm.d,_xlfn.XLOOKUP(1,(Event_logs!$A$2:$A$1588=$A27)*(Event_logs!$H$2:$H$1588="side_align_complete"),Event_logs!$I$2:$I$1588,""),IFERROR(_xlfn.NUMBERVALUE(_xlfn.TEXTBEFORE(_xlfn.TEXTAFTER(_xlpm.d,"error_x=")&" "," "),".",","),"")),"")} -> 0.0034 | T27: {=IF($D27="success",_xlfn.LET(_xlpm.d,_xlfn.XLOOKUP(1,(Event_logs!$A$2:$A$1588=$A27)*(Event_logs!$H$2:$H$1588="side_align_complete"),Event_logs!$I$2:$I$1588,""),IFERROR(_xlfn.NUMBERVALUE(_xlfn.TEXTBEFORE(_xlfn.TEXTAFTER(_xlpm.d,"yaw_error="),"deg"),".",","),"")),"")} -> -0.25 | U27: {=IF(AND($F27="success",D27="success"),_xlfn.LET(_xlpm.d,_xlfn.XLOOKUP(1,(Event_logs!$A$2:$A$1588=$A27)*(Event_logs!$H$2:$H$1588="side_align_complete"),Event_logs!$I$2:$I$1588,""),IFERROR(_xlfn.NUMBERVALUE(_xlfn.TEXTBEFORE(_xlfn.TEXTAFTER(_xlpm.d,"yaw_error="),"deg"),".",","),"")),"")} -> -0.25 | W27: {=IF(OR($G27="success",$G27="sucess"),_xlfn.LET(_xlpm.d,_xlfn.XLOOKUP(1,(Event_logs!$A$2:$A$1588=$A27)*(Event_logs!$H$2:$H$1588="side_align_complete"),Event_logs!$I$2:$I$1588,""),IFERROR(_xlfn.NUMBERVALUE(_xlfn.TEXTBEFORE(_xlfn.TEXTAFTER(_xlpm.d,"yaw="),"deg"),".",","),"")),"")} -> 179.75 | X27: {=IF(OR($G27="success",$G27="sucess"),_xlfn.XLOOKUP(1,(Event_logs!$A$2:$A$1588=$A27)*(Event_logs!$H$2:$H$1588="side_align_complete"),Event_logs!$I$2:$I$1588,""),"")} -> side_align_left_done | final camera=left ids=[23, 24, 25, 26] target_pair=[24, 25] target_x=+0.3594 target_y=+0.2713 center_x=+0.3676 center_y=-0.0358 yaw=+179.75deg error_x=+0.0034 yaw_error=-0.25deg tolerance_x=0.0060 tolerance_yaw=2.00deg | Z27: {=IF(OR($G27="success",$G27="sucess",$G27="unsuccessfull",$G27="partial"),_xlfn.LET(_xlpm.d,_xlfn.XLOOKUP(1,(Event_logs!$A$2:$A$1588=$A27)*(Event_logs!$H$2:$H$1588="fine_align_complete"),Event_logs!$I$2:$I$1588,""),IFERROR(_xlfn.NUMBERVALUE(_xlfn.TEXTBEFORE(_xlfn.TEXTAFTER(_xlpm.d,"error_x=")&" "," "),".",","),"")),"")} -> -0.0019 | AA27: {=IF(AND($G27="success",$I27="success"),_xlfn.LET(_xlpm.d,_xlfn.XLOOKUP(1,(Event_logs!$A$2:$A$1588=$A27)*(Event_logs!$H$2:$H$1588="fine_align_complete"),Event_logs!$I$2:$I$1588,""),IFERROR(_xlfn.NUMBERVALUE(_xlfn.TEXTBEFORE(_xlfn.TEXTAFTER(_xlpm.d,"error_x=")&" "," "),".",","),"")),"")} -> -0.0019 | AB27: {=IF($G27="success",_xlfn.LET(_xlpm.d,_xlfn.XLOOKUP(1,(Event_logs!$A$2:$A$1588=$A27)*(Event_logs!$H$2:$H$1588="fine_align_complete"),Event_logs!$I$2:$I$1588,""),IFERROR(_xlfn.NUMBERVALUE(_xlfn.TEXTBEFORE(_xlfn.TEXTAFTER(_xlpm.d,"error_y=")&" "," "),".",","),"")),"")} -> -0.0053 | AC27: {=IF(AND($G27="success",$I27="success"),_xlfn.LET(_xlpm.d,_xlfn.XLOOKUP(1,(Event_logs!$A$2:$A$1588=$A27)*(Event_logs!$H$2:$H$1588="fine_align_complete"),Event_logs!$I$2:$I$1588,""),IFERROR(_xlfn.NUMBERVALUE(_xlfn.TEXTBEFORE(_xlfn.TEXTAFTER(_xlpm.d,"error_y=")&" "," "),".",","),"")),"")} -> -0.0053 | AD27: {=IF(AND($G27="success",$I27="success"),_xlfn.LET(_xlpm.d,_xlfn.XLOOKUP(1,(Event_logs!$A$2:$A$1588=$A27)*(Event_logs!$H$2:$H$1588="fine_align_complete"),Event_logs!$I$2:$I$1588,""),IFERROR(_xlfn.NUMBERVALUE(_xlfn.TEXTBEFORE(_xlfn.TEXTAFTER(_xlpm.d,"yaw_error="),"deg"),".",","),"")),"")} -> -2.02 | AE27: {=IF($G27="success",_xlfn.LET(_xlpm.d,_xlfn.XLOOKUP(1,(Event_logs!$A$2:$A$1588=$A27)*(Event_logs!$H$2:$H$1588="fine_align_complete"),Event_logs!$I$2:$I$1588,""),IFERROR(_xlfn.NUMBERVALUE(_xlfn.TEXTBEFORE(_xlfn.TEXTAFTER(_xlpm.d,"yaw_error="),"deg"),".",","),"")),"")} -> -2.02
A28: =IF(Handnotes!$A$4="y",Handnotes!$B$4,"") -> 3 | B28: =IF($A28="","",IFERROR(Handnotes!$C$4,"")) -> Flipped 180 deg | C28: =IF($A28="","",IFERROR(Handnotes!$D$4,"")) -> Trash Trolley | D28: =IF($A28="","",IFERROR(Handnotes!$E$4,"")) -> success | E28: =IF($A28="","",IFERROR(Handnotes!$G$4,"")) -> correct | F28: =IF($A28="","",IFERROR(Handnotes!$H$4,"")) -> success | G28: =IF($A28="","",IFERROR(Handnotes!$J$4,"")) -> success | H28: =IF($A28="","",IFERROR(Handnotes!$K$4,"")) -> YES | I28: =IF($A28="","",IFERROR(Handnotes!$M$4,"")) -> unsuccessfull | J28: =IF($A28="","",IFERROR(Handnotes!$O$4,"")) -> success | K28: =IF($A28="","",IFERROR(Handnotes!$P$4,"")) -> success | L28: =IF($A28="","",IFERROR(Handnotes!$Q$4,"")) -> success | M28: {=IF($D28="success",_xlfn.LET(_xlpm.run,$A28,_xlpm.start_cmd,IFERROR(_xlfn.XLOOKUP(1,(Event_logs!$A$2:$A$1588=_xlpm.run)*(Event_logs!$F$2:$F$1588="command")*(Event_logs!$G$2:$G$1588="trolley_command")*(Event_logs!$H$2:$H$1588="side_align"),Event_logs!$E$2:$E$1588),""),_xlpm.start_fb,IFERROR(_xlfn.XLOOKUP(1,(Event_logs!$A$2:$A$1588=_xlpm.run)*(Event_logs!$F$2:$F$1588="dropzone_status")*ISNUMBER(SEARCH("side_aligning",Event_logs!$I$2:$I$1588)),Event_logs!$E$2:$E$1588),""),_xlpm.start,IF(_xlpm.start_cmd<>"",_xlpm.start_cmd,_xlpm.start_fb),_xlpm.ende,IFERROR(_xlfn.XLOOKUP(1,(Event_logs!$A$2:$A$1588=_xlpm.run)*(Event_logs!$F$2:$F$1588="physical_status")*(Event_logs!$G$2:$G$1588="physical_alignment")*(Event_logs!$H$2:$H$1588="side_align_complete")*ISNUMBER(SEARCH("side_align_left_done",Event_logs!$I$2:$I$1588)),Event_logs!$E$2:$E$1588),""),_xlpm.diff,_xlpm.ende-_xlpm.start,_xlpm.sek,IF(_xlpm.diff>1000,_xlpm.diff/1000,_xlpm.diff),IFERROR(IF(AND(_xlpm.start<>"",_xlpm.ende<>"",_xlpm.sek>=0),_xlpm.sek,""),"")),"")} -> 18.675 | N28: {=IF($F28="success",_xlfn.LET(_xlpm.run,$A28,_xlpm.start_cmd,IFERROR(_xlfn.XLOOKUP(1,(Event_logs!$A$2:$A$1588=_xlpm.run)*(Event_logs!$F$2:$F$1588="command")*(Event_logs!$G$2:$G$1588="trolley_command")*(Event_logs!$H$2:$H$1588="drive_under"),Event_logs!$E$2:$E$1588),""),_xlpm.start_fb,IFERROR(_xlfn.XLOOKUP(1,(Event_logs!$A$2:$A$1588=_xlpm.run)*(Event_logs!$F$2:$F$1588="dropzone_status")*ISNUMBER(SEARCH("drive_under_active",Event_logs!$I$2:$I$1588)),Event_logs!$E$2:$E$1588),""),_xlpm.start,IF(_xlpm.start_cmd<>"",_xlpm.start_cmd,_xlpm.start_fb),_xlpm.ende,IFERROR(_xlfn.XLOOKUP(1,(Event_logs!$A$2:$A$1588=_xlpm.run)*(Event_logs!$F$2:$F$1588="physical_status")*(Event_logs!$G$2:$G$1588="physical_alignment")*(Event_logs!$H$2:$H$1588="under_trolley")*ISNUMBER(SEARCH("drive_straight_under_done",Event_logs!$I$2:$I$1588)),Event_logs!$E$2:$E$1588),""),_xlpm.diff,_xlpm.ende-_xlpm.start,_xlpm.sek,IF(_xlpm.diff>1000,_xlpm.diff/1000,_xlpm.diff),IFERROR(IF(AND(_xlpm.start<>"",_xlpm.ende<>"",_xlpm.sek>=0),_xlpm.sek,""),"")),"")} -> 9.483 | O28: {=IF($G28="success",_xlfn.LET(_xlpm.run,$A28,_xlpm.start_cmd,IFERROR(_xlfn.XLOOKUP(1,(Event_logs!$A$2:$A$1588=_xlpm.run)*(Event_logs!$F$2:$F$1588="command")*(Event_logs!$G$2:$G$1588="trolley_command")*(Event_logs!$H$2:$H$1588="fine_align"),Event_logs!$E$2:$E$1588),""),_xlpm.start_fb,IFERROR(_xlfn.XLOOKUP(1,(Event_logs!$A$2:$A$1588=_xlpm.run)*(Event_logs!$F$2:$F$1588="dropzone_status")*ISNUMBER(SEARCH("fine_aligning",Event_logs!$I$2:$I$1588)),Event_logs!$E$2:$E$1588),""),_xlpm.start,IF(_xlpm.start_cmd<>"",_xlpm.start_cmd,_xlpm.start_fb),_xlpm.ende,IFERROR(_xlfn.XLOOKUP(1,(Event_logs!$A$2:$A$1588=_xlpm.run)*(Event_logs!$F$2:$F$1588="physical_status")*(Event_logs!$G$2:$G$1588="physical_alignment")*(Event_logs!$H$2:$H$1588="fine_align_complete")*ISNUMBER(SEARCH("fine_align_under_done",Event_logs!$I$2:$I$1588)),Event_logs!$E$2:$E$1588),""),_xlpm.diff,_xlpm.ende-_xlpm.start,_xlpm.sek,IF(_xlpm.diff>1000,_xlpm.diff/1000,_xlpm.diff),IFERROR(IF(AND(_xlpm.start<>"",_xlpm.ende<>"",_xlpm.sek>=0),_xlpm.sek,""),"")),"")} -> 134.049 | P28: =IF(AND(D28="success",F28="success",G28="success"),SUM(M28:O28),"") -> 162.207 | Q28: =_xlfn.LET(_xlpm.t,$A28,_xlpm.s,_xlfn.MINIFS(Event_logs!$E$2:$E$1588,Event_logs!$A$2:$A$1588,_xlpm.t,Event_logs!$H$2:$H$1588,"fine_align_complete"),_xlpm.e,_xlfn.MINIFS(Event_logs!$E$2:$E$1588,Event_logs!$A$2:$A$1588,_xlpm.t,Event_logs!$H$2:$H$1588,"docking sucessfull"),IF(AND(OR($I28="success",$I28="sucess"),_xlpm.s>0,_xlpm.e>_xlpm.s),(_xlpm.e-_xlpm.s)/1000,"")) | R28: {=IF($D28="success",_xlfn.LET(_xlpm.d,_xlfn.XLOOKUP(1,(Event_logs!$A$2:$A$1588=$A28)*(Event_logs!$H$2:$H$1588="side_align_complete"),Event_logs!$I$2:$I$1588,""),IFERROR(_xlfn.NUMBERVALUE(_xlfn.TEXTBEFORE(_xlfn.TEXTAFTER(_xlpm.d,"error_x=")&" "," "),".",","),"")),"")} -> -0.0057 | S28: {=IF(AND($F28="success",$D28="success"),_xlfn.LET(_xlpm.d,_xlfn.XLOOKUP(1,(Event_logs!$A$2:$A$1588=$A28)*(Event_logs!$H$2:$H$1588="side_align_complete"),Event_logs!$I$2:$I$1588,""),IFERROR(_xlfn.NUMBERVALUE(_xlfn.TEXTBEFORE(_xlfn.TEXTAFTER(_xlpm.d,"error_x=")&" "," "),".",","),"")),"")} -> -0.0057 | T28: {=IF($D28="success",_xlfn.LET(_xlpm.d,_xlfn.XLOOKUP(1,(Event_logs!$A$2:$A$1588=$A28)*(Event_logs!$H$2:$H$1588="side_align_complete"),Event_logs!$I$2:$I$1588,""),IFERROR(_xlfn.NUMBERVALUE(_xlfn.TEXTBEFORE(_xlfn.TEXTAFTER(_xlpm.d,"yaw_error="),"deg"),".",","),"")),"")} -> 0.08 | U28: {=IF(AND($F28="success",D28="success"),_xlfn.LET(_xlpm.d,_xlfn.XLOOKUP(1,(Event_logs!$A$2:$A$1588=$A28)*(Event_logs!$H$2:$H$1588="side_align_complete"),Event_logs!$I$2:$I$1588,""),IFERROR(_xlfn.NUMBERVALUE(_xlfn.TEXTBEFORE(_xlfn.TEXTAFTER(_xlpm.d,"yaw_error="),"deg"),".",","),"")),"")} -> 0.08 | W28: {=IF(OR($G28="success",$G28="sucess"),_xlfn.LET(_xlpm.d,_xlfn.XLOOKUP(1,(Event_logs!$A$2:$A$1588=$A28)*(Event_logs!$H$2:$H$1588="side_align_complete"),Event_logs!$I$2:$I$1588,""),IFERROR(_xlfn.NUMBERVALUE(_xlfn.TEXTBEFORE(_xlfn.TEXTAFTER(_xlpm.d,"yaw="),"deg"),".",","),"")),"")} -> -179.92 | X28: {=IF(OR($G28="success",$G28="sucess"),_xlfn.XLOOKUP(1,(Event_logs!$A$2:$A$1588=$A28)*(Event_logs!$H$2:$H$1588="side_align_complete"),Event_logs!$I$2:$I$1588,""),"")} -> side_align_left_done | final camera=left ids=[17, 18, 19, 20] target_pair=[18, 19] target_x=+0.3503 target_y=+0.2783 center_x=+0.3593 center_y=+0.5844 yaw=-179.92deg error_x=-0.0057 yaw_error=+0.08deg tolerance_x=0.0060 tolerance_yaw=2.00deg | Z28: {=IF(OR($G28="success",$G28="sucess",$G28="unsuccessfull",$G28="partial"),_xlfn.LET(_xlpm.d,_xlfn.XLOOKUP(1,(Event_logs!$A$2:$A$1588=$A28)*(Event_logs!$H$2:$H$1588="fine_align_complete"),Event_logs!$I$2:$I$1588,""),IFERROR(_xlfn.NUMBERVALUE(_xlfn.TEXTBEFORE(_xlfn.TEXTAFTER(_xlpm.d,"error_x=")&" "," "),".",","),"")),"")} -> 0.0037 | AA28: {=IF(AND($G28="success",$I28="success"),_xlfn.LET(_xlpm.d,_xlfn.XLOOKUP(1,(Event_logs!$A$2:$A$1588=$A28)*(Event_logs!$H$2:$H$1588="fine_align_complete"),Event_logs!$I$2:$I$1588,""),IFERROR(_xlfn.NUMBERVALUE(_xlfn.TEXTBEFORE(_xlfn.TEXTAFTER(_xlpm.d,"error_x=")&" "," "),".",","),"")),"")} | AB28: {=IF($G28="success",_xlfn.LET(_xlpm.d,_xlfn.XLOOKUP(1,(Event_logs!$A$2:$A$1588=$A28)*(Event_logs!$H$2:$H$1588="fine_align_complete"),Event_logs!$I$2:$I$1588,""),IFERROR(_xlfn.NUMBERVALUE(_xlfn.TEXTBEFORE(_xlfn.TEXTAFTER(_xlpm.d,"error_y=")&" "," "),".",","),"")),"")} -> 0.005 | AC28: {=IF(AND($G28="success",$I28="success"),_xlfn.LET(_xlpm.d,_xlfn.XLOOKUP(1,(Event_logs!$A$2:$A$1588=$A28)*(Event_logs!$H$2:$H$1588="fine_align_complete"),Event_logs!$I$2:$I$1588,""),IFERROR(_xlfn.NUMBERVALUE(_xlfn.TEXTBEFORE(_xlfn.TEXTAFTER(_xlpm.d,"error_y=")&" "," "),".",","),"")),"")} | AD28: {=IF(AND($G28="success",$I28="success"),_xlfn.LET(_xlpm.d,_xlfn.XLOOKUP(1,(Event_logs!$A$2:$A$1588=$A28)*(Event_logs!$H$2:$H$1588="fine_align_complete"),Event_logs!$I$2:$I$1588,""),IFERROR(_xlfn.NUMBERVALUE(_xlfn.TEXTBEFORE(_xlfn.TEXTAFTER(_xlpm.d,"yaw_error="),"deg"),".",","),"")),"")} | AE28: {=IF($G28="success",_xlfn.LET(_xlpm.d,_xlfn.XLOOKUP(1,(Event_logs!$A$2:$A$1588=$A28)*(Event_logs!$H$2:$H$1588="fine_align_complete"),Event_logs!$I$2:$I$1588,""),IFERROR(_xlfn.NUMBERVALUE(_xlfn.TEXTBEFORE(_xlfn.TEXTAFTER(_xlpm.d,"yaw_error="),"deg"),".",","),"")),"")} -> -0.01
