Workbook

Sheet elevator_wifi
A1: timestamp | B1: command | C1: url | D1: success | E1: http_status | F1: response_time_ms | G1: response_bytes | H1: press_finished | I1: energy_saving_mode | J1: threshold | K1: threshold_reached | L1: trigger_angle | M1: fsr_raw | N1: fsr_voltage | O1: status | P1: wifi_mode | Q1: wifi_ssid | R1: ip | S1: wifi_connected | T1: current_angle | U1: fsr_threshold | V1: last_fsr_raw | W1: last_fsr_voltage | X1: last_trigger_angle | Y1: last_press_reached_threshold | Z1: wifi_rssi_dbm | AA1: response | AB1: error
A2: 2026-06-21T19:13:08.193 | B2: press | C2: http://192.168.8.226/press | D2: True | E2: 200 | F2: 1277.11 | G2: 147 | H2: yes | I2: yes | J2: 10 | K2: yes | L2: 176 | M2: 27 | N2: 0.0218 | Z2: -34 | AA2: Press command finished | energy_saving_mode=yes | threshold=10 | threshold_reached=yes | trigger_angle=176 | fsr_raw=27 | fsr_voltage=0.0218 | wifi_rssi_dbm=-34
A3: 2026-06-21T19:13:24.622 | B3: press | C3: http://192.168.8.226/press | D3: True | E3: 200 | F3: 4374.44 | G3: 146 | H3: yes | I3: yes | J3: 10 | K3: yes | L3: 98 | M3: 16 | N3: 0.0129 | Z3: -36 | AA3: Press command finished | energy_saving_mode=yes | threshold=10 | threshold_reached=yes | trigger_angle=98 | fsr_raw=16 | fsr_voltage=0.0129 | wifi_rssi_dbm=-36
A4: 2026-06-21T19:14:25.036 | B4: press | C4: http://192.168.8.226/press | D4: True | E4: 200 | F4: 1070.82 | G4: 147 | H4: yes | I4: yes | J4: 20 | K4: yes | L4: 180 | M4: 20 | N4: 0.0161 | Z4: -39 | AA4: Press command finished | energy_saving_mode=yes | threshold=20 | threshold_reached=yes | trigger_angle=180 | fsr_raw=20 | fsr_voltage=0.0161 | wifi_rssi_dbm=-39
A5: 2026-06-21T19:15:28.599 | B5: press | C5: http://192.168.8.226/press | D5: True | E5: 200 | F5: 6504.3 | G5: 147 | H5: yes | I5: yes | J5: 50 | K5: yes | L5: 45 | M5: 206 | N5: 0.166 | Z5: -36 | AA5: Press command finished | energy_saving_mode=yes | threshold=50 | threshold_reached=yes | trigger_angle=45 | fsr_raw=206 | fsr_voltage=0.1660 | wifi_rssi_dbm=-36
A6: 2026-06-21T19:16:30.526 | B6: press | C6: http://192.168.8.226/press | D6: True | E6: 200 | F6: 6985.64 | G6: 147 | H6: yes | I6: yes | J6: 50 | K6: yes | L6: 43 | M6: 158 | N6: 0.1273 | Z6: -47 | AA6: Press command finished | energy_saving_mode=yes | threshold=50 | threshold_reached=yes | trigger_angle=43 | fsr_raw=158 | fsr_voltage=0.1273 | wifi_rssi_dbm=-47
A7: 2026-06-21T19:18:39.920 | B7: press | C7: http://192.168.8.226/press | D7: True | E7: 200 | F7: 6512.91 | G7: 147 | H7: yes | I7: yes | J7: 50 | K7: yes | L7: 44 | M7: 120 | N7: 0.0967 | Z7: -41 | AA7: Press command finished | energy_saving_mode=yes | threshold=50 | threshold_reached=yes | trigger_angle=44 | fsr_raw=120 | fsr_voltage=0.0967 | wifi_rssi_dbm=-41
A8: 2026-06-21T19:18:56.486 | B8: press | C8: http://192.168.8.226/press | D8: True | E8: 200 | F8: 6680.63 | G8: 147 | H8: yes | I8: yes | J8: 50 | K8: yes | L8: 45 | M8: 105 | N8: 0.0846 | Z8: -40 | AA8: Press command finished | energy_saving_mode=yes | threshold=50 | threshold_reached=yes | trigger_angle=45 | fsr_raw=105 | fsr_voltage=0.0846 | wifi_rssi_dbm=-40
A9: 2026-06-21T19:19:11.362 | B9: press | C9: http://192.168.8.226/press | D9: True | E9: 200 | F9: 6751.25 | G9: 147 | H9: yes | I9: yes | J9: 50 | K9: yes | L9: 44 | M9: 172 | N9: 0.1386 | Z9: -43 | AA9: Press command finished | energy_saving_mode=yes | threshold=50 | threshold_reached=yes | trigger_angle=44 | fsr_raw=172 | fsr_voltage=0.1386 | wifi_rssi_dbm=-43
A10: 2026-06-21T19:20:46.243 | B10: press | C10: http://192.168.8.226/press | D10: True | E10: 200 | F10: 6644.41 | G10: 147 | H10: yes | I10: yes | J10: 50 | K10: yes | L10: 45 | M10: 166 | N10: 0.1338 | Z10: -39 | AA10: Press command finished | energy_saving_mode=yes | threshold=50 | threshold_reached=yes | trigger_angle=45 | fsr_raw=166 | fsr_voltage=0.1338 | wifi_rssi_dbm=-39
A11: 2026-06-21T19:20:59.350 | B11: press | C11: http://192.168.8.226/press | D11: True | E11: 200 | F11: 6540.67 | G11: 147 | H11: yes | I11: yes | J11: 50 | K11: yes | L11: 45 | M11: 167 | N11: 0.1346 | Z11: -45 | AA11: Press command finished | energy_saving_mode=yes | threshold=50 | threshold_reached=yes | trigger_angle=45 | fsr_raw=167 | fsr_voltage=0.1346 | wifi_rssi_dbm=-45
A12: 2026-06-21T19:21:10.655 | B12: press | C12: http://192.168.8.226/press | D12: True | E12: 200 | F12: 6526.52 | G12: 147 | H12: yes | I12: yes | J12: 50 | K12: yes | L12: 44 | M12: 158 | N12: 0.1273 | Z12: -47 | AA12: Press command finished | energy_saving_mode=yes | threshold=50 | threshold_reached=yes | trigger_angle=44 | fsr_raw=158 | fsr_voltage=0.1273 | wifi_rssi_dbm=-47
A13: 2026-06-21T19:21:20.076 | B13: press | C13: http://192.168.8.226/press | D13: True | E13: 200 | F13: 6517.65 | G13: 147 | H13: yes | I13: yes | J13: 50 | K13: yes | L13: 44 | M13: 157 | N13: 0.1265 | Z13: -50 | AA13: Press command finished | energy_saving_mode=yes | threshold=50 | threshold_reached=yes | trigger_angle=44 | fsr_raw=157 | fsr_voltage=0.1265 | wifi_rssi_dbm=-50
... A56: 2026-06-21T19:35:43.428 | B56: press | C56: http://192.168.8.226/press | D56: True | E56: 200 | F56: 8294.69 | G56: 144 | H56: yes | I56: yes | J56: 50 | K56: no | L56: 0 | M56: 29 | N56: 0.0234 | Z56: -57 | AA56: Press command finished | energy_saving_mode=yes | threshold=50 | threshold_reached=no | trigger_angle=0 | fsr_raw=29 | fsr_voltage=0.0234 | wifi_rssi_dbm=-57

Sheet elevator_ble
A1: timestamp | B1: command | C1: device_name | D1: device_address | E1: success | F1: scan_ms | G1: rssi_last_dbm | H1: rssi_mean_dbm | I1: rssi_min_dbm | J1: rssi_max_dbm | K1: rssi_samples | L1: connect_ms | M1: notify_setup_ms | N1: command_write_ms | O1: time_to_first_response_ms | P1: response_wait_ms | Q1: disconnect_ms | R1: total_ms | S1: notification_count | T1: response_line_count | U1: press_finished | V1: threshold | W1: threshold_reached
A2: 2026-06-21T21:53:10,878 | B2: PRESS | C2: XIAO-FSR-SERVO | D2: F6:75:48:70:C7:F7 | E2: True | F2: 6091.18 | G2: -64 | H2: -68.83 | I2: -76 | J2: -64 | K2: 6 | L2: 2457.12 | M2: 169.55 | N2: 1.72 | O2: 88.82 | P2: 9164.44 | Q2: 2218.7 | R2: 20108.12 | S2: 19 | T2: 10 | U2: yes | V2: 50 | W2: yes
A3: 2026-06-21T21:53:40,990 | B3: PRESS | C3: XIAO-FSR-SERVO | D3: F6:75:48:70:C7:F7 | E3: True | F3: 6034.84 | G3: -75 | H3: -68.89 | I3: -77 | J3: -57 | K3: 9 | L3: 1379.94 | M3: 172.76 | N3: 1.06 | O3: 134.09 | P3: 9209.88 | Q3: 2219.61 | R3: 19020.94 | S3: 18 | T3: 9 | U3: yes | V3: 50 | W3: yes
A4: 2026-06-21T21:54:03,907 | B4: PRESS | C4: XIAO-FSR-SERVO | D4: F6:75:48:70:C7:F7 | E4: True | F4: 6080.28 | G4: -64 | H4: -65.83 | I4: -74 | J4: -58 | K4: 12 | L4: 3887.16 | M4: 173.2 | N4: 1.06 | O4: 134.09 | P4: 9210.95 | Q4: 2759.26 | R4: 22114.6 | S4: 19 | T4: 10 | U4: yes | V4: 50 | W4: yes
A5: 2026-06-21T21:54:41,926 | B5: PRESS | C5: XIAO-FSR-SERVO | D5: F6:75:48:70:C7:F7 | E5: True | F5: 6042.38 | G5: -70 | H5: -68.82 | I5: -75 | J5: -60 | K5: 11 | L5: 1545.55 | M5: 173.1 | N5: 1.03 | O5: 89.12 | P5: 9165.37 | Q5: 2128.95 | R5: 19059.06 | S5: 19 | T5: 10 | U5: yes | V5: 50 | W5: yes
A6: 2026-06-21T21:55:03,514 | B6: PRESS | C6: XIAO-FSR-SERVO | D6: F6:75:48:70:C7:F7 | E6: True | F6: 6048.05 | G6: -72 | H6: -69.22 | I6: -79 | J6: -65 | K6: 9 | L6: 2271.43 | M6: 173.7 | N6: 0.99 | O6: 88.88 | P6: 9120.02 | Q6: 1859.62 | R6: 19476.3 | S6: 18 | T6: 9 | U6: yes | V6: 50 | W6: yes
A7: 2026-06-21T21:55:27,599 | B7: PRESS | C7: XIAO-FSR-SERVO | D7: F6:75:48:70:C7:F7 | E7: True | F7: 6026.89 | G7: -85 | H7: -73.6 | I7: -85 | J7: -64 | K7: 10 | L7: 1741 | M7: 174.45 | N7: 1.43 | O7: 133.38 | P7: 9209.34 | Q7: 2264.86 | R7: 19420.52 | S7: 19 | T7: 10 | U7: yes | V7: 50 | W7: yes
A8: 2026-06-21T21:55:48,666 | B8: PRESS | C8: XIAO-FSR-SERVO | D8: F6:75:48:70:C7:F7 | E8: True | F8: 6059.66 | G8: -61 | H8: -63.75 | I8: -72 | J8: -59 | K8: 8 | L8: 1657.16 | M8: 174.05 | N8: 1.41 | O8: 88.26 | P8: 9163.76 | Q8: 2264.15 | R8: 19322.63 | S8: 19 | T8: 10 | U8: yes | V8: 50 | W8: yes
A9: 2026-06-21T21:56:09,405 | B9: PRESS | C9: XIAO-FSR-SERVO | D9: F6:75:48:70:C7:F7 | E9: False | F9: 6029.61 | G9: -66 | H9: -64.11 | I9: -74 | J9: -59 | K9: 9 | L9: 1377.6 | M9: 173.41 | N9: 1.04 | O9: 89.25 | P9: 15306.54 | Q9: 2691.77 | R9: 25583.53 | S9: 23 | T9: 11 | U9: no | V9: 50 | W9: yes
A10: 2026-06-21T21:56:36,626 | B10: PRESS | C10: XIAO-FSR-SERVO | D10: F6:75:48:70:C7:F7 | E10: True | F10: 6024.62 | G10: -70 | H10: -70.2 | I10: -77 | J10: -66 | K10: 10 | L10: 4266.08 | M10: 174.47 | N10: 2.41 | O10: 87.44 | P10: 9162.23 | Q10: 2759.13 | R10: 22391.85 | S10: 19 | T10: 10 | U10: yes | V10: 50 | W10: yes
A11: 2026-06-21T21:57:01,080 | B11: PRESS | C11: XIAO-FSR-SERVO | D11: F6:75:48:70:C7:F7 | E11: True | F11: 6038.3 | G11: -61 | H11: -67.8 | I11: -78 | J11: -60 | K11: 10 | L11: 1802.44 | M11: 174.2 | N11: 1.09 | O11: 88.64 | P11: 9119.73 | Q11: 2757.66 | R11: 19896.94 | S11: 19 | T11: 10 | U11: yes | V11: 50 | W11: yes
A12: 2026-06-21T21:57:23,877 | B12: PRESS | C12: XIAO-FSR-SERVO | D12: F6:75:48:70:C7:F7 | E12: True | F12: 6037.12 | G12: -63 | H12: -67 | I12: -72 | J12: -62 | K12: 11 | L12: 1416.6 | M12: 173.7 | N12: 1.04 | O12: 89.17 | P12: 9165.32 | Q12: 2309.31 | R12: 19106.4 | S12: 19 | T12: 10 | U12: yes | V12: 50 | W12: yes
A13: 2026-06-21T21:57:44,957 | B13: PRESS | C13: XIAO-FSR-SERVO | D13: F6:75:48:70:C7:F7 | E13: True | F13: 6085.02 | G13: -63 | H13: -64.75 | I13: -73 | J13: -60 | K13: 12 | L13: 1258.58 | M13: 173.62 | N13: 1.1 | O13: 89.13 | P13: 9121.15 | Q13: 2397.25 | R13: 19040.07 | S13: 19 | T13: 10 | U13: yes | V13: 50 | W13: yes
... A55: 2026-06-21T22:15:50,601 | B55: PRESS | C55: XIAO-FSR-SERVO | D55: F6:75:48:70:C7:F7 | E55: True | F55: 6087.82 | G55: -50 | H55: -50.82 | I55: -56 | J55: -43 | K55: 11 | L55: 1625.98 | M55: 173.59 | N55: 1.13 | O55: 88.84 | P55: 9119.52 | Q55: 2399.69 | R55: 19410.22 | S55: 19 | T55: 10 | U55: yes | V55: 50 | W55: yes

Sheet dist_wifi
A1: source_csv | B1: cycle_id | C1: timestamp | D1: distance_m | E1: attempt | F1: url | G1: success | H1: attempt_started_at | I1: attempt_completed_at | J1: attempt_total_ms | K1: tcp_connect_success | L1: tcp_connect_ms | M1: tcp_error | N1: request_started_at | O1: headers_received_at | P1: response_completed_at | Q1: time_to_headers_ms | R1: body_download_ms | S1: http_total_ms | T1: measurement_total_ms | U1: http_status | V1: response_bytes | W1: press_finished | X1: threshold | Y1: threshold_reached | Z1: trigger_angle | AA1: fsr_raw | AB1: fsr_voltage | AC1: esp32_rssi_dbm | AD1: robot_wifi_signal_before_dbm | AE1: robot_wifi_signal_after_dbm
A2: distance_check_wifi_20260621_150721.csv | B2: 1 | C2: 2026-06-21T15:07:31.777 | D2: 1 | E2: 1 | F2: http://192.168.8.226/press | G2: TRUE | H2: 2026-06-21T15:07:23.470 | I2: 2026-06-21T15:07:31.777 | J2: 8306.62 | K2: TRUE | L2: 24.97 | N2: 2026-06-21T15:07:23.504 | O2: 2026-06-21T15:07:31.764 | P2: 2026-06-21T15:07:31.767 | Q2: 8260.72 | R2: 2.15 | S2: 8262.9 | T2: 8288.03 | U2: 200 | V2: 144 | W2: yes | X2: 100 | Y2: no | Z2: 0 | AA2: 0 | AB2: 0 | AC2: -66 | AD2: -68 | AE2: -68
A3: distance_check_wifi_20260621_150721.csv | B3: 1 | C3: 2026-06-21T15:08:05.793 | D3: 2 | E3: 1 | F3: http://192.168.8.226/press | G3: TRUE | H3: 2026-06-21T15:07:57.450 | I3: 2026-06-21T15:08:05.793 | J3: 8343.54 | K3: TRUE | L3: 51.23 | N3: 2026-06-21T15:07:57.508 | O3: 2026-06-21T15:08:05.783 | P3: 2026-06-21T15:08:05.784 | Q3: 8274.69 | R3: 0.34 | S3: 8275.05 | T3: 8326.48 | U3: 200 | V3: 144 | W3: yes | X3: 100 | Y3: no | Z3: 0 | AA3: 0 | AB3: 0 | AC3: -71 | AD3: -68 | AE3: -68
A4: distance_check_wifi_20260621_150721.csv | B4: 1 | C4: 2026-06-21T15:08:27.961 | D4: 3 | E4: 1 | F4: http://192.168.8.226/press | G4: TRUE | H4: 2026-06-21T15:08:19.223 | I4: 2026-06-21T15:08:27.961 | J4: 8737.6 | K4: TRUE | L4: 271.67 | N4: 2026-06-21T15:08:19.503 | O4: 2026-06-21T15:08:27.914 | P4: 2026-06-21T15:08:27.953 | Q4: 8411.59 | R4: 38.65 | S4: 8450.29 | T4: 8722.16 | U4: 200 | V4: 144 | W4: yes | X4: 100 | Y4: no | Z4: 0 | AA4: 1 | AB4: 0.0008 | AC4: -73 | AD4: -67 | AE4: -68
A5: distance_check_wifi_20260621_150721.csv | B5: 1 | C5: 2026-06-21T15:08:46.511 | D5: 4 | E5: 1 | F5: http://192.168.8.226/press | G5: TRUE | H5: 2026-06-21T15:08:37.962 | I5: 2026-06-21T15:08:46.511 | J5: 8549.6 | K5: TRUE | L5: 98.15 | N5: 2026-06-21T15:08:38.067 | O5: 2026-06-21T15:08:46.474 | P5: 2026-06-21T15:08:46.504 | Q5: 8406.93 | R5: 29.19 | S5: 8436.17 | T5: 8534.52 | U5: 200 | V5: 144 | W5: yes | X5: 100 | Y5: no | Z5: 0 | AA5: 0 | AB5: 0 | AC5: -76 | AD5: -68 | AE5: -68
A6: distance_check_wifi_20260621_150721.csv | B6: 1 | C6: 2026-06-21T15:09:02.522 | D6: 5 | E6: 1 | F6: http://192.168.8.226/press | G6: TRUE | H6: 2026-06-21T15:08:54.026 | I6: 2026-06-21T15:09:02.522 | J6: 8495.85 | K6: TRUE | L6: 197.11 | N6: 2026-06-21T15:08:54.232 | O6: 2026-06-21T15:09:02.502 | P6: 2026-06-21T15:09:02.515 | Q6: 8270.7 | R6: 12.21 | S6: 8282.94 | T6: 8480.26 | U6: 200 | V6: 144 | W6: yes | X6: 100 | Y6: no | Z6: 0 | AA6: 0 | AB6: 0 | AC6: -71 | AD6: -68 | AE6: -68
A7: distance_check_wifi_20260621_150721.csv | B7: 1 | C7: 2026-06-21T15:09:17.876 | D7: 6 | E7: 1 | F7: http://192.168.8.226/press | G7: TRUE | H7: 2026-06-21T15:09:09.526 | I7: 2026-06-21T15:09:17.876 | J7: 8349.89 | K7: TRUE | L7: 54.73 | N7: 2026-06-21T15:09:09.589 | O7: 2026-06-21T15:09:17.868 | P7: 2026-06-21T15:09:17.868 | Q7: 8278.92 | R7: 0.62 | S7: 8279.58 | T7: 8334.51 | U7: 200 | V7: 144 | W7: yes | X7: 100 | Y7: no | Z7: 0 | AA7: 0 | AB7: 0 | AC7: -73 | AD7: -68 | AE7: -68
A8: distance_check_wifi_20260621_150721.csv | B8: 1 | C8: 2026-06-21T15:09:40.863 | D8: 7 | E8: 1 | F8: http://192.168.8.226/press | G8: TRUE | H8: 2026-06-21T15:09:32.271 | I8: 2026-06-21T15:09:40.863 | J8: 8591.04 | K8: TRUE | L8: 102.22 | N8: 2026-06-21T15:09:32.382 | O8: 2026-06-21T15:09:40.808 | P8: 2026-06-21T15:09:40.853 | Q8: 8426.57 | R8: 44.68 | S8: 8471.29 | T8: 8573.68 | U8: 200 | V8: 144 | W8: yes | X8: 100 | Y8: no | Z8: 0 | AA8: 0 | AB8: 0 | AC8: -78 | AD8: -68 | AE8: -68
A9: distance_check_wifi_20260621_150721.csv | B9: 1 | C9: 2026-06-21T15:10:03.803 | D9: 8 | E9: 1 | F9: http://192.168.8.226/press | G9: TRUE | H9: 2026-06-21T15:09:55.181 | I9: 2026-06-21T15:10:03.803 | J9: 8622.69 | K9: TRUE | L9: 109.21 | N9: 2026-06-21T15:09:55.299 | O9: 2026-06-21T15:10:03.747 | P9: 2026-06-21T15:10:03.795 | Q9: 8447.94 | R9: 47.5 | S9: 8495.48 | T9: 8604.87 | U9: 200 | V9: 144 | W9: yes | X9: 100 | Y9: no | Z9: 0 | AA9: 0 | AB9: 0 | AC9: -76 | AD9: -68 | AE9: -68
A10: distance_check_wifi_20260621_150721.csv | B10: 1 | C10: 2026-06-21T15:10:32.997 | D10: 9 | E10: 1 | F10: http://192.168.8.226/press | G10: FALSE | H10: 2026-06-21T15:10:17.693 | I10: 2026-06-21T15:10:32.997 | J10: 15303.89 | K10: TRUE | L10: 140.1 | N10: 2026-06-21T15:10:17.843 | P10: 2026-06-21T15:10:32.989 | S10: 15146.3 | T10: 15286.62 | W10: no | AD10: -68 | AE10: -68
A11: distance_check_wifi_20260621_150721.csv | B11: 1 | C11: 2026-06-21T15:10:59.717 | D11: 10 | E11: 1 | F11: http://192.168.8.226/press | G11: FALSE | H11: 2026-06-21T15:10:52.527 | I11: 2026-06-21T15:10:59.717 | J11: 7189.48 | K11: FALSE | L11: 4100.23 | M11: [Errno 113] No route to host | N11: 2026-06-21T15:10:56.637 | P11: 2026-06-21T15:10:59.709 | S11: 3072.3 | T11: 7172.65 | W11: no | AD11: -68 | AE11: -68
A12: distance_check_wifi_20260621_151117.csv | B12: 2 | C12: 2026-06-21T15:11:46.335 | D12: 1 | E12: 1 | F12: http://192.168.8.226/press | G12: TRUE | H12: 2026-06-21T15:11:37.892 | I12: 2026-06-21T15:11:46.335 | J12: 8442.63 | K12: TRUE | L12: 167.63 | N12: 2026-06-21T15:11:38.069 | O12: 2026-06-21T15:11:46.327 | P12: 2026-06-21T15:11:46.327 | Q12: 8258.04 | R12: 0.33 | S12: 8258.39 | T12: 8426.2 | U12: 200 | V12: 144 | W12: yes | X12: 100 | Y12: no | Z12: 0 | AA12: 0 | AB12: 0 | AC12: -69 | AD12: -68 | AE12: -68
A13: distance_check_wifi_20260621_151117.csv | B13: 2 | C13: 2026-06-21T15:12:06.011 | D13: 2 | E13: 1 | F13: http://192.168.8.226/press | G13: TRUE | H13: 2026-06-21T15:11:57.695 | I13: 2026-06-21T15:12:06.011 | J13: 8315.28 | K13: TRUE | L13: 39.39 | N13: 2026-06-21T15:11:57.743 | O13: 2026-06-21T15:12:06.001 | P13: 2026-06-21T15:12:06.001 | Q13: 8257.64 | R13: 0.28 | S13: 8257.94 | T13: 8297.5 | U13: 200 | V13: 144 | W13: yes | X13: 100 | Y13: no | Z13: 0 | AA13: 0 | AB13: 0 | AC13: -71 | AD13: -68 | AE13: -68
A14: distance_check_wifi_20260621_151117.csv | B14: 2 | C14: 2026-06-21T15:12:44.894 | D14: 3 | E14: 1 | F14: http://192.168.8.226/press | G14: FALSE | H14: 2026-06-21T15:12:14.854 | I14: 2026-06-21T15:12:44.894 | J14: 30040.37 | K14: FALSE | L14: 15007.15 | M14: timed out | N14: 2026-06-21T15:12:29.869 | P14: 2026-06-21T15:12:44.885 | S14: 15016.58 | T14: 30023.85 | W14: no | AD14: -68 | AE14: -68
A15: distance_check_wifi_20260621_151321.csv | B15: 3 | C15: 2026-06-21T15:13:45.727 | D15: 1 | E15: 1 | F15: http://192.168.8.226/press | G15: TRUE | H15: 2026-06-21T15:13:37.132 | I15: 2026-06-21T15:13:45.727 | J15: 8594.6 | K15: TRUE | L15: 234.97 | N15: 2026-06-21T15:13:37.376 | O15: 2026-06-21T15:13:45.718 | P15: 2026-06-21T15:13:45.718 | Q15: 8341.79 | R15: 0.29 | S15: 8342.1 | T15: 8577.26 | U15: 200 | V15: 144 | W15: yes | X15: 100 | Y15: no | Z15: 0 | AA15: 0 | AB15: 0 | AC15: -69 | AD15: -68 | AE15: -68
A16: distance_check_wifi_20260621_151321.csv | B16: 3 | C16: 2026-06-21T15:14:07.030 | D16: 2 | E16: 1 | F16: http://192.168.8.226/press | G16: TRUE | H16: 2026-06-21T15:13:58.738 | I16: 2026-06-21T15:14:07.030 | J16: 8292.39 | K16: TRUE | L16: 18.67 | N16: 2026-06-21T15:13:58.765 | O16: 2026-06-21T15:14:07.023 | P16: 2026-06-21T15:14:07.023 | Q16: 8257.91 | R16: 0.29 | S16: 8258.23 | T16: 8277.12 | U16: 200 | V16: 144 | W16: yes | X16: 100 | Y16: no | Z16: 0 | AA16: 0 | AB16: 0 | AC16: -70 | AD16: -67 | AE16: -68
A17: distance_check_wifi_20260621_151321.csv | B17: 3 | C17: 2026-06-21T15:14:26.160 | D17: 3 | E17: 1 | F17: http://192.168.8.226/press | G17: TRUE | H17: 2026-06-21T15:14:17.438 | I17: 2026-06-21T15:14:26.160 | J17: 8722.35 | K17: TRUE | L17: 242.73 | N17: 2026-06-21T15:14:17.689 | O17: 2026-06-21T15:14:26.113 | P17: 2026-06-21T15:14:26.152 | Q17: 8424.24 | R17: 38.34 | S17: 8462.62 | T17: 8705.56 | U17: 200 | V17: 144 | W17: yes | X17: 100 | Y17: no | Z17: 0 | AA17: 0 | AB17: 0 | AC17: -75 | AD17: -68 | AE17: -68
A18: distance_check_wifi_20260621_151321.csv | B18: 3 | C18: 2026-06-21T15:14:46.170 | D18: 4 | E18: 1 | F18: http://192.168.8.226/press | G18: TRUE | H18: 2026-06-21T15:14:37.619 | I18: 2026-06-21T15:14:46.170 | J18: 8550.91 | K18: TRUE | L18: 99.17 | N18: 2026-06-21T15:14:37.726 | O18: 2026-06-21T15:14:46.116 | P18: 2026-06-21T15:14:46.162 | Q18: 8389.4 | R18: 45.82 | S18: 8435.27 | T18: 8534.68 | U18: 200 | V18: 144 | W18: yes | X18: 100 | Y18: no | Z18: 0 | AA18: 1 | AB18: 0.0008 | AC18: -73 | AD18: -68 | AE18: -68
A19: distance_check_wifi_20260621_151321.csv | B19: 3 | C19: 2026-06-21T15:15:04.784 | D19: 5 | E19: 1 | F19: http://192.168.8.226/press | G19: TRUE | H19: 2026-06-21T15:14:56.373 | I19: 2026-06-21T15:15:04.784 | J19: 8411.5 | K19: TRUE | L19: 138.07 | N19: 2026-06-21T15:14:56.519 | O19: 2026-06-21T15:15:04.775 | P19: 2026-06-21T15:15:04.776 | Q19: 8256.62 | R19: 0.46 | S19: 8257.1 | T19: 8395.32 | U19: 200 | V19: 144 | W19: yes | X19: 100 | Y19: no | Z19: 0 | AA19: 0 | AB19: 0 | AC19: -68 | AD19: -67 | AE19: -68
A20: distance_check_wifi_20260621_151321.csv | B20: 3 | C20: 2026-06-21T15:15:42.779 | D20: 6 | E20: 1 | F20: http://192.168.8.226/press | G20: FALSE | H20: 2026-06-21T15:15:12.732 | I20: 2026-06-21T15:15:42.779 | J20: 30045.97 | K20: FALSE | L20: 15012.03 | M20: timed out | N20: 2026-06-21T15:15:27.753 | P20: 2026-06-21T15:15:42.769 | S20: 15016.54 | T20: 30028.68 | W20: no | AD20: -68 | AE20: -68
A21: distance_check_wifi_20260621_151559.csv | B21: 4 | C21: 2026-06-21T15:16:22.812 | D21: 1 | E21: 1 | F21: http://192.168.8.226/press | G21: TRUE | H21: 2026-06-21T15:16:14.254 | I21: 2026-06-21T15:16:22.811 | J21: 8557.57 | K21: TRUE | L21: 203.64 | N21: 2026-06-21T15:16:14.466 | O21: 2026-06-21T15:16:22.803 | P21: 2026-06-21T15:16:22.804 | Q21: 8337.56 | R21: 0.36 | S21: 8337.94 | T21: 8541.73 | U21: 200 | V21: 144 | W21: yes | X21: 100 | Y21: no | Z21: 0 | AA21: 0 | AB21: 0 | AC21: -68 | AD21: -67 | AE21: -68
A22: distance_check_wifi_20260621_151559.csv | B22: 4 | C22: 2026-06-21T15:16:43.919 | D22: 2 | E22: 1 | F22: http://192.168.8.226/press | G22: TRUE | H22: 2026-06-21T15:16:35.483 | I22: 2026-06-21T15:16:43.919 | J22: 8436.12 | K22: TRUE | L22: 149.81 | N22: 2026-06-21T15:16:35.641 | O22: 2026-06-21T15:16:43.896 | P22: 2026-06-21T15:16:43.911 | Q22: 8255.17 | R22: 14.94 | S22: 8270.16 | T22: 8420.13 | U22: 200 | V22: 144 | W22: yes | X22: 100 | Y22: no | Z22: 0 | AA22: 1 | AB22: 0.0008 | AC22: -72 | AD22: -68 | AE22: -68
A23: distance_check_wifi_20260621_151559.csv | B23: 4 | C23: 2026-06-21T15:17:02.223 | D23: 3 | E23: 1 | F23: http://192.168.8.226/press | G23: TRUE | H23: 2026-06-21T15:16:53.705 | I23: 2026-06-21T15:17:02.223 | J23: 8517.87 | K23: TRUE | L23: 159.53 | N23: 2026-06-21T15:16:53.873 | O23: 2026-06-21T15:17:02.214 | P23: 2026-06-21T15:17:02.215 | Q23: 8340.95 | R23: 0.31 | S23: 8341.28 | T23: 8501.04 | U23: 200 | V23: 144 | W23: yes | X23: 100 | Y23: no | Z23: 0 | AA23: 0 | AB23: 0 | AC23: -75 | AD23: -67 | AE23: -68
A24: distance_check_wifi_20260621_151559.csv | B24: 4 | C24: 2026-06-21T15:17:20.525 | D24: 4 | E24: 1 | F24: http://192.168.8.226/press | G24: TRUE | H24: 2026-06-21T15:17:12.063 | I24: 2026-06-21T15:17:20.525 | J24: 8461.9 | K24: TRUE | L24: 33.42 | N24: 2026-06-21T15:17:12.105 | O24: 2026-06-21T15:17:20.513 | P24: 2026-06-21T15:17:20.516 | Q24: 8408.07 | R24: 3.08 | S24: 8411.17 | T24: 8444.79 | U24: 200 | V24: 144 | W24: yes | X24: 100 | Y24: no | Z24: 0 | AA24: 0 | AB24: 0 | AC24: -73 | AD24: -68 | AE24: -68
A25: distance_check_wifi_20260621_151559.csv | B25: 4 | C25: 2026-06-21T15:17:40.458 | D25: 5 | E25: 1 | F25: http://192.168.8.226/press | G25: TRUE | H25: 2026-06-21T15:17:31.953 | I25: 2026-06-21T15:17:40.458 | J25: 8505.02 | K25: TRUE | L25: 205.25 | N25: 2026-06-21T15:17:32.166 | O25: 2026-06-21T15:17:40.423 | P25: 2026-06-21T15:17:40.448 | Q25: 8256.98 | R25: 24.99 | S25: 8282.02 | T25: 8487.49 | U25: 200 | V25: 144 | W25: yes | X25: 100 | Y25: no | Z25: 0 | AA25: 0 | AB25: 0 | AC25: -70 | AD25: -68 | AE25: -68
A26: distance_check_wifi_20260621_151559.csv | B26: 4 | C26: 2026-06-21T15:18:01.759 | D26: 6 | E26: 1 | F26: http://192.168.8.226/press | G26: TRUE | H26: 2026-06-21T15:17:50.024 | I26: 2026-06-21T15:18:01.759 | J26: 11735.05 | K26: TRUE | L26: 418.67 | N26: 2026-06-21T15:17:50.451 | O26: 2026-06-21T15:18:01.749 | P26: 2026-06-21T15:18:01.749 | Q26: 11298.06 | R26: 0.29 | S26: 11298.37 | T26: 11717.22 | U26: 200 | V26: 144 | W26: yes | X26: 100 | Y26: no | Z26: 0 | AA26: 0 | AB26: 0 | AC26: -80 | AD26: -68 | AE26: -68
A27: distance_check_wifi_20260621_151559.csv | B27: 4 | C27: 2026-06-21T15:18:19.961 | D27: 7 | E27: 1 | F27: http://192.168.8.226/press | G27: TRUE | H27: 2026-06-21T15:18:11.327 | I27: 2026-06-21T15:18:19.961 | J27: 8634.31 | K27: TRUE | L27: 179.59 | N27: 2026-06-21T15:18:11.515 | O27: 2026-06-21T15:18:19.945 | P27: 2026-06-21T15:18:19.954 | Q27: 8429.76 | R27: 9.07 | S27: 8438.87 | T27: 8618.65 | U27: 200 | V27: 144 | W27: yes | X27: 100 | Y27: no | Z27: 0 | AA27: 0 | AB27: 0 | AC27: -80 | AD27: -68 | AE27: -68
A28: distance_check_wifi_20260621_151559.csv | B28: 4 | C28: 2026-06-21T15:18:46.077 | D28: 8 | E28: 1 | F28: http://192.168.8.226/press | G28: FALSE | H28: 2026-06-21T15:18:30.882 | I28: 2026-06-21T15:18:46.077 | J28: 15194.73 | K28: TRUE | L28: 66.09 | N28: 2026-06-21T15:18:30.956 | P28: 2026-06-21T15:18:46.069 | S28: 15113.09 | T28: 15179.33 | W28: no | AD28: -68 | AE28: -68
C32: Max run 1 | D32: 8 | H32: esp32_rssi_dbm | I32: robot_wifi_signal_before_dbm | J32: robot_wifi_signal_after_dbm
C33: Max run 2 | D33: 2 | G33: Signal strength 1m | H33: -68 | I33: -67.75 | J33: -68
C34: Max run 3 | D34: 5
C35: Max run 4 | D35: 7
C36: Mean | D36: 5.5

Sheet dist_ble
A1: source_csv | B1: cycle_id | C1: timestamp | D1: distance_m | E1: attempt | F1: command | G1: configured_address | H1: connected_address | I1: device_name | J1: success | K1: scan_before_found | L1: scan_before_ms | M1: rssi_before_last_dbm | N1: rssi_before_mean_dbm | O1: rssi_before_min_dbm | P1: rssi_before_max_dbm | Q1: rssi_before_samples | R1: connect_ms | S1: notify_setup_ms | T1: command_write_ms | U1: time_to_first_notification_ms | V1: command_to_completion_ms | W1: response_wait_ms | X1: disconnect_ms | Y1: total_attempt_ms
A2: distance_check_ble_20260621_211416.csv | B2: 1 | C2: 2026-06-21T21:14:37.423 | D2: 1 | E2: 1 | F2: PRESS | H2: F6:75:48:70:C7:F7 | I2: XIAO-FSR-SERVO | J2: TRUE | K2: TRUE | L2: 3084.72 | M2: -80 | N2: -82 | O2: -84 | P2: -80 | Q2: 2 | R2: 5826.98 | S2: 347.16 | T2: 1.05 | U2: 88.74 | V2: 10529.09 | W2: 11029.89 | X2: 2739.06 | Y2: 25129.89
A3: distance_check_ble_20260621_211416.csv | B3: 1 | C3: 2026-06-21T21:15:29.630 | D3: 2 | E3: 1 | F3: PRESS | J3: FALSE | K3: FALSE | L3: 3020.06 | Q3: 0 | Y3: 3020.24
A4: distance_check_ble_20260621_211726.csv | B4: 2 | C4: 2026-06-21T21:17:28.242 | D4: 1 | E4: 1 | F4: PRESS | H4: F6:75:48:70:C7:F7 | I4: XIAO-FSR-SERVO | J4: TRUE | K4: TRUE | L4: 3116.1 | M4: -80 | N4: -80 | O4: -80 | P4: -80 | Q4: 2 | R4: 5122.1 | S4: 393.73 | T4: 1.43 | U4: 88.58 | V4: 10483.35 | W4: 10984.83 | X4: 2603.74 | Y4: 24353.73
A5: distance_check_ble_20260621_211726.csv | B5: 2 | C5: 2026-06-21T21:18:07.628 | D5: 2 | E5: 1 | F5: PRESS | G5: F6:75:48:70:C7:F7 | H5: F6:75:48:70:C7:F7 | I5: XIAO-FSR-SERVO | J5: TRUE | K5: TRUE | L5: 3019.04 | M5: -91 | N5: -91 | O5: -91 | P5: -91 | Q5: 1 | R5: 2506.93 | S5: 172.58 | T5: 1.2 | U5: 88.72 | V5: 10483.3 | W5: 10984.55 | X5: 2154.27 | Y5: 20941.75
A6: distance_check_ble_20260621_211726.csv | B6: 2 | C6: 2026-06-21T21:18:40.604 | D6: 3 | E6: 1 | F6: PRESS | G6: F6:75:48:70:C7:F7 | H6: F6:75:48:70:C7:F7 | I6: XIAO-FSR-SERVO | J6: FALSE | K6: TRUE | L6: 6080.29 | M6: -88 | N6: -88 | O6: -88 | P6: -88 | Q6: 2 | Y6: 18158.62
A7: distance_check_ble_20260621_211726.csv | B7: 2 | C7: 2026-06-21T21:19:22.047 | D7: 4 | E7: 1 | F7: PRESS | G7: F6:75:48:70:C7:F7 | H7: F6:75:48:70:C7:F7 | I7: XIAO-FSR-SERVO | J7: TRUE | K7: TRUE | L7: 3026.18 | M7: -90 | N7: -90 | O7: -90 | P7: -90 | Q7: 1 | R7: 4580.31 | S7: 172.42 | T7: 0.99 | U7: 88.8 | V7: 10528.86 | W7: 11029.66 | X7: 2604.37 | Y7: 23546.07
A8: distance_check_ble_20260621_211726.csv | B8: 2 | C8: 2026-06-21T21:19:53.560 | D8: 5 | E8: 1 | F8: PRESS | G8: F6:75:48:70:C7:F7 | H8: F6:75:48:70:C7:F7 | I8: XIAO-FSR-SERVO | J8: TRUE | K8: TRUE | L8: 6176.51 | M8: -87 | N8: -87 | O8: -87 | P8: -87 | Q8: 1 | R8: 2270.82 | S8: 173.89 | T8: 0.99 | U8: 88.42 | V8: 10393.53 | W8: 10894.91 | X8: 2423.35 | Y8: 24062.48
A9: distance_check_ble_20260621_211726.csv | B9: 2 | C9: 2026-06-21T21:20:24.975 | D9: 6 | E9: 1 | F9: PRESS | G9: F6:75:48:70:C7:F7 | H9: F6:75:48:70:C7:F7 | I9: XIAO-FSR-SERVO | J9: FALSE | K9: TRUE | L9: 3051.91 | M9: -87 | N9: -87 | O9: -87 | P9: -87 | Q9: 1 | R9: 3546.17 | S9: 218.8 | T9: 1.31 | U9: 88.45 | W9: 15513.44 | Y9: 24350.76
A10: distance_check_ble_20260621_211726.csv | B10: 2 | C10: 2026-06-21T21:21:00.492 | D10: 7 | E10: 1 | F10: PRESS | G10: F6:75:48:70:C7:F7 | H10: F6:75:48:70:C7:F7 | I10: XIAO-FSR-SERVO | J10: FALSE | K10: TRUE | L10: 3061.62 | M10: -87 | N10: -86.25 | O10: -87 | P10: -85 | Q10: 4 | Y10: 15200.46
A11: distance_check_ble_20260621_212139.csv | B11: 3 | C11: 2026-06-21T21:21:41.865 | D11: 1 | E11: 1 | F11: PRESS | H11: F6:75:48:70:C7:F7 | I11: XIAO-FSR-SERVO | J11: FALSE | K11: TRUE | L11: 6111.64 | M11: -82 | N11: -82 | O11: -82 | P11: -82 | Q11: 1 | Y11: 15494.28
A12: distance_check_ble_20260621_212407.csv | B12: 4 | C12: 2026-06-21T21:24:08.390 | D12: 1 | E12: 1 | F12: PRESS | H12: F6:75:48:70:C7:F7 | I12: XIAO-FSR-SERVO | J12: TRUE | K12: TRUE | L12: 3116.88 | M12: -86 | N12: -86 | O12: -86 | P12: -86 | Q12: 1 | R12: 5020.46 | S12: 172.64 | T12: 1.13 | U12: 88.9 | V12: 10528.88 | W12: 11030.29 | X12: 2737.77 | Y12: 24184.32
A13: distance_check_ble_20260621_212407.csv | B13: 4 | C13: 2026-06-21T21:24:42.435 | D13: 2 | E13: 1 | F13: PRESS | G13: F6:75:48:70:C7:F7 | H13: F6:75:48:70:C7:F7 | I13: XIAO-FSR-SERVO | J13: TRUE | K13: TRUE | L13: 3117.42 | M13: -81 | N13: -81 | O13: -81 | P13: -81 | Q13: 3 | R13: 1846.38 | S13: 173.54 | T13: 1.11 | U13: 133.8 | V13: 10483.77 | W13: 10985.07 | X13: 1928.44 | Y13: 20286.11
A14: distance_check_ble_20260621_212407.csv | B14: 4 | C14: 2026-06-21T21:25:12.458 | D14: 3 | E14: 1 | F14: PRESS | G14: F6:75:48:70:C7:F7 | H14: F6:75:48:70:C7:F7 | I14: XIAO-FSR-SERVO | J14: TRUE | K14: TRUE | L14: 6097.15 | M14: -87 | N14: -88 | O14: -89 | P14: -87 | Q14: 2 | R14: 2413.21 | S14: 263.63 | T14: 0.87 | U14: 89 | V14: 10529.4 | W14: 11030.27 | X14: 2558.15 | Y14: 24456.83
A15: distance_check_ble_20260621_212407.csv | B15: 4 | C15: 2026-06-21T21:25:48.452 | D15: 4 | E15: 1 | F15: PRESS | G15: F6:75:48:70:C7:F7 | H15: F6:75:48:70:C7:F7 | I15: XIAO-FSR-SERVO | J15: TRUE | K15: TRUE | L15: 3075.87 | M15: -87 | N15: -88 | O15: -89 | P15: -87 | Q15: 2 | R15: 4990.39 | S15: 172.94 | T15: 0.99 | U15: 89.14 | V15: 10483.91 | W15: 10984.47 | X15: 1793.9 | Y15: 23107.5
A16: distance_check_ble_20260621_212407.csv | B16: 4 | C16: 2026-06-21T21:26:19.334 | D16: 5 | E16: 1 | F16: PRESS | G16: F6:75:48:70:C7:F7 | H16: F6:75:48:70:C7:F7 | I16: XIAO-FSR-SERVO | J16: TRUE | K16: TRUE | L16: 3099.91 | M16: -84 | N16: -84 | O16: -84 | P16: -84 | Q16: 1 | R16: 3425.11 | S16: 173.25 | T16: 1.29 | U16: 88.27 | V16: 10573.67 | W16: 11074.92 | X16: 2378.19 | Y16: 22233.91
A17: distance_check_ble_20260621_212407.csv | B17: 4 | C17: 2026-06-21T21:26:48.621 | D17: 6 | E17: 1 | F17: PRESS | G17: F6:75:48:70:C7:F7 | H17: F6:75:48:70:C7:F7 | I17: XIAO-FSR-SERVO | J17: TRUE | K17: TRUE | L17: 3021.91 | M17: -81 | N17: -84.25 | O17: -87 | P17: -81 | Q17: 4 | R17: 4274.59 | S17: 218.9 | T17: 1.21 | U17: 179.53 | V17: 10843.94 | W17: 11344.9 | X17: 1973.55 | Y17: 22950.29
A18: distance_check_ble_20260621_212407.csv | B18: 4 | C18: 2026-06-21T21:27:19.581 | D18: 7 | E18: 1 | F18: PRESS | G18: F6:75:48:70:C7:F7 | H18: F6:75:48:70:C7:F7 | I18: XIAO-FSR-SERVO | J18: FALSE | K18: FALSE | L18: 9143.67 | Q18: 0 | Y18: 29303.76
H21: rssi_before_last_dbm | I21: rssi_before_mean_dbm | J21: rssi_before_min_dbm | K21: rssi_before_max_dbm
C22: max run 1 | D22: 1 | G22: Signal strength 1m | H22: -82 | I22: -82.5 | J22: -83 | K22: -82
C23: max run 2 | D23: 5
C24: max run 3 | D24: 0
C25: max run 4 | D25: 6
D26: 3

Sheet idle_test
A1: Idle Test
A2: Stage | B2: Time/Condition | C2: Button pressed once | D2: Voltage
A4: BLE | B4: 0.43611111 | C4: success | D4: 3.96
A5: BLE | B5: after 1h | C5: success | D5: 3.96
A8: Wi-Fi | B8: 0.49097222 | C8: success | D8: 3.95
A9: Wi-Fi | B9: after 1h | C9: success | D9: 3.92

Sheet operation_notes
C1: wifi | D1: ble
C2: 3.96V | D2: 3.97V
C3: 0.79236111 | D3: 0.91180556
A4: Test Nr | B4: Button | C4: success (y/n) | D4: success (y/n) | G4: Wifi | I4: BLE
F5: Test Nr | G5: Button pressed | H5: threshhold reached | I5: Button pressed | J5: threshhold reached
A6: 1 | B6: 2 | C6: y | D6: y | F6: 1 | G6: y | H6: yes | I6: y | J6: yes
A7: 2 | B7: 2 | C7: y | D7: y | F7: 2 | G7: y | H7: yes | I7: y | J7: yes
A8: 3 | B8: 2 | C8: y | D8: y | F8: 3 | G8: y | H8: yes | I8: y | J8: yes
A9: 4 | B9: 2 | C9: y | D9: y | F9: 4 | G9: y | H9: yes | I9: y | J9: yes
A10: 5 | B10: 2 | C10: y | D10: y | F10: 5 | G10: y | H10: yes | I10: y | J10: yes
A11: 6 | B11: 2 | C11: y | D11: y | F11: 6 | G11: y | H11: yes | I11: y | J11: yes
A12: 7 | B12: 2 | C12: y | D12: y | F12: 7 | G12: y | H12: yes | I12: y | J12: yes
A13: 8 | B13: 2 | C13: y | D13: y | F13: 8 | G13: y | H13: yes | I13: y | J13: yes
A14: 9 | B14: 2 | C14: y | D14: y | F14: 9 | G14: y | H14: yes | I14: y | J14: yes
A15: 10 | B15: 2 | C15: y | D15: y | F15: 10 | G15: y | H15: yes | I15: y | J15: yes
A16: 11 | B16: 2 | C16: y | D16: y | F16: 11 | G16: y | H16: yes | I16: y | J16: yes
A17: 12 | B17: 2 | C17: y | D17: y | F17: 12 | G17: y | H17: yes | I17: y | J17: yes
... A35: 30 | B35: 3 | C35: y | D35: y | F35: 30 | G35: y | H35: yes | I35: y | J35: yes
A36: 31 | B36: out 1 | C36: y | D36: y | F36: 31 | G36: y | H36: yes | I36: y | J36: yes
A37: 32 | B37: out 1 | C37: y | D37: y | F37: 32 | G37: y | H37: yes | I37: y | J37: yes
A38: 33 | B38: out 1 | C38: y | D38: y | F38: 33 | G38: y | H38: no | I38: y | J38: yes
A39: 34 | B39: out 1 | C39: y | D39: y | F39: 34 | G39: y | H39: yes | I39: y | J39: yes
A40: 35 | B40: out 1 | C40: y | D40: y | F40: 35 | G40: y | H40: yes | I40: y | J40: no
A41: 36 | B41: out 1 | C41: y | D41: y | F41: 36 | G41: y | H41: yes | I41: y | J41: yes
A42: 37 | B42: out 1 | C42: y | D42: y | F42: 37 | G42: y | H42: yes | I42: y | J42: yes
A43: 38 | B43: out 1 | C43: y | D43: y | F43: 38 | G43: y | H43: yes | I43: y | J43: yes
A44: 39 | B44: out 1 | C44: y | D44: y | F44: 39 | G44: y | H44: yes | I44: y | J44: yes
A45: 40 | B45: out 1 | C45: y | D45: n | F45: 40 | G45: y | H45: yes | I45: n | J45: yes
A46: 41 | B46: out 1 | C46: y | D46: y | F46: 41 | G46: y | H46: yes | I46: y | J46: yes
A47: 42 | B47: out 1 | C47: y | D47: y | F47: 42 | G47: y | H47: yes | I47: y | J47: yes
... A59: 54 | B59: out 1 | C59: y | D59: y | F59: 54 | G59: y | H59: yes | I59: y | J59: yes
A60: 55 | B60: out 1 | C60: y | D60: y | F60: 55 | G60: y | H60: no
A61: amount correct | C61: 55 | D61: 54
A62: final test done | G62: Successrate | H62: Successrate | I62: Successrate | J62: Successrate
A63: 0.81666667 | B63: 3.91 V | C63: 0.92708333 | D63: 3.97V | G63: 0.96491228 | H63: 0.92857143 | I63: 0.94642857 | J63: 0.96363636
A66: Voltage in V | B66: Wifi | C66: BLE
A67: Start | B67: 3.96 | C67: 3.97
A68: End | B68: 3.91 | C68: 3.97
A69: Time start | B69: 0.79236111 | C69: 0.91180556
A70: Time end | B70: 0.81666667 | C70: 0.92708333
...

Sheet recalibration_points
A1: sheet_name | B1: row_in_sheet | C1: run_start_datetime_raw | D1: estimated_datetime | E1: time_min | F1: calibrated_floor | G1: estimated_floor | H1: actual_floor | I1: pressure_hPa | J1: relative_height_m | K1: temperature_C
A2: floor0_recal | B2: 86 | C2: 20.06.26 20:37 | D2: 46193.86 | E2: 1.3985833 | F2: 0 | G2: 0 | I2: 1012.39 | J2: 0.01 | K2: 27.97
A3: floor0_recali | B3: 37 | C3: 20.06.26 20:46:20 | D3: 46193.866 | E3: 0.60316667 | F3: 0 | G3: 0 | I3: 1012.46 | J3: 0 | K3: 28.3
A4: floor0_recalibrated | B4: 29 | C4: 20.02.26 20:22:34 | D4: 46193.849 | E4: 0.46821667 | F4: 0 | G4: 0 | I4: 1012.16 | J4: 0.02 | K4: 27.45
A5: floor1_recal | B5: 22 | C5: 22.06.36 13:08:49 | D5: 46195.548 | E5: 0.3515 | F5: 1 | G5: 1 | I5: 1022.28 | J5: 2.37 | K5: 25.13

Sheet manual_test_points
A1: sheet_name | B1: row_in_sheet | C1: run_start_datetime_raw | D1: estimated_datetime | E1: time_ms_start_of_recording | F1: time_ms | G1: time_min | H1: calibration_phase | I1: actual_floor | J1: estimated_floor | K1: floor_error | L1: abs_floor_error | M1: correct_eval | N1: calibrated_floor | O1: pressure_hPa | P1: relative_height_m | Q1: offset_from_estimated_floor_m
A2: floor0_recal | B2: 41 | C2: 46193.859 | D2: =C2+((F2-E2)/86400000) -> 46193.859 | E2: 3067186 | F2: 3106153 | G2: =(F2-E2)/60000 -> 0.64945 | H2: before_calibration | I2: 4 | J2: 4 | K2: 0 | L2: 0 | M2: TRUE | O2: 1010.62 | P2: 77 | Q2: 63.61
A3: floor0_recal | B3: 69 | C3: 46193.859 | D3: =C3+((F3-E3)/86400000) -> 46193.86 | E3: 3067186 | F3: 3133559 | G3: =(F3-E3)/60000 -> 1.1062167 | H3: before_calibration | I3: 0 | J3: 4 | K3: 4 | L3: 4 | M3: FALSE | O3: 1012.38 | P3: 62.36 | Q3: 48.97
A4: floor0_recal | B4: 90 | C4: 46193.859 | D4: =C4+((F4-E4)/86400000) -> 46193.86 | E4: 3067186 | F4: 3154734 | G4: =(F4-E4)/60000 -> 1.4591333 | H4: after_calibration | I4: 0 | J4: 0 | K4: 0 | L4: 0 | M4: TRUE | O4: 1012.38 | P4: 0.1 | Q4: 0.1
A5: floor0_recal | B5: 100 | C5: 46193.859 | D5: =C5+((F5-E5)/86400000) -> 46193.86 | E5: 3067186 | F5: 3163965 | G5: =(F5-E5)/60000 -> 1.6129833 | H5: after_calibration | I5: 0 | J5: 0 | K5: 0 | L5: 0 | M5: TRUE | O5: 1012.37 | P5: 0.17 | Q5: 0.17
A6: floor0_recal | B6: 224 | C6: 46193.859 | D6: =C6+((F6-E6)/86400000) -> 46193.862 | E6: 3067186 | F6: 3288449 | G6: =(F6-E6)/60000 -> 3.6877167 | H6: after_calibration | I6: 0 | J6: 0 | K6: 0 | L6: 0 | M6: TRUE | O6: 1012.42
A7: floor0_recal | B7: 344 | C7: 46193.859 | D7: =C7+((F7-E7)/86400000) -> 46193.863 | E7: 3067186 | F7: 3408662 | G7: =(F7-E7)/60000 -> 5.6912667 | H7: after_calibration | I7: 0 | J7: 0 | K7: 0 | L7: 0 | M7: TRUE | O7: 1012.45
A8: floor0_recali | B8: 70 | C8: 46193.866 | D8: =C8+((F8-E8)/86400000) -> 46193.866 | E8: 3752348 | F8: 3821589 | G8: =(F8-E8)/60000 -> 1.1540167 | H8: after_calibration | I8: 0 | J8: 0 | K8: 0 | L8: 0 | M8: TRUE | O8: 1012.48
A9: floor0_recali | B9: 81 | C9: 46193.866 | D9: =C9+((F9-E9)/86400000) -> 46193.866 | E9: 3752348 | F9: 3831932 | G9: =(F9-E9)/60000 -> 1.3264 | H9: after_calibration | I9: 0 | J9: 0 | K9: 0 | L9: 0 | M9: TRUE | O9: 1012.47
A10: floor0_recali | B10: 112 | C10: 46193.866 | D10: =C10+((F10-E10)/86400000) -> 46193.867 | E10: 3752348 | F10: 3863180 | G10: =(F10-E10)/60000 -> 1.8472 | H10: after_calibration | I10: 1 | J10: 1 | K10: 0 | L10: 0 | M10: TRUE | O10: 1012.09 | P10: 3.24 | Q10: 0.84
A11: floor0_recali | B11: 125 | C11: 46193.866 | D11: =C11+((F11-E11)/86400000) -> 46193.867 | E11: 3752348 | F11: 3875468 | G11: =(F11-E11)/60000 -> 2.052 | H11: after_calibration | I11: 1 | J11: 1 | K11: 0 | L11: 0 | M11: TRUE | O11: 1012.1 | P11: 3.12 | Q11: 0.72
A12: floor0_recali | B12: 143 | C12: 46193.866 | D12: =C12+((F12-E12)/86400000) -> 46193.867 | E12: 3752348 | F12: 3893209 | G12: =(F12-E12)/60000 -> 2.3476833 | H12: after_calibration | I12: 2 | J12: 2 | K12: 0 | L12: 0 | M12: TRUE | O12: 1011.66 | P12: 6.83 | Q12: 0.97
A13: floor0_recali | B13: 146 | C13: 46193.866 | D13: =C13+((F13-E13)/86400000) -> 46193.867 | E13: 3752348 | F13: 3895630 | G13: =(F13-E13)/60000 -> 2.3880333 | H13: after_calibration | I13: 2 | J13: 2 | K13: 0 | L13: 0 | M13: TRUE | O13: 1011.65 | P13: 6.88 | Q13: 1.02
A14: floor0_recali | B14: 160 | C14: 46193.866 | D14: =C14+((F14-E14)/86400000) -> 46193.867 | E14: 3752348 | F14: 3908919 | G14: =(F14-E14)/60000 -> 2.6095167 | H14: after_calibration | I14: 2 | J14: 2 | K14: 0 | L14: 0 | M14: TRUE | O14: 1011.65 | P14: 6.93 | Q14: 1.07
A15: floor0_recali | B15: 181 | C15: 46193.866 | D15: =C15+((F15-E15)/86400000) -> 46193.868 | E15: 3752348 | F15: 3929560 | G15: =(F15-E15)/60000 -> 2.9535333 | H15: after_calibration | I15: 3 | J15: 3 | K15: 0 | L15: 0 | M15: TRUE | O15: 1011.21 | P15: 10.57 | Q15: 0.86
A16: floor0_recali | B16: 206 | C16: 46193.866 | D16: =C16+((F16-E16)/86400000) -> 46193.868 | E16: 3752348 | F16: 3954274 | G16: =(F16-E16)/60000 -> 3.3654333 | H16: after_calibration | I16: 4 | J16: 4 | K16: 0 | L16: 0 | M16: TRUE | O16: 1010.76 | P16: 14.3 | Q16: 0.81
A17: floor0_recalibrated | B17: 53 | C17: 46193.849 | D17: =C17+((F17-E17)/86400000) -> 46193.85 | E17: 2283808 | F17: 2335809 | G17: =(F17-E17)/60000 -> 0.86668333 | H17: after_calibration | I17: 0 | J17: 0 | K17: 0 | L17: 0 | M17: TRUE | O17: 1012.15 | P17: 0.05 | Q17: 0.05
A18: floor0_recalibrated | B18: 82 | C18: 46193.849 | D18: =C18+((F18-E18)/86400000) -> 46193.85 | E18: 2283808 | F18: 2364633 | G18: =(F18-E18)/60000 -> 1.3470833 | H18: after_calibration | I18: 4 | J18: 4 | K18: 0 | L18: 0 | M18: TRUE | O18: 1010.44 | P18: 14.38 | Q18: 0.89
A19: floor0_recalibrated | B19: 88 | C19: 46193.849 | D19: =C19+((F19-E19)/86400000) -> 46193.85 | E19: 2283808 | F19: 2370206 | G19: =(F19-E19)/60000 -> 1.4399667 | H19: after_calibration | I19: 4 | J19: 4 | K19: 0 | L19: 0 | M19: TRUE | O19: 1010.43 | P19: 14.41 | Q19: 0.92
A20: floor0_recalibrated | B20: 92 | C20: 46193.849 | D20: =C20+((F20-E20)/86400000) -> 46193.85 | E20: 2283808 | F20: 2373416 | G20: =(F20-E20)/60000 -> 1.4934667 | H20: after_calibration | I20: 4 | J20: 4 | K20: 0 | L20: 0 | M20: TRUE | O20: 1010.42 | P20: 14.52 | Q20: 1.02
A21: floor0_recalibrated | B21: 115 | C21: 46193.849 | D21: =C21+((F21-E21)/86400000) -> 46193.85 | E21: 2283808 | F21: 2395809 | G21: =(F21-E21)/60000 -> 1.8666833 | H21: after_calibration | I21: 3 | J21: 3 | K21: 0 | L21: 0 | M21: TRUE | O21: 1010.87 | P21: 10.78 | Q21: 1.07
... A28: floor0_recalibrated | B28: 194 | C28: 46193.849 | D28: =C28+((F28-E28)/86400000) -> 46193.851 | E28: 2283808 | F28: 2469923 | G28: =(F28-E28)/60000 -> 3.1019167 | H28: after_calibration | I28: 1 | J28: 1 | K28: 0 | L28: 0 | M28: TRUE | O28: 1011.8 | P28: 3.01 | Q28: 0.61
A29: floor0_recalibrated | B29: 209 | C29: 46193.849 | D29: =C29+((F29-E29)/86400000) -> 46193.851 | E29: 2283808 | F29: 2484243 | G29: =(F29-E29)/60000 -> 3.3405833 | H29: after_calibration | I29: 0 | J29: 0 | K29: 0 | L29: 0 | M29: TRUE | O29: 1012.18
A30: floor0_recalibrated | B30: 212 | C30: 46193.849 | D30: =C30+((F30-E30)/86400000) -> 46193.851 | E30: 2283808 | F30: 2486606 | G30: =(F30-E30)/60000 -> 3.3799667 | H30: after_calibration | I30: 0 | J30: 0 | K30: 0 | L30: 0 | M30: TRUE | O30: 1012.19
A31: floor0_recalibrated | B31: 225 | C31: 46193.849 | D31: =C31+((F31-E31)/86400000) -> 46193.851 | E31: 2283808 | F31: 2498880 | G31: =(F31-E31)/60000 -> 3.5845333 | H31: after_calibration | I31: 0 | J31: 0 | K31: 0 | L31: 0 | M31: TRUE | O31: 1012.18
A32: floor1_recal | B32: 75 | C32: 49848.548 | D32: =C32+((F32-E32)/86400000) -> 49848.548 | E32: 6276712 | F32: 6276712 | G32: =(F32-E32)/60000 -> 0 | H32: after_calibration | I32: 1 | J32: 1 | K32: 0 | L32: 0 | M32: TRUE | O32: 1022.29 | P32: 2.27
A33: floor1_recal | B33: 93 | C33: 49848.548 | D33: =C33+((F33-E33)/86400000) -> 49848.548 | E33: 6276712 | F33: 6294009 | G33: =(F33-E33)/60000 -> 0.28828333 | H33: after_calibration | I33: 0 | J33: 0 | K33: 0 | L33: 0 | M33: TRUE | O33: 1022.66
A34: floor1_recal | B34: 126 | C34: 49848.548 | D34: =C34+((F34-E34)/86400000) -> 49848.548 | E34: 6276712 | F34: 6326536 | G34: =(F34-E34)/60000 -> 0.8304 | H34: after_calibration | I34: 4 | J34: 4 | K34: 0 | L34: 0 | M34: TRUE | O34: 1020.9 | P34: 13.77 | Q34: 0.42
A35: floor1_recal | B35: 130 | C35: 49848.548 | D35: =C35+((F35-E35)/86400000) -> 49848.548 | E35: 6276712 | F35: 6329822 | G35: =(F35-E35)/60000 -> 0.88516667 | H35: after_calibration | I35: 4 | J35: 4 | K35: 0 | L35: 0 | M35: TRUE | O35: 1020.9 | P35: 13.75 | Q35: 0.39
A36: floor1_recal | B36: 142 | C36: 49848.548 | D36: =C36+((F36-E36)/86400000) -> 49848.549 | E36: 6276712 | F36: 6341108 | G36: =(F36-E36)/60000 -> 1.0732667 | H36: after_calibration | I36: 4 | J36: 4 | K36: 0 | L36: 0 | M36: TRUE | O36: 1020.88 | P36: 13.9 | Q36: 0.54
A37: floor1_recal | B37: 148 | C37: 49848.548 | D37: =C37+((F37-E37)/86400000) -> 49848.549 | E37: 6276712 | F37: 6346331 | G37: =(F37-E37)/60000 -> 1.1603167 | H37: after_calibration | I37: 4 | J37: 4 | K37: 0 | L37: 0 | M37: TRUE | O37: 1020.89 | P37: 13.88 | Q37: 0.53
A38: floor1_recal | B38: 183 | C38: 49848.548 | D38: =C38+((F38-E38)/86400000) -> 49848.549 | E38: 6276712 | F38: 6380904 | G38: =(F38-E38)/60000 -> 1.7365333 | H38: after_calibration | I38: 3 | J38: 3 | K38: 0 | L38: 0 | M38: TRUE | O38: 1021.37 | P38: 9.89 | Q38: 0.28
A39: floor1_recal | B39: 187 | C39: 49848.548 | D39: =C39+((F39-E39)/86400000) -> 49848.549 | E39: 6276712 | F39: 6384098 | G39: =(F39-E39)/60000 -> 1.7897667 | H39: after_calibration | I39: 3 | J39: 3 | K39: 0 | L39: 0 | M39: TRUE | O39: 1021.36 | P39: 9.99 | Q39: 0.37
A40: floor1_recal | B40: 198 | C40: 49848.548 | D40: =C40+((F40-E40)/86400000) -> 49848.549 | E40: 6276712 | F40: 6394412 | G40: =(F40-E40)/60000 -> 1.9616667 | H40: after_calibration | I40: 3 | J40: 3 | K40: 0 | L40: 0 | M40: TRUE | O40: 1021.36 | P40: 10.01 | Q40: 0.39
A41: floor1_recal | B41: 212 | C41: 49848.548 | D41: =C41+((F41-E41)/86400000) -> 49848.549 | E41: 6276712 | F41: 6407881 | G41: =(F41-E41)/60000 -> 2.18615 | H41: after_calibration | I41: 2 | J41: 2 | K41: 0 | L41: 0 | M41: TRUE | O41: 1021.83 | P41: 6.13 | Q41: 0.33
A42: floor1_recal | B42: 215 | C42: 49848.548 | D42: =C42+((F42-E42)/86400000) -> 49848.549 | E42: 6276712 | F42: 6410152 | G42: =(F42-E42)/60000 -> 2.224 | H42: after_calibration | I42: 2 | J42: 2 | K42: 0 | L42: 0 | M42: TRUE | O42: 1021.82 | P42: 6.17 | Q42: 0.37
A43: floor1_recal | B43: 228 | C43: 49848.548 | D43: =C43+((F43-E43)/86400000) -> 49848.549 | E43: 6276712 | F43: 6422418 | G43: =(F43-E43)/60000 -> 2.4284333 | H43: after_calibration | I43: 2 | J43: 2 | K43: 0 | L43: 0 | M43: TRUE | O43: 1021.81 | P43: 6.22 | Q43: 0.42
A44: floor1_recal | B44: 237 | C44: 49848.548 | D44: =C44+((F44-E44)/86400000) -> 49848.55 | E44: 6276712 | F44: 6430874 | G44: =(F44-E44)/60000 -> 2.5693667 | H44: after_calibration | I44: 2 | J44: 2 | K44: 0 | L44: 0 | M44: TRUE | O44: 1021.83 | P44: 6.07 | Q44: 0.27
A45: floor1_recal | B45: 262 | C45: 49848.548 | D45: =C45+((F45-E45)/86400000) -> 49848.55 | E45: 6276712 | F45: 6455260 | G45: =(F45-E45)/60000 -> 2.9758 | H45: after_calibration | I45: 2 | J45: 2 | K45: 0 | L45: 0 | M45: TRUE | O45: 1021.82 | P45: 6.19 | Q45: 0.39
A46: floor1_recal | B46: 323 | C46: 49848.548 | D46: =C46+((F46-E46)/86400000) -> 49848.551 | E46: 6276712 | F46: 6516242 | G46: =(F46-E46)/60000 -> 3.9921667 | H46: after_calibration | I46: 0 | J46: 0 | K46: 0 | L46: 0 | M46: TRUE | O46: 1022.69
...

Sheet desk_drift
A1: type | B1: time_ms | C1: temperature_C | D1: pressure_Pa | E1: pressure_hPa | F1: relative_height_m | G1: estimated_floor | H1: offset_from_estimated_floor_m | I1: actual_floor | J1: correct | K1: calibrated_floor
A2: calibration | B2: 43053 | C2: 23.81 | D2: 101392.03 | E2: 1013.92 | F2: 0 | K2: 0
A3: calibration | B3: 1057142 | C3: 24 | D3: 101394.27 | E3: 1013.94 | F3: 0 | K3: 0
A4: read | B4: 1085782 | C4: 24.05 | D4: 101901.79 | E4: 1019.02 | F4: -42.14 | G4: 0 | H4: -42.14
A5: read | B5: 1086787 | C5: 24.03 | D5: 101903.48 | E5: 1019.03 | F5: -42.28 | G5: 0 | H5: -42.28
A6: read | B6: 1087796 | C6: 24.03 | D6: 101903.98 | E6: 1019.04 | F6: -42.32 | G6: 0 | H6: -42.32
A7: read | B7: 1088798 | C7: 24.04 | D7: 101904.05 | E7: 1019.04 | F7: -42.33 | G7: 0 | H7: -42.33
A8: read | B8: 1089801 | C8: 24.04 | D8: 101903.88 | E8: 1019.04 | F8: -42.31 | G8: 0 | H8: -42.31
A9: read | B9: 1090808 | C9: 24.05 | D9: 101903.35 | E9: 1019.03 | F9: -42.27 | G9: 0 | H9: -42.27
A10: read | B10: 1091815 | C10: 24.05 | D10: 101903.3 | E10: 1019.03 | F10: -42.26 | G10: 0 | H10: -42.26
A11: read | B11: 1092823 | C11: 24.06 | D11: 101903.51 | E11: 1019.04 | F11: -42.28 | G11: 0 | H11: -42.28
A12: read | B12: 1093833 | C12: 24.06 | D12: 101903.33 | E12: 1019.03 | F12: -42.27 | G12: 0 | H12: -42.27
A13: read | B13: 1094844 | C13: 24.06 | D13: 101902.73 | E13: 1019.03 | F13: -42.22 | G13: 0 | H13: -42.22
A14: read | B14: 1095856 | C14: 24.07 | D14: 101902.92 | E14: 1019.03 | F14: -42.23 | G14: 0 | H14: -42.23
A15: read | B15: 1096924 | C15: 24.07 | D15: 101903.33 | E15: 1019.03 | F15: -42.27 | G15: 0 | H15: -42.27
... A78: read | B78: 1209578 | C78: 24.05 | D78: 101900.61 | E78: 1019.01 | F78: -42.04 | G78: 0 | H78: -42.04

Sheet floor_confusion
A1: actual_floor | B1: 0 | C1: 1 | D1: 2 | E1: 3 | F1: 4
A2: 0 | B2: 18 | C2: 0 | D2: 0 | E2: 0 | F2: 0
A3: 1 | B3: 0 | C3: 15 | D3: 0 | E3: 0 | F3: 0
A4: 2 | B4: 0 | C4: 0 | D4: 18 | E4: 0 | F4: 0
A5: 3 | B5: 0 | C5: 0 | D5: 0 | E5: 11 | F5: 0
A6: 4 | B6: 0 | C6: 0 | D6: 0 | E6: 0 | F6: 13

Sheet Elevator Summary
A1: Section | B1: Metric | C1: Formula value | D1: Unit/notes | F1: Comparison metric | G1: WiFi | H1: BLE | I1: Note
A2: WiFi normal | B2: Total commands | C2: =COUNTA(elevator_wifi!A2:A63) -> 55 | D2: runs | F2: Normal success rate | G2: =C4 -> 1 | H2: =C19 -> 0.96296296 | I2: same normal operation test
A3: WiFi normal | B3: Successful commands | C3: =COUNTIF(elevator_wifi!D:D,"True") -> 55 | D3: runs | F3: Average normal command time | G3: =C7 -> 6820.9475 | H3: =C22 -> 19265.203 | I3: ms
A4: WiFi normal | B4: Success rate | C4: =C3/C2 -> 1 | D4: success / total | F4: Average normal RSSI | G4: =C8 -> -46.618182 | H4: =C23 -> -60.99537 | I4: dBm
A5: WiFi normal | B5: Threshold reached | C5: =COUNTIF(elevator_wifi!K2:K49,"yes") -> 46 | D5: runs | F5: Distance success rate | G5: =C34 -> 0.81481481 | H5: =C42 -> 0.64705882 | I5: distance test
A6: WiFi normal | B6: Threshold reached rate | C6: =C5/C2 -> 0.83636364 | D6: threshold yes / total | F6: Maximum successful distance | G6: =C35 -> 8 | H6: =C43 -> 6 | I6: m
A7: WiFi normal | B7: Average response time | C7: =AVERAGEIF(elevator_wifi!D:D,"True",elevator_wifi!F:F) -> 6820.9475 | D7: ms, successful only | F7: Average distance command time | G7: =C36 -> 8644.2877 | H7: =C44 -> 23204.807 | I7: ms
A8: WiFi normal | B8: Average ESP32 RSSI | C8: =AVERAGE(elevator_wifi!Z:Z) -> -46.618182 | D8: dBm
A9: WiFi normal | B9: Minimum ESP32 RSSI | C9: =MIN(elevator_wifi!Z2:Z49) -> -58 | D9: dBm
A10: WiFi normal | B10: Maximum ESP32 RSSI | C10: =MAX(elevator_wifi!Z2:Z49) -> -34 | D10: dBm
A11: WiFi normal | B11: Start Voltage | C11: =operation_notes!B67 -> 3.96 | D11: V
A12: WiFi normal | B12: End Voltage | C12: =operation_notes!B68 -> 3.91 | D12: V
A13: WiFi normal | B13: Time start | C13: =operation_notes!B69 -> 0.79236111 | D13: time
A14: WiFi normal | B14: Time end | C14: =operation_notes!B70 -> 0.81666667 | D14: time
A15: WiFi normal | B15: Duration | C15: =operation_notes!B71 -> 0.024305556 | D15: time
A17: BLE normal | B17: Total commands | C17: =COUNTA(elevator_ble!A2:A55) -> 54 | D17: runs
A18: BLE normal | B18: Successful commands | C18: =SUMPRODUCT(--(elevator_ble!E2:E55=TRUE))+COUNTIF(elevator_ble!E2:E55,"TRUE") -> 52 | D18: runs
A19: BLE normal | B19: Success rate | C19: =C18/C17 -> 0.96296296 | D19: success / total
A20: BLE normal | B20: Threshold reached | C20: =COUNTIF(elevator_ble!W2:W55,"yes") -> 53 | D20: runs
A21: BLE normal | B21: Threshold reached rate | C21: =C20/C17 -> 0.98148148 | D21: threshold yes / total
A22: BLE normal | B22: Average total time | C22: 19265.203 | D22: ms, successful only
A23: BLE normal | B23: Average RSSI mean | C23: =AVERAGE(elevator_ble!H2:H55) -> -60.99537 | D23: dBm
A24: BLE normal | B24: Minimum RSSI last | C24: =MIN(elevator_ble!G2:G55) -> -85 | D24: dBm
A25: BLE normal | B25: Maximum RSSI last | C25: =MAX(elevator_ble!G2:G55) -> -43 | D25: dBm
A26: BLE normal | B26: Start Voltage | C26: =operation_notes!C67 -> 3.97 | D26: V
A27: BLE normal | B27: End Voltage | C27: =operation_notes!C68 -> 3.97 | D27: V
A28: BLE normal | B28: Time start | C28: =operation_notes!C69 -> 0.91180556 | D28: time
A29: BLE normal | B29: Time end | C29: =operation_notes!C70 -> 0.92708333 | D29: time
A30: BLE normal | B30: Duration | C30: =operation_notes!C71 -> 0.015277778 | D30: time
A32: WiFi distance | B32: Total distance attempts | C32: =COUNTA(dist_wifi!A2:A36) -> 27 | D32: attempts
A33: WiFi distance | B33: Successful distance attempts | C33: =SUMPRODUCT(--(dist_wifi!G2:G36=TRUE))+COUNTIF(dist_wifi!G2:G36,"TRUE") -> 22 | D33: attempts
A34: WiFi distance | B34: Distance success rate | C34: =C33/C32 -> 0.81481481 | D34: success / total
A35: WiFi distance | B35: Maximum successful distance | C35: 8 | D35: m
A36: WiFi distance | B36: Average attempt total time | C36: 8644.2877 | D36: ms, successful only
A37: WiFi distance | B37: Average HTTP total time | C37: 8482.0527 | D37: ms, successful only
A38: WiFi distance | B38: Average ESP32 RSSI | C38: =AVERAGE(dist_wifi!AC2:AC36) -> -72.590909 | D38: dBm
A40: BLE distance | B40: Total distance attempts | C40: =COUNTA(dist_ble!A2:A26) -> 17 | D40: attempts
A41: BLE distance | B41: Successful distance attempts | C41: =SUMPRODUCT(--(dist_ble!J2:J26=TRUE))+COUNTIF(dist_ble!J2:J26,"TRUE") -> 11 | D41: attempts
A42: BLE distance | B42: Distance success rate | C42: =C41/C40 -> 0.64705882 | D42: success / total
A43: BLE distance | B43: Maximum successful distance | C43: 6 | D43: m
...

Sheet Barometer Summary
A1: Section | B1: Metric | C1: Formula value | D1: Unit/notes | F1: Actual floor | G1: Correct points | H1: Total points | I1: Accuracy
A2: Manual floor test | B2: Total test points | C2: =COUNTA(manual_test_points!A2:A83) -> 82 | D2: points | F2: 0 | G2: =SUMIFS(floor_confusion!B2:F2,floor_confusion!B1:F1,0) -> 18 | H2: =SUM(floor_confusion!B2:F2) -> 18 | I2: =G2/H2 -> 1
A3: Manual floor test | B3: Correct test points | C3: =SUMPRODUCT(--(manual_test_points!M2:M83=TRUE))+COUNTIF(manual_test_points!M2:M83,"TRUE") -> 77 | D3: points | F3: 1 | G3: =SUMIFS(floor_confusion!B3:F3,floor_confusion!B1:F1,1) -> 15 | H3: =SUM(floor_confusion!B3:F3) -> 15 | I3: =G3/H3 -> 1
A4: Manual floor test | B4: Overall accuracy | C4: =C3/C2 -> 0.93902439 | D4: correct / total | F4: 2 | G4: =SUMIFS(floor_confusion!B4:F4,floor_confusion!B1:F1,2) -> 18 | H4: =SUM(floor_confusion!B4:F4) -> 18 | I4: =G4/H4 -> 1
A5: Manual floor test | B5: Mean floor error | C5: =AVERAGE(manual_test_points!K2:K83) -> 0.17073171 | D5: floors | F5: 3 | G5: =SUMIFS(floor_confusion!B5:F5,floor_confusion!B1:F1,3) -> 11 | H5: =SUM(floor_confusion!B5:F5) -> 11 | I5: =G5/H5 -> 1
A6: Manual floor test | B6: Mean absolute floor error | C6: =AVERAGE(manual_test_points!L2:L83) -> 0.17073171 | D6: floors | F6: 4 | G6: =SUMIFS(floor_confusion!B6:F6,floor_confusion!B1:F1,4) -> 13 | H6: =SUM(floor_confusion!B6:F6) -> 13 | I6: =G6/H6 -> 1
A7: Manual floor test | B7: Maximum absolute floor error | C7: =MAX(manual_test_points!L2:L83) -> 4 | D7: floors
A9: After calibration | B9: Test points | C9: =COUNTIF(manual_test_points!H2:H83,"after_calibration") -> 75 | D9: points
A10: After calibration | B10: Correct points | C10: =SUMPRODUCT(--(manual_test_points!H2:H83="after_calibration"),--(manual_test_points!M2:M83=TRUE))+COUNTIFS(manual_test_points!H2:H83,"after_calibration",manual_test_points!M2:M83,"TRUE") -> 75 | D10: points
A11: After calibration | B11: Accuracy | C11: =C10/C9 -> 1 | D11: correct / total
A12: After calibration | B12: Mean absolute floor error | C12: =AVERAGEIF(manual_test_points!H2:H83,"after_calibration",manual_test_points!Q2:Q83) -> 0.60508772 | D12: m
A13: After calibration | B13: Maximum absolute floor error | C13: =_xlfn.MAXIFS(manual_test_points!Q2:Q83,manual_test_points!H2:H83,"after_calibration") -> 1.1 | D13: m
A15: Before calibration | B15: Test points | C15: =COUNTIF(manual_test_points!H2:H83,"before_calibration") -> 2 | D15: points
A16: Before calibration | B16: Correct points | C16: =SUMPRODUCT(--(manual_test_points!H2:H83="before_calibration"),--(manual_test_points!M2:M83=TRUE))+COUNTIFS(manual_test_points!H2:H83,"before_calibration",manual_test_points!M2:M83,"TRUE") -> 1 | D16: points
A17: Before calibration | B17: Accuracy | C17: =C16/C15 -> 0.5 | D17: correct / total
A18: Before calibration | B18: Mean absolute floor error | C18: =AVERAGEIF(manual_test_points!H2:H83,"before_calibration",manual_test_points!Q2:Q83) -> 56.29 | D18: m
A19: Before calibration | B19: Maximum absolute floor error | C19: =_xlfn.MAXIFS(manual_test_points!Q2:Q83,manual_test_points!H2:H83,"before_calibration") -> 63.61 | D19: m
A21: No calibration in run | B21: Test points | C21: =COUNTIF(manual_test_points!H2:H83,"no_calibration_in_run") -> 5 | D21: points
A22: No calibration in run | B22: Correct points | C22: =SUMPRODUCT(--(manual_test_points!H2:H83="no_calibration_in_run"),--(manual_test_points!M2:M83=TRUE))+COUNTIFS(manual_test_points!H2:H83,"no_calibration_in_run",manual_test_points!M2:M83,"TRUE") -> 1 | D22: points
A23: No calibration in run | B23: Accuracy | C23: =C22/C21 -> 0.2 | D23: correct / total
A24: No calibration in run | B24: Mean absolute floor error | C24: =AVERAGEIF(manual_test_points!H2:H83,"no_calibration_in_run",manual_test_points!Q2:Q83) -> 58.008 | D24: m
A25: No calibration in run | B25: Maximum absolute floor error | C25: =_xlfn.MAXIFS(manual_test_points!Q2:Q83,manual_test_points!H2:H83,"no_calibration_in_run") -> 65.34 | D25: m
A27: Before calibration + No calibration run | B27: Test points | C27: =C21+C15 -> 7 | D27: points
A28: Before calibration + No calibration run | B28: Correct points | C28: =C16+C22 -> 2 | D28: points
A29: Before calibration + No calibration run | B29: Accuracy | C29: =C28/C27 -> 0.28571429 | D29: correct / total
A30: Before calibration + No calibration run | B30: Mean absolute floor error | C30: {=AVERAGE(_xlfn._xlws.FILTER(manual_test_points!Q2:Q83,(manual_test_points!H2:H83="before_calibration")+(manual_test_points!H2:H83="no_calibration_in_run")))} -> 57.517143 | D30: m
A31: Before calibration + No calibration run | B31: Maximum absolute floor error | C31: {=MAX(_xlfn._xlws.FILTER(manual_test_points!Q2:Q83,(manual_test_points!H2:H83="no_calibration_in_run")+(manual_test_points!H2:H83="before_calibration")))} -> 65.34 | D31: m
A34: Calibration points | B34: Calibration point count | C34: =COUNTA(recalibration_points!A2:A5) -> 4 | D34: points
A35: Calibration points | B35: Average calibration pressure | C35: =AVERAGE(recalibration_points!I2:I5) -> 1014.8225 | D35: hPa
A36: Calibration points | B36: Minimum calibration pressure | C36: =MIN(recalibration_points!I2:I5) -> 1012.16 | D36: hPa
A37: Calibration points | B37: Maximum calibration pressure | C37: =MAX(recalibration_points!I2:I5) -> 1022.28 | D37: hPa
A41: Desk drift test | B41: Read rows | C41: =COUNTIF(desk_drift!A2:A78,"read") -> 75 | D41: read samples
A42: Desk drift test | B42: Duration | C42: =(_xlfn.MAXIFS(desk_drift!B2:B78,desk_drift!A2:A78,"read")-_xlfn.MINIFS(desk_drift!B2:B78,desk_drift!A2:A78,"read"))/1000 -> 123.796 | D42: s
A43: Desk drift test | B43: Average pressure | C43: =AVERAGEIFS(desk_drift!D2:D78,desk_drift!A2:A78,"read") -> 101902.65 | D43: Pa
A44: Desk drift test | B44: Minimum pressure | C44: =_xlfn.MINIFS(desk_drift!D2:D78,desk_drift!A2:A78,"read") -> 101900.33 | D44: Pa
A45: Desk drift test | B45: Maximum pressure | C45: =_xlfn.MAXIFS(desk_drift!D2:D78,desk_drift!A2:A78,"read") -> 101905.3 | D45: Pa
A46: Desk drift test | B46: Pressure range | C46: =C45-C44 -> 4.97 | D46: Pa
A47: Desk drift test | B47: Pressure standard deviation | C47: =_xlfn.STDEV.S(desk_drift!D4:D78) -> 1.1574265 | D47: Pa
A48: Desk drift test | B48: Average relative height | C48: =AVERAGEIFS(desk_drift!F2:F78,desk_drift!A2:A78,"read") -> -42.210533 | D48: m
A49: Desk drift test | B49: Minimum relative height | C49: =_xlfn.MINIFS(desk_drift!F2:F78,desk_drift!A2:A78,"read") -> -42.43 | D49: m
...
